Workbook

Sheet form
A1: monthly_v2.0

Sheet Instructions and Glossary
A1: Project Tracker - Instructions
B4: Purpose | C4: The Project Tracker is a tool for capital analysts to capture information about each board's projects. This data provides a line of sight into project progress and details that is critical to both analysts, other folks within the branch, and management. The data gathered here facilitates project accountability and oversight of project milestones and finances.
B6: Instructions
B7: During Meetings with the Board | C7: When analysts meet with their board to discuss projects, you should use this tool to guide your meetings and capture information. Make sure you update the meeting date on the Monthly Tracker worksheet. You'll notice that this sheet has conditional formatting that greys out the sheet when the meeting date is not set to the current day. This is done so you have a visual reminder to update this date before you talk with your boards. Taking comprehensive minutes is especially important part of your meetings with the boards. The template provides space for you to enter project-specific minutes, as well as a section for minuting any more general information discussed that might not fall under one specific project. The data is scraped regularly and then the template is regenerated with updated information. During this process, minutes are archived and relocated to the far-left side of the template (column BD), sorted with the most recent minutes closest to the left.
B8: As Needed | C8: If you need to update information at any time other than during a meeting with the board, you are free to do so and the revised information will be captured the next time the data team extracts data from worksheet. Do NOT change the meeting date during any such ad-hoc updates. You should only change the meeting dates when you actually meet with the school board.
B9: General Information & Error Checking | C9: As mentioned above, the Monthly Update worksheet contains conditional formatting that incentivizes you not to forget to enter a meeting date when you talk with the school board. You will notice that once the meeting date is has passed (i.e., it is something other than the current date), the whole sheet goes grey. This provides a visual cue for you to update the date prior to meeting with your board. The sheet also contains some automatic error checking. Cells contain errors when they are highlighted in purple. To determine the reason for the error, scroll over to columns CY to ES. This section contains the same columns as the main table; cells in this table will only contains text if there is an error. That text will describe the cause of the error in the corresponding cell in the main table.
B11: Within-Budget Acknowledgement Process
B12: Analyst Checks | C12: Confirm that the board has submitted all necessary documentation: •Class A/B cost estimate •Revised CPBF form that reflects the Class A/B cost estimate. •80% design drawings that align with the cost estimate and approved space template. •Child care floor plan approval letter (if applicable). Ensure that all documents are saved in the appropriate folder on the Share Drive. Once you have checked and confirmed all documents, send an email to the board acknowledging receipt of the pre/post tender package.
B13: Record Keeping | C13: Create a folder in the following directory: \\csc.ad.gov.on.ca\dfs$\GrpData\CBSD\CAPITAL\STRATEGY\Operations\BOARDS\^Project Commitment\Pre & Post Tender Check-In •The folder should be named using the following naming format: project id # YYYY-MM-DD Example: 12-123 # 2025-12-30 •The date in the folder name should be the date of the email acknowledging receipt of the documents and confirming the board can proceed. •Save the following in the folder you created above: o The CPBF form that reflects the pre-tender/post-tender budget. o The email to the school board (sent within 7 days of the board’s submission) confirming all documents have been submitted and that the ministry has no concerns with the board proceeding to tender/awarding the contract.
A15: Project Tracker Glossary
B17: Overview of the Worksheets within the Project Tracker
B18: Board Contacts | C18: Use this worksheet to enter the contact information for your boards. This is a central location for Capital Analysts to store this information, as well as a place where management and other analysts can go if they need this information. This is important to support coverage for analysts who are absent.
B19: Monthly Update | C19: Use this tab to memorialize meetings with the school boards. See instructions above and glossary below for more information.
B20: Basic Project Info | C20: Use this worksheet to enter the official school name, the school's location information, sign installation information, and the opening ceremony date. See below for a glossary, defining what should be entered in each column.
B21: Ad-Hoc or Potential Projects | C21: Use this worksheet to enter data about potential projects that have not yet been approved or about ad-hoc, minor projects that don't show up on the Monthly Tracker sheet.
B22: Project Commitment | C22: This sheet is for your reference only. It is not editable. It provides information about the current project commitment for the projects for this board.
A24: Glossary - Basic Project Info Tab
A26: ='Basic Project Info'!A2 -> Section 1: Project Details
A27: Col 1 | B27: =_xlfn.XLOOKUP(A27,'Basic Project Info'!$A$3:$L$3, 'Basic Project Info'!$A$4:$L$4) -> Project ID | C27: =C44 -> Automatically generated and uneditable. Each project is assigned a unique ID for tracking throughout its lifecycle. The ID displayed here is the ID for the construction portion of the project.
A28: ="Col " & ROW() -ROW($A$27)+1 -> Col 2 | B28: =_xlfn.XLOOKUP(A28,'Basic Project Info'!$A$3:$L$3, 'Basic Project Info'!$A$4:$L$4) -> Project Name | C28: Automatically generated and uneditable. This is the name assigned to the project when it is first approved. It cannot be changed and is constant throughout the project's lifecycle.
A29: ="Col " & ROW() -ROW($A$27)+1 -> Col 3 | B29: =_xlfn.XLOOKUP(A29,'Basic Project Info'!$A$3:$L$3, 'Basic Project Info'!$A$4:$L$4) -> Official School Name | C29: Use this field to update the official school name that will be used after the school is open. Please use the complete name and do not use abbreviations (e.g. use "Example Public School" instead of "Example" or "Example P.S.". If this project is an addition, this field can be completed as soon as the project is approved.
A30: ="Col " & ROW() -ROW($A$27)+1 -> Col 4 | B30: =_xlfn.XLOOKUP(A30,'Basic Project Info'!$A$3:$L$3, 'Basic Project Info'!$A$4:$L$4) -> Project Type | C30: =C47 -> Automatically generated and uneditable. Project types potentially included in this tracker are: New Construction, Retrofit, Addition, and Purchase.
A31: ="Col " & ROW() -ROW($A$27)+1 -> Col 5 | B31: =_xlfn.XLOOKUP(A31,'Basic Project Info'!$A$3:$L$3, 'Basic Project Info'!$A$4:$L$4) -> Project Category | C31: =C48 -> Automatically generated and uneditable. This field identifies the need that is met by the project. Potential project categories that could be included on this tracker are: Accommodation Pressure, Child Care, Facility Condition, Consolidation, and French Language Access.
A32: ="Col " & ROW() -ROW($A$27)+1 -> Col 6 | B32: =_xlfn.XLOOKUP(A32,'Basic Project Info'!$A$3:$L$3, 'Basic Project Info'!$A$4:$L$4) -> Address | C32: Enter the address for the school. If it's not yet known, leave it blank.
A33: ="Col " & ROW() -ROW($A$27)+1 -> Col 7 | B33: =_xlfn.XLOOKUP(A33,'Basic Project Info'!$A$3:$L$3, 'Basic Project Info'!$A$4:$L$4) -> City | C33: Use this field to enter the city/town where the project is located. This should be known at the time of project approval and be pre-populated on the template. Therefore, this field can be left unedited except for very rare circumstances.
A34: ="Col " & ROW() -ROW($A$27)+1 -> Col 8 | B34: =_xlfn.XLOOKUP(A34,'Basic Project Info'!$A$3:$L$3, 'Basic Project Info'!$A$4:$L$4) -> Postal Code | C34: Enter the postal code of the school. If the it's not yet known, leave it blank.
A35: ="Col " & ROW() -ROW($A$27)+1 -> Col 9 | B35: =_xlfn.XLOOKUP(A35,'Basic Project Info'!$A$3:$L$3, 'Basic Project Info'!$A$4:$L$4) -> Latitude | C35: Enter the latitude of the school. This information should be updated once the site has been purchased.
A36: ="Col " & ROW() -ROW($A$27)+1 -> Col 10 | B36: =_xlfn.XLOOKUP(A36,'Basic Project Info'!$A$3:$L$3, 'Basic Project Info'!$A$4:$L$4) -> Longitude | C36: Enter the longitude of the school. This information should be updated once the site has been purchased.
A37: ='Basic Project Info'!K2 -> Section 2: Communications Issues
A38: ="Col " & ROW() -ROW($A$27) -> Col 11 | B38: =_xlfn.XLOOKUP(A38,'Basic Project Info'!$A$3:$L$3, 'Basic Project Info'!$A$4:$L$4) -> Sign Installed | C38: Indicate whether the board has installed a sign on the project site.
A39: ="Col " & ROW() -ROW($A$27) -> Col 12 | B39: =_xlfn.XLOOKUP(A39,'Basic Project Info'!$A$3:$L$3, 'Basic Project Info'!$A$4:$L$4) -> Opening Ceremony - Date | C39: Use this once the project approaches completion if the board plans an opening ceremony. Otherwise, leave this blank.
A41: Glossary - Monthly Update Tab
A43: ='Monthly Update'!A5 -> Section 1: Project Details
A44: Col 1 | B44: =_xlfn.XLOOKUP(A44, 'Monthly Update'!$A$6:$AU$6, 'Monthly Update'!$A$7:$AU$7) -> Project ID | C44: Automatically generated and uneditable. Each project is assigned a unique ID for tracking throughout its lifecycle. The ID displayed here is the ID for the construction portion of the project.
A45: Col 2 | B45: =_xlfn.XLOOKUP(A45, 'Monthly Update'!$A$6:$AU$6, 'Monthly Update'!$A$7:$AU$7) -> Project Name | C45: Automatically generated and uneditable. This is the name assigned to the project when it is first approved. It cannot be changed and is constant throughout the project's lifecycle. The official name of the school can be modified on the Basic Project Info tab.
A46: Col 3 | B46: =_xlfn.XLOOKUP(A46, 'Monthly Update'!$A$6:$AU$6, 'Monthly Update'!$A$7:$AU$7) -> Meeting Minutes | C46: Enter details about each project based on conversations with the school board.
A47: Col 4 | B47: =_xlfn.XLOOKUP(A47, 'Monthly Update'!$A$6:$AU$6, 'Monthly Update'!$A$7:$AU$7) -> Project Type | C47: Automatically generated and uneditable. Project types potentially included in this tracker are: New Construction, Retrofit, Addition, and Purchase.
A48: Col 5 | B48: =_xlfn.XLOOKUP(A48, 'Monthly Update'!$A$6:$AU$6, 'Monthly Update'!$A$7:$AU$7) -> Project Category | C48: Automatically generated and uneditable. This field identifies the need that is met by the project. Potential project categories that could be included on this tracker are: Accommodation Pressure, Child Care, Facility Condition, Consolidation, and French Language Access.
A49: Col 6 | B49: =_xlfn.XLOOKUP(A49, 'Monthly Update'!$A$6:$AU$6, 'Monthly Update'!$A$7:$AU$7) -> Record Status | C49: This drop-down determines which projects will be removed from your trackers. If you want to remove a project, you must identify whether it has been completed or cancelled. The default is for projects to remain on the tracker. When projects are removed from the tracker, it triggers an email notification to your manager and director.
A50: Col 7 | B50: =_xlfn.XLOOKUP(A50, 'Monthly Update'!$A$6:$AU$6, 'Monthly Update'!$A$7:$AU$7) -> Construction Status | C50: Automatically generated and uneditable. This field is calculated based on the dates provided to the right in this sheet. If the meeting date is after the opening date, the construction status is "Open"; if the meeting date is after the construction date, the status is "Under Construction". Otherwise the project status is "Planning".
...

Sheet Board Contacts
A1: School Board Contact List
A4: Name | B4: Role | C4: Title | D4: Email | E4: Phone
A5: Milka Zlomislic | B5: Senior Buisness Official | C5: Superintendent of Capital Development and Asset Renewal | D5: milka.zlomislic@tcdsb.org
A6: Amal
A7: Michael Loberto | B7: Senior Buisness Official | C7: Superintendent of Planning and Development Services | D7: michael.loberto@tcdsb.org
A8: Barbara Leporati | B8: Primary Contact | C8: Head of Plannin Services Planning and Development | D8: barbara.leporati@tcdsb.org | E8: 416-222-8282 ext. 72270 or 416-522-8861 (cell)

Sheet Basic Project Info
A1: Basic Project Information
A2: =Translation!A5 -> Section 1: Project Details | K2: Section 2: Communications Issues
A3: ="Col "&COLUMN() -> Col 1 | B3: ="Col "&COLUMN() -> Col 2 | C3: ="Col "&COLUMN() -> Col 3 | D3: ="Col "&COLUMN() -> Col 4 | E3: ="Col "&COLUMN() -> Col 5 | F3: ="Col "&COLUMN() -> Col 6 | G3: ="Col "&COLUMN() -> Col 7 | H3: ="Col "&COLUMN() -> Col 8 | ... L3: ="Col "&COLUMN() -> Col 12
A4: =Translation!A6 -> Project ID | B4: =Translation!A7 -> Project Name | C4: Official School Name | D4: =Translation!A11 -> Project Type | E4: =Translation!A13 -> Project Category | F4: =Translation!A8 -> Address | G4: =Translation!A9 -> City | H4: =Translation!A10 -> Postal Code | I4: Latitude | J4: Longitude | K4: Sign Installed | L4: =Translation!A70 -> Opening Ceremony - Date
A5: No. de projet | B5: Nom du projet | D5: Type de projet | E5: Catégorie de projet
A7: 40-010-01 | B7: Blessed Cardinal Newman Catholic Secondary School | D7: New Construction | E7: Accommodation Pressure | F7: 100 BRIMLEY RD S | G7: SCARBOROUGH | H7: M1M3X4 | I7: 43.71291 | J7: -79.24269
A8: 40-017 | B8: Dante Alighieri Catholic Secondary School | D8: New Construction | E8: Accommodation Pressure | F8: 60 PLAYFAIR AVE | G8: NORTH YORK | H8: M6B2P9 | I8: 43.71017 | J8: -79.45802
A9: 40-076-01 | B9: St. Fidelis Catholic Elementary School | D9: New Construction | E9: Accommodation Pressure | F9: 155 FALSTAFF AVE | G9: NORTH YORK | H9: M6L2E5 | I9: 43.71768 | J9: -79.495826
A10: 40-109-01 | B10: St. Raymond Catholic Elementary School | C10: St. Peter Catholic Elementary School | D10: New Construction | E10: Consolidation | F10: 270 BARTON AVE | G10: TORONTO | H10: M6G1R4 | I10: 43.66592 | J10: -79.42317
A11: 40-127 | B11: St. Antoine Daniel Catholic Elementary School | D11: New Construction | E11: Accommodation Pressure | F11: 160 FINCH AVE W | G11: NORTH YORK | H11: M2N2J2 | I11: 43.777552 | J11: -79.429777
A12: 40-128 | B12: Regina Mundi Catholic Elementary School | D12: Retrofit | E12: Condition | F12: 70 PLAYFAIR AVE | G12: NORTH YORK | H12: M6B2P9 | I12: 43.71006 | J12: -79.4593
A13: 40-151 | B13: St. Michael's Choir Catholic Elementary School | D13: New Construction | E13: Condition | G13: TORONTO
A14: 40-152 | B14: Holy Angels Catholic Elementary School | D14: New Construction | E14: Accommodation Pressure | F14: 65 JUTLAND RD | G14: ETOBICOKE | H14: M8Z2G6 | I14: 43.628248 | J14: -79.517714
A15: 40-153 | B15: St. Matthias Catholic Elementary School | C15: Divine Mercy Catholic Elementary School | D15: New Construction | E15: Consolidation | F15: 101 VAN HORNE AVE | G15: NORTH YORK | H15: M2J2S8 | I15: 43.784481 | J15: -79.35948
A16: 40-154 | B16: St. Margaret Catholic Elementary School | D16: Addition | E16: Accommodation Pressure | F16: 85 CARMICHAEL AVE | G16: NORTH YORK | H16: M5M2X1 | I16: 43.73611 | J16: -79.42667
A17: 40-156 | B17: Baycrest Catholic Elementary School | D17: New Construction | E17: Accommodation Pressure | F17: 145 BAYCREST AVE | G17: NORTH YORK | H17: M6A1W4 | I17: 43.726739 | J17: -79.44428
A18: 40-157 | B18: Buttonwood Catholic Elementary School | D18: New Construction | E18: Accommodation Pressure | F18: 100 ALLANHURST DR | G18: TORONTO | H18: M9A4K4 | I18: 43.68026 | J18: -79.519277
A19: 40-158 | B19: Buttonwood Catholic Secondary School | D19: New Construction | E19: Accommodation Pressure | F19: 15 TREHORNE DR | G19: ETOBICOKE | H19: M9P1N8 | I19: 43.680688 | J19: -79.519123
A20: 40-159 | B20: Bishop Allen Academy Catholic Secondary School | D20: New Construction | E20: Accommodation Pressure | F20: 721 ROYAL YORK RD | G20: ETOBICOKE | H20: M8Y2T3 | I20: 43.634 | J20: -79.50543
A21: 40-160 | B21: Loretto Abbey Catholic Secondary School | D21: Addition | E21: Accommodation Pressure | F21: 101 MASON BLVD | G21: NORTH YORK | H21: M5M3E2 | I21: 43.74088 | J21: -79.4111
A22: 40-167 | B22: St. Elizabeth Catholic Elementary School | D22: New Construction | E22: Accommodation Pressure | G22: ETOBICOKE | H22: M9B1J8
A23: 40-168 | B23: St. Monica Catholic Elementary School | D23: New Construction | E23: Accommodation Pressure | G23: TORONTO | H23: M4P1T4
A24: 40-175 | B24: Block 9 Concord Place | D24: New Construction | E24: Accommodation Pressure | F24: SHEPPARD/LESLIE AREA | G24: NORTH YORK
A100: 1 | B100: 1 | C100: 1 | D100: 1 | E100: 1 | F100: 1 | G100: 1 | H100: 1 | I100: 1 | J100: 1 | K100: 1 | L100: 1

Sheet Monthly Update
A1: Monthly Project Updates | C1: 40 - Toronto Catholic DSB
E2: =COLUMNS($D$3:$AU$3) - COUNTIF($D$3:$AU$3, "") -> 0 | F2: 0
A3: Meeting Date | C3: 46072 | CX3: =COUNTA(CY9:ES104) -> 545 | CY3: TRUE | CZ3: =AND(CZ4, ISBLANK(CZ11)) -> FALSE | DA3: =AND(CAA4, ISBLANK(CAA11)) -> TRUE | DB3: =AND(CAB4, ISBLANK(CAB11)) -> TRUE | DC3: =AND(CAC4, ISBLANK(CAC11)) -> TRUE | DD3: =AND(CAD4, ISBLANK(CAD11)) -> TRUE | DE3: =AND(CAE4, ISBLANK(CAE11)) -> TRUE | DF3: =AND(CAF4, ISBLANK(CAF11)) -> TRUE | DG3: =AND(CAG4, ISBLANK(CAG11)) -> TRUE | DH3: =AND(CAH4, ISBLANK(CAH11)) -> TRUE | ... ES3: =AND(CBS4, ISBLANK(CBS11)) -> TRUE
B4: General Meeting Minutes: | AT4: Historical General Meeting Minutes -------------> | CX4: 97 | CY4: =ISNUMBER(SEARCH("formula", CY10)) -> FALSE | CZ4: =ISNUMBER(SEARCH("formula", CZ10)) -> FALSE | DA4: =ISNUMBER(SEARCH("formula", CAA10)) -> FALSE | DB4: =ISNUMBER(SEARCH("formula", CAB10)) -> FALSE | DC4: =ISNUMBER(SEARCH("formula", CAC10)) -> FALSE | DD4: =ISNUMBER(SEARCH("formula", CAD10)) -> FALSE | DE4: =ISNUMBER(SEARCH("formula", CAE10)) -> FALSE | DF4: =ISNUMBER(SEARCH("formula", CAF10)) -> FALSE | DG4: =ISNUMBER(SEARCH("formula", CAG10)) -> FALSE | DH4: =ISNUMBER(SEARCH("formula", CAH10)) -> FALSE | ... ES4: =ISNUMBER(SEARCH("formula", CBS10)) -> FALSE
A5: Section 1: Project Details | H5: Section 2: Project Commitment Progress | P5: Section 3: Pre-Tender | AB5: Section 4: Construction | AG5: Section 5: Project Completion | AL5: Section 6: Approved Project Funding | AQ5: Section 7: Projected Cost | AV5: Section 10: Project Risks and Mitigation Stategies | BD5: Section 8: Historical Meeting Minutes | CY5: Error Messages | DD5: Error Messages | DM5: Error Messages | DR5: Error Messages | DV5: Error Messages | DY5: Error Messages | EB5: Error Messages | EG5: Error Messages | EL5: Error Messages | EQ5: Error Messages
A6: Col 1 | B6: ="Col "&COLUMN() -> Col 2 | C6: ="Col "&COLUMN() -> Col 3 | D6: ="Col "&COLUMN() -> Col 4 | E6: ="Col "&COLUMN() -> Col 5 | F6: ="Col "&COLUMN() -> Col 6 | G6: ="Col "&COLUMN() -> Col 7 | H6: ="Col "&COLUMN() -> Col 8 | I6: ="Col "&COLUMN() -> Col 9 | ... AV6: ="Col "&COLUMN() -> Col 48 | BC6: ="Col "&COLUMN() -> Col 55 | BD6: ="Col "&COLUMN() -> Col 56 | BE6: ="Col "&COLUMN() -> Col 57 | BF6: ="Col "&COLUMN() -> Col 58 | BG6: ="Col "&COLUMN() -> Col 59 | BH6: ="Col "&COLUMN() -> Col 60 | BI6: ="Col "&COLUMN() -> Col 61 | BJ6: ="Col "&COLUMN() -> Col 62 | ... CA6: ="Col "&COLUMN() -> Col 79 | CY6: =A6 -> Col 1 | CZ6: =B6 -> Col 2 | DA6: =C6 -> Col 3 | DB6: =D6 -> Col 4 | DC6: =E6 -> Col 5 | DD6: =F6 -> Col 6 | DE6: =G6 -> Col 7 | DF6: =H6 -> Col 8 | ... ES6: =AU6 -> Col 47 | EW6: Col 11 | EX6: Col 11 | EY6: =EX6 -> Col 11 | EZ6: =EY6 -> Col 11 | FA6: Col 15 | FB6: Col 15 | FC6: =FB6 -> Col 15 | FD6: =FC6 -> Col 15 | FE6: Col 16 | FF6: Col 16 | FG6: =FF6 -> Col 16 | FH6: =FG6 -> Col 16 | FI6: Col 17 | FJ6: Col 17 | FK6: =FJ6 -> Col 17 | FL6: =FK6 -> Col 17
A7: Project ID | B7: Project Name | C7: Meeting Minutes | D7: Project Type | E7: Project Category | F7: Record Status | G7: Construction Status | H7: Pre-Tender Submission Date | I7: Pre-Tender Package Type | J7: Pre-Tender Package Complete | K7: CA Reviewed All Pre-Tender Documents | L7: Post-Tender Submission Date | M7: Post-Tender Package Type | N7: Post-Tender Package Complete | O7: CA Reviewed All Post-Tender Documents | P7: Site Ownership Status | Q7: Site Purchase Date | R7: Design Status | S7: Space Template Approval Date | T7: Child Care Floorplan Approval Date | U7: Initial Site Plan Submission Date | V7: Site Plan Approval Date | W7: Site Plan Approval Date Error Explanation | X7: Build Permit Obtained Date | Y7: Build Permit Obtained Date Error Explanation | Z7: Tender Issued Date | AA7: Tender Closed Date | AB7: Contract Awarded Date | AC7: Construction Start Date | AD7: Construction Start Date Error Explanation | AE7: Substantial Completion Date | AF7: Substantial Completion Date Error Explanation | AG7: School Opening Date | AH7: School Opening Date Error Explanation | AI7: Child Care Opening Date | AJ7: Child Care Opening Date Error Explanation | AK7: Financial Close-Out Date | AL7: Funding - All Associated Projects | AM7: Funding - Construction Project | AN7: Funding - Site Acquisition | AO7: Funding - Demolition | AP7: Funding - All Other Associated Projects | AQ7: Basis of Cost Estimate | AR7: Estimated Cost - Construction Project | AS7: Estimated Cost - Land | AT7: Estimated Cost - Demolition | AU7: Estimated Cost - All Other Associated Projects | AV7: Risk Type | AW7: Risk Rating | AX7: Risk Exposure Start Date | AY7: Min Cost of Risk ($M) | AZ7: Max Cost of Risk ($M) | BA7: Min Delay of Risk (Months) | BB7: Max Delay of Risk (Months) | BC7: Mitigation Stategies/Comments | BD7: December 04, 2025 | BE7: October 23, 2025 | BF7: September 29, 2025 | BG7: August 21, 2025 | BH7: August 27, 2024 | BI7: August 01, 2024 | BJ7: June 25, 2024 | BK7: May 30, 2024 | BL7: May 09, 2024 | BM7: April 04, 2024 | BN7: June 16, 2023 | CC7: *((table_end*((meeting_minutes_heading | CE7: cc_amount | CF7: Site Purchase Date | CG7: Space Template Approval Date | CH7: Child Care Floorplan Approval Date | CI7: Initial Site Plan Submission Date | CJ7: Site Plan Approval Date | CK7: Build Permit Obtained Date | CL7: Pre-Tender Submission Date | CM7: Tender Issued Date | CN7: Tender Closed Date | CO7: Post-Tender Submission Date | CP7: Contract Awarded Date | CQ7: Construction Start Date | CR7: Substantial Completion Date | CS7: School Opening Date | CT7: Child Care Opening Date | CU7: Financial Close-Out Date | CY7: =A7 -> Project ID | CZ7: =B7 -> Project Name | DA7: =C7 -> Meeting Minutes | DB7: =D7 -> Project Type | DC7: =E7 -> Project Category | DD7: =F7 -> Record Status | DE7: =G7 -> Construction Status | DF7: =H7 -> Pre-Tender Submission Date | ... ES7: =AU7 -> Estimated Cost - All Other Associated Projects
A8: No. de projet | B8: Nom du projet | D8: Type de projet | E8: Catégorie de projet | AN8: IP | AO8: Service de garde | AP8: Autre | AQ8: Base de l'estimation des coûts | AU8: Coûts du site
A10: 40-010-01 | B10: Blessed Cardinal Newman Catholic Secondary School | C10: The TCDSB team shared with the school community the tender price due to the escalation cost was much higher than the ministry allocation. The school board is now considering a re-design to fit within the ministry allocation. School board informed the contractor that the project is not moving at the moment. Costs incurred to date on this project (on architect designs, studies) is approximately $5M. Board will reconcile the funding. After the reconciliation, the board will part with the current architect and prepare another RFP for a new architectural team to take over (confidential information at the moment). Board plans to hire consultants to undertake a feasibility study and review designs to fit within budget and within the site limitations. Enrolment projections - Ministry to contact Planning to get revised enrolment numbers to see if the 1100pp is still correct. | D10: New Construction | E10: Accommodation Pressure | F10: In Progress | G10: =_xlfn.IFS($C$3>AK10, "Complete", $C$3>AG10, "Open", $C$3>AC10, "Under Construction", TRUE, "Planning") -> Planning | H10: 46418 | I10: Not Yet Known | J10: Not yet submitted/reviewed | K10: Not yet submitted/reviewed | L10: 46568 | M10: Not Yet Known | N10: Not yet submitted/reviewed | O10: Not yet submitted/reviewed | P10: Site Purchased | Q10: 41456 | R10: >80% Complete | S10: 43536 | V10: 45596 | X10: 46428 | Z10: 46428 | AA10: 46456 | AB10: 46583 | AC10: 46600 | AE10: 47611 | AG10: 47731 | AK10: 48096 | AL10: =SUM(AM10:AP10) -> 96240494 | AM10: 73057674 | AN10: 17452257 | AO10: 5730563 | AQ10: Based on Tender Results | BD10: Need update post letter - what is the board looking into, OTG scaledown?, Recommendation has not made public yet - Derek will organize an in person meeting to school community hopefully by the end of the year. SB has had problems with the city and the site plan (NOAC approved with manu conditions that are cleared at the end ofthe project). Legal was going to pursue the site plan with the city, but the SB indicated to stop all work due to confidential issues. Contractor who bid on the project has reached out to the Supervisor of the SB to discuss the project. It is likley possible the Contractor is not aware of the final ministry decision. | BE10: Tender is still open, contractor is holding the price until a decision is made. If the board needs to re-design the project - a change to the design, muncipal SPA, building permit etc will need to happen. The heritage designation happened after the project design began. The first SPA submission (May 2020) the buildings were NOT designated heritage. The original plan was to demolish all three buildings on site. The heritage designated happened in October 2021, the board recieved an intension to designate the structures in March 2021. | BF10: Tender is still open, contractor is holding the price until a decision is made. If the board needs to re-design the project - a change to the design, muncipal SPA, building permit etc will need to happen. The heritage designation happened after the project design began. The first SPA submission (May 2020) the buildings were NOT designated heritage. The original plan was to demolish all three buildings on site. The heritage designated happened in October 2021, the board recieved an intension to designate the structures in March 2021. | BG10: Tender is still open, and extending the tender month by month. What is the proposed schedule to demolish the non-heritage buildings/wing on site? Will remain on site until a ministry reponse is given. | CD10: =IF(AND(Q10="", A10<>"", P10<>"Site Purchased Prior to Capital Approval"), 1, 0) -> 0 | CE10: 0 | CF10: =_xlfn.XLOOKUP($A10, 'Project Commitment'!$A:$A, 'Project Commitment'!M:M, "") -> 0 | CG10: =_xlfn.XLOOKUP($A10, 'Project Commitment'!$A:$A, 'Project Commitment'!N:N, "") -> 0 | CH10: =_xlfn.XLOOKUP($A10, 'Project Commitment'!$A:$A, 'Project Commitment'!O:O, "") -> 0 | CI10: =_xlfn.XLOOKUP($A10, 'Project Commitment'!$A:$A, 'Project Commitment'!P:P, "") -> 0 | CJ10: =_xlfn.XLOOKUP($A10, 'Project Commitment'!$A:$A, 'Project Commitment'!Q:Q, "") -> 0 | CK10: =_xlfn.XLOOKUP($A10, 'Project Commitment'!$A:$A, 'Project Commitment'!R:R, "") -> 0 | CL10: =_xlfn.XLOOKUP($A10, 'Project Commitment'!$A:$A, 'Project Commitment'!S:S, "") -> #VALUE! | CM10: =_xlfn.XLOOKUP($A10, 'Project Commitment'!$A:$A, 'Project Commitment'!T:T, "") -> 0 | CN10: =_xlfn.XLOOKUP($A10, 'Project Commitment'!$A:$A, 'Project Commitment'!U:U, "") -> #VALUE! | CO10: =_xlfn.XLOOKUP($A10, 'Project Commitment'!$A:$A, 'Project Commitment'!V:V, "") -> #VALUE! | CP10: =_xlfn.XLOOKUP($A10, 'Project Commitment'!$A:$A, 'Project Commitment'!W:W, "") -> 0 | CQ10: =_xlfn.XLOOKUP($A10, 'Project Commitment'!$A:$A, 'Project Commitment'!X:X, "") -> -942 | CR10: =_xlfn.XLOOKUP($A10, 'Project Commitment'!$A:$A, 'Project Commitment'!Y:Y, "") -> #VALUE! | CS10: =_xlfn.XLOOKUP($A10, 'Project Commitment'!$A:$A, 'Project Commitment'!Z:Z, "") -> -1100 | CT10: =_xlfn.XLOOKUP($A10, 'Project Commitment'!$A:$A, 'Project Commitment'!AA:AA, "") -> 0 | CU10: =_xlfn.XLOOKUP($A10, 'Project Commitment'!$A:$A, 'Project Commitment'!AB:AB, "") -> #VALUE! | DA10: =IF(C10="", "Meeting Minutes cannot be blank", "") | DF10: =_xlfn.IFS(AND(J10="Not Applicable", H10<>""), "No date is needed if Column 10 is Not Applicable",J10= "Not Applicable", "", H10="",DF$7&" cannot be blank", $AC10="", "", H10>$AC10, DF$7&" must preceed construction start date.", TRUE, "") | DG10: =_xlfn.IFS(I10="", DG$7&" cannot be left blank.",H10="", "", AND( H10 < TODAY(), I10="Not Yet Known"), "After the submission date, the pre-tender package type must be selected.", TRUE, "") | DI10: =EW10 | DJ10: =_xlfn.IFS(AND(N10="Not Applicable", L10<>""), "No date is needed if Column 14 is Not Applicable",N10= "Not Applicable", "", L10="",DJ$7&" cannot be blank", $AC10="", "", L10>$AC10, DJ$7&" must preceed construction start date.", TRUE, "") | DK10: =_xlfn.IFS(M10="", DK$7&" cannot be left blank.",L10="", "", AND( L10 < TODAY(), M10="Not Yet Known"), "After the submission date, the pre-tender package type must be selected.", TRUE, "") | DM10: =FA10 | DN10: =FE10 | DO10: =FI10 | DP10: =IF(R10="", DP$7&" cannot be blank", "") | DQ10: =_xlfn.IFS(S10="",DQ$7&" cannot be blank",AND(J10<>"Not yet submitted/reviewed",S10>TODAY()),DQ$7&" cannot be in the future if project is ready for a pre-tender package.",TRUE,"") | DR10: =_xlfn.IFS(CE10=0, "", T10="",DR$7&" cannot be blank if project includes child care.", AND(J10="Not Applicable",T10>TODAY()), "Projects under construction must have a "&DR$7, J10="Not Applicable", "", T10<I10, T6&" must preceed pre-tender package submission date",TRUE, "") | DS10: =_xlfn.IFS(U10="",DS$7&" cannot be blank", $AC10="", "", U10>$AC10, DS$7&" must preceed construction start date.", TRUE, "") -> Initial Site Plan Submission Date cannot be blank | DT10: =_xlfn.IFS(W10<>"", "", V10="",DT$7&" cannot be blank", $AC10="", "", V10>$AC10, DT$7&" must preceed construction start date.", TRUE, "") | DV10: =_xlfn.IFS(Y10<>"", "", X10="",DV$7&" cannot be blank", $AC10="", "", X10>$AC10, DV$7&" must preceed construction start date.", TRUE, "") | DX10: =_xlfn.IFS(Z10="",DX$7&" cannot be blank", $AC10="", "", Z10>$AC10, DX$7&" must preceed construction start date.", TRUE, "") | DY10: =_xlfn.IFS(AA10="",DY$7&" cannot be blank", $AC10="", "", AA10>$AC10, DY$7&" must preceed construction start date.", TRUE, "") | DZ10: =_xlfn.IFS(AB10="",DZ$7&" cannot be blank", $AC10="", "", AB10>$AC10, DZ$7&" must preceed construction start date.", TRUE, "") | EA10: =_xlfn.IFS(AD10<>"", "", AC10="",EA$7&" cannot be blank", $AG10="", "", AC10>EDATE($AG10,-12), EA$7&" must preceed school opening date by more than 12 months.", TRUE, "") | EC10: =_xlfn.IFS(AF10<>"", "", AE10="",EC$7&" cannot be blank", $AG10="", "", AE10>EDATE($AG10,-1), EC$7&" must preceed school opening date by more than one month.", TRUE, "") | EE10: =_xlfn.IFS(AK10="", "", AG10="",EE$7&" cannot be blank",AH10<>"", "", $AG10="", "", AG10>=EDATE($AK10,-11), EE$7&" must preceed financial close date by at least 12 months.", TRUE, "") | EG10: =_xlfn.IFS(CE10=0, "", AI10="",EG$7&" cannot be blank",$AK10="", "",AJ10<>"", "", AI10>=EDATE($AK10,0), EG$7&" must preceed financial close date.", TRUE, "") | EI10: =_xlfn.IFS( AK10="",EI$7&" cannot be blank", TRUE, "") | EO10: =_xlfn.IFS(AQ10="", "Basis of Cost Estimate cannot be blank", AND(AC10<TODAY(), AQ10<>"Based on Tender Results"), "Contract awarded date suggests estimate should be based on tender results", AND(H10<TODAY(), AQ10<>"Based on Class A or B Cost Report"), "If project has already come in for a pre-tender budget, they must have a class A or B cost estimate.", TRUE, "") | EP10: =_xlfn.IFS(OR(AM10=0, AM10=""), "", AR10="", EP$7&" cannot be blank.", TRUE, "") -> Estimated Cost - Construction Project cannot be blank. | EQ10: =_xlfn.IFS(OR(AN10=0, AN10=""), "", AS10="", EQ$7&" cannot be blank.", TRUE, "") -> Estimated Cost - Land cannot be blank. | ER10: =_xlfn.IFS(OR(AO10=0, AO10=""), "", AT10="", ER$7&" cannot be blank.", TRUE, "") -> Estimated Cost - Demolition cannot be blank. | ES10: =_xlfn.IFS(OR(AP10=0, AP10=""), "", AU10="", ES$7&" cannot be blank.", TRUE, "") | EW10: =_xlfn.IFS(EX10<>"", EX10, EY10<>"", EY10, EZ10<>"", EZ10, TRUE, "") | EX10: =IF(J10="MISSING", "This package is missing!", "") | EY10: =IF(K10="", "Confirm you reviewed the pretender checkin documents", "") | EZ10: =IF(AND(K10="Not yet submitted/reviewed", J10<>"Not yet submitted/reviewed"), "Pretender package submitted; col 9 cann't indicate otherwise.", "") | FA10: =_xlfn.IFS(FB10<>"", FB10, FC10<>"", FC10, FD10<>"", FD10, TRUE, "") | FB10: =IF(N10="MISSING", "The post tender package is missing!", "") | FC10: =IF(O10="", "Confirm you reviewed the post tender check-in documents", "") | FD10: =IF(AND(O10="Not yet submitted/reviewed", N10<>"Not yet submitted/reviewed"), "Post-tender package submitted; col 9 cann't indicate otherwise.", "") | FE10: =_xlfn.IFS(FF10<>"", FF10, FG10<>"", FG10, TRUE, FH10) | FF10: =IF(P10<>"", "", "Site Ownership Status cannot be blank") | FG10: =_xlfn.IFS(AND(Q10="", OR(P10="Site Purchased Prior to Capital Approval", P10="Site Purchased")), "", AND(OR(P10="Site Purchased Prior to Capital Approval", P10="Site Purchased"), Q10>TODAY()), "Site purchase date is in the future, but site ownership status indicates site is already purchaseed", TRUE, "") | FH10: =IF(AND(AND(P10<>"Site Purchased Prior to Capital Approval", P10<>"Site Purchased"), Q10<=TODAY()), "Site purchase date is in the past, but site ownership status indicates site has not yet been purchaseed", "") | FI10: =_xlfn.IFS(FJ10<>"", FJ10, FK10<>"", FK10, TRUE,FL10 ) | FJ10: =IF(AND(P10<>"Not Applicable",Q10=""),"Site Purchased Date cannot be blank","") | FK10: =FE10 | FL10: =_xlfn.IFS(Q10="", "", U10="", "", Q10>U10, "Site Purchase Date must preceed Site Plan Submission.", TRUE, "")
A11: 40-017 | B11: Dante Alighieri Catholic Secondary School | C11: Construction underway - completing water tight. Utilities not connected at this point, but in the next few days. Enbridge working to get heat to the site. Waiting for windows. Hoping to have the building fully enclosed for end of February. Progressing well, no concerns with opening and budget. | D11: New Construction | E11: Accommodation Pressure | F11: In Progress | G11: =_xlfn.IFS($C$3>AK11, "Complete", $C$3>AG11, "Open", $C$3>AC11, "Under Construction", TRUE, "Planning") -> Under Construction | H11: 45140 | I11: Not Applicable | J11: Not Applicable | K11: Not Applicable | L11: 45245 | M11: Not Applicable | N11: Not Applicable | O11: Not Applicable | P11: Not Applicable | R11: >80% Complete | S11: 43692 | V11: 45531 | X11: 45531 | Z11: 45214 | AA11: 45245 | AB11: 45267 | AC11: 45338 | AE11: 46203 | AG11: 46273 | AK11: 46688 | AL11: =SUM(AM11:AP11) -> 62436028 | AM11: 60656214 | AO11: 1779814 | AQ11: Based on Tender Results | BD11: Dante construction is underway and on schedule. As of December, the project is not water tight, SB was hopignt ohave this complete before winter. Some windows in, frames are installed, glazing not finished, green roof not finished (some issues). If not water tight and winter sets in, there will be added costs. Still not 100% water tight. Amal to provide update next meeting re. if the project is water tight at that point. Working out utilities and encountering problems currently with Enbridge, Rogers etc. BOard has resolved Hydro issues at the moment. Supply challenges with elevators (vertex), SB has is using Vertex on six other schools (problem with low bidding). The Regina Mundi playground and parking lot is almost complete. City - placed a hold on digging underground along the street (due to recent paving), not sure how the u/g servicing will be done. Servicing may need to be above ground. Redesign needs to happen. This also happened with the Baycrest project - new trees planted where drop off area is designed to be. | BE11: Dante construction is underway and on schedule. At this point, the contractor has finished water tight, working on windows before the winter season. Working out utilities - Enbridge, Rogers etc. Supply challenges with elevators (vertex), other schools also have challeges with elevators. The Regina Mundi playground and parking lot is almost complete. | BF11: Dante construction is underway and on schedule. At this point, the contractor is working to have the building water tight (water proofing, windows in, roof complete) before the winter season. The Regina Mundi playground and parking lot is almost complete. | BG11: RMC Playground is almost complete. Gates might be installed at a later date. Dante construction is underway and on schedule. | CD11: =IF(AND(Q11="", A11<>"", P11<>"Site Purchased Prior to Capital Approval"), 1, 0) -> 1 | CE11: 0 | CF11: =_xlfn.XLOOKUP($A11, 'Project Commitment'!$A:$A, 'Project Commitment'!M:M, "") -> 0 | CG11: =_xlfn.XLOOKUP($A11, 'Project Commitment'!$A:$A, 'Project Commitment'!N:N, "") -> 0 | CH11: =_xlfn.XLOOKUP($A11, 'Project Commitment'!$A:$A, 'Project Commitment'!O:O, "") -> 0 | CI11: =_xlfn.XLOOKUP($A11, 'Project Commitment'!$A:$A, 'Project Commitment'!P:P, "") -> 0 | CJ11: =_xlfn.XLOOKUP($A11, 'Project Commitment'!$A:$A, 'Project Commitment'!Q:Q, "") -> 0 | CK11: =_xlfn.XLOOKUP($A11, 'Project Commitment'!$A:$A, 'Project Commitment'!R:R, "") -> 0 | CL11: =_xlfn.XLOOKUP($A11, 'Project Commitment'!$A:$A, 'Project Commitment'!S:S, "") -> #VALUE! | CM11: =_xlfn.XLOOKUP($A11, 'Project Commitment'!$A:$A, 'Project Commitment'!T:T, "") -> 0 | CN11: =_xlfn.XLOOKUP($A11, 'Project Commitment'!$A:$A, 'Project Commitment'!U:U, "") -> 22 | CO11: =_xlfn.XLOOKUP($A11, 'Project Commitment'!$A:$A, 'Project Commitment'!V:V, "") -> #VALUE! | CP11: =_xlfn.XLOOKUP($A11, 'Project Commitment'!$A:$A, 'Project Commitment'!W:W, "") -> 0 | CQ11: =_xlfn.XLOOKUP($A11, 'Project Commitment'!$A:$A, 'Project Commitment'!X:X, "") -> 0 | CR11: =_xlfn.XLOOKUP($A11, 'Project Commitment'!$A:$A, 'Project Commitment'!Y:Y, "") -> 0 | CS11: =_xlfn.XLOOKUP($A11, 'Project Commitment'!$A:$A, 'Project Commitment'!Z:Z, "") -> 0 | CT11: =_xlfn.XLOOKUP($A11, 'Project Commitment'!$A:$A, 'Project Commitment'!AA:AA, "") -> 0 | CU11: =_xlfn.XLOOKUP($A11, 'Project Commitment'!$A:$A, 'Project Commitment'!AB:AB, "") -> -50 | DA11: =IF(C11="", "Meeting Minutes cannot be blank", "") | DF11: =_xlfn.IFS(AND(J11="Not Applicable", H11<>""), "No date is needed if Column 10 is Not Applicable",J11= "Not Applicable", "", H11="",DF$7&" cannot be blank", $AC11="", "", H11>$AC11, DF$7&" must preceed construction start date.", TRUE, "") -> No date is needed if Column 10 is Not Applicable | DG11: =_xlfn.IFS(I11="", DG$7&" cannot be left blank.",H11="", "", AND( H11 < TODAY(), I11="Not Yet Known"), "After the submission date, the pre-tender package type must be selected.", TRUE, "") | DI11: =EW11 | DJ11: =_xlfn.IFS(AND(N11="Not Applicable", L11<>""), "No date is needed if Column 14 is Not Applicable",N11= "Not Applicable", "", L11="",DJ$7&" cannot be blank", $AC11="", "", L11>$AC11, DJ$7&" must preceed construction start date.", TRUE, "") -> No date is needed if Column 14 is Not Applicable | DK11: =_xlfn.IFS(M11="", DK$7&" cannot be left blank.",L11="", "", AND( L11 < TODAY(), M11="Not Yet Known"), "After the submission date, the pre-tender package type must be selected.", TRUE, "") | DM11: =FA11 | DN11: =FE11 | DO11: =FI11 | DP11: =IF(R11="", DP$7&" cannot be blank", "") | DQ11: =_xlfn.IFS(S11="",DQ$7&" cannot be blank",AND(J11<>"Not yet submitted/reviewed",S11>TODAY()),DQ$7&" cannot be in the future if project is ready for a pre-tender package.",TRUE,"") | DR11: =_xlfn.IFS(CE11=0, "", T11="",DR$7&" cannot be blank if project includes child care.", AND(J11="Not Applicable",T11>TODAY()), "Projects under construction must have a "&DR$7, J11="Not Applicable", "", T11<I11, T7&" must preceed pre-tender package submission date",TRUE, "") | DS11: =_xlfn.IFS(U11="",DS$7&" cannot be blank", $AC11="", "", U11>$AC11, DS$7&" must preceed construction start date.", TRUE, "") -> Initial Site Plan Submission Date cannot be blank | DT11: =_xlfn.IFS(W11<>"", "", V11="",DT$7&" cannot be blank", $AC11="", "", V11>$AC11, DT$7&" must preceed construction start date.", TRUE, "") -> Site Plan Approval Date must preceed construction start date. | DV11: =_xlfn.IFS(Y11<>"", "", X11="",DV$7&" cannot be blank", $AC11="", "", X11>$AC11, DV$7&" must preceed construction start date.", TRUE, "") -> Build Permit Obtained Date must preceed construction start date. | DX11: =_xlfn.IFS(Z11="",DX$7&" cannot be blank", $AC11="", "", Z11>$AC11, DX$7&" must preceed construction start date.", TRUE, "") | DY11: =_xlfn.IFS(AA11="",DY$7&" cannot be blank", $AC11="", "", AA11>$AC11, DY$7&" must preceed construction start date.", TRUE, "") | DZ11: =_xlfn.IFS(AB11="",DZ$7&" cannot be blank", $AC11="", "", AB11>$AC11, DZ$7&" must preceed construction start date.", TRUE, "") | EA11: =_xlfn.IFS(AD11<>"", "", AC11="",EA$7&" cannot be blank", $AG11="", "", AC11>EDATE($AG11,-12), EA$7&" must preceed school opening date by more than 12 months.", TRUE, "") | EC11: =_xlfn.IFS(AF11<>"", "", AE11="",EC$7&" cannot be blank", $AG11="", "", AE11>EDATE($AG11,-1), EC$7&" must preceed school opening date by more than one month.", TRUE, "") | EE11: =_xlfn.IFS(AK11="", "", AG11="",EE$7&" cannot be blank",AH11<>"", "", $AG11="", "", AG11>=EDATE($AK11,-11), EE$7&" must preceed financial close date by at least 12 months.", TRUE, "") | EG11: =_xlfn.IFS(CE11=0, "", AI11="",EG$7&" cannot be blank",$AK11="", "",AJ11<>"", "", AI11>=EDATE($AK11,0), EG$7&" must preceed financial close date.", TRUE, "") | EI11: =_xlfn.IFS( AK11="",EI$7&" cannot be blank", TRUE, "") | EO11: =_xlfn.IFS(AQ11="", "Basis of Cost Estimate cannot be blank", AND(AC11<TODAY(), AQ11<>"Based on Tender Results"), "Contract awarded date suggests estimate should be based on tender results", AND(H11<TODAY(), AQ11<>"Based on Class A or B Cost Report"), "If project has already come in for a pre-tender budget, they must have a class A or B cost estimate.", TRUE, "") -> If project has already come in for a pre-tender budget, they must have a class A or B cost estimate. | EP11: =_xlfn.IFS(OR(AM11=0, AM11=""), "", AR11="", EP$7&" cannot be blank.", TRUE, "") -> Estimated Cost - Construction Project cannot be blank. | EQ11: =_xlfn.IFS(OR(AN11=0, AN11=""), "", AS11="", EQ$7&" cannot be blank.", TRUE, "") | ER11: =_xlfn.IFS(OR(AO11=0, AO11=""), "", AT11="", ER$7&" cannot be blank.", TRUE, "") -> Estimated Cost - Demolition cannot be blank. | ES11: =_xlfn.IFS(OR(AP11=0, AP11=""), "", AU11="", ES$7&" cannot be blank.", TRUE, "") | EW11: =_xlfn.IFS(EX11<>"", EX11, EY11<>"", EY11, EZ11<>"", EZ11, TRUE, "") | EX11: =IF(J11="MISSING", "This package is missing!", "") | EY11: =IF(K11="", "Confirm you reviewed the pretender checkin documents", "") | EZ11: =IF(AND(K11="Not yet submitted/reviewed", J11<>"Not yet submitted/reviewed"), "Pretender package submitted; col 9 cann't indicate otherwise.", "") | FA11: =_xlfn.IFS(FB11<>"", FB11, FC11<>"", FC11, FD11<>"", FD11, TRUE, "") | FB11: =IF(N11="MISSING", "The post tender package is missing!", "") | FC11: =IF(O11="", "Confirm you reviewed the post tender check-in documents", "") | FD11: =IF(AND(O11="Not yet submitted/reviewed", N11<>"Not yet submitted/reviewed"), "Post-tender package submitted; col 9 cann't indicate otherwise.", "") | FE11: =_xlfn.IFS(FF11<>"", FF11, FG11<>"", FG11, TRUE, FH11) | FF11: =IF(P11<>"", "", "Site Ownership Status cannot be blank") | FG11: =_xlfn.IFS(AND(Q11="", OR(P11="Site Purchased Prior to Capital Approval", P11="Site Purchased")), "", AND(OR(P11="Site Purchased Prior to Capital Approval", P11="Site Purchased"), Q11>TODAY()), "Site purchase date is in the future, but site ownership status indicates site is already purchaseed", TRUE, "") | FH11: =IF(AND(AND(P11<>"Site Purchased Prior to Capital Approval", P11<>"Site Purchased"), Q11<=TODAY()), "Site purchase date is in the past, but site ownership status indicates site has not yet been purchaseed", "") | FI11: =_xlfn.IFS(FJ11<>"", FJ11, FK11<>"", FK11, TRUE,FL11 ) | FJ11: =IF(AND(P11<>"Not Applicable",Q11=""),"Site Purchased Date cannot be blank","") | FK11: =FE11 | FL11: =_xlfn.IFS(Q11="", "", U11="", "", Q11>U11, "Site Purchase Date must preceed Site Plan Submission.", TRUE, "")
A12: 40-076-01 | B12: St. Fidelis Catholic Elementary School | C12: School opened in September 2025, with a partial occupancy permit. Board still doesnt have full occupancy permit due to the elevator installation not completion. The child care centre construction is complete but part of licensing is that a full occupnancy permit is in place. The Elevator operator (Vertix) has not been to the site since September. They are billing for work that doesn’t match the work that has progressed to date. School board is working with legal team to remove the elevator contractor from the job. Once the legal has been sorted out and another elevator contractor can be hired and brought in,. Installation scheduling will need to be scheduled when students aren't in the facility. | D12: New Construction | E12: Accommodation Pressure | F12: In Progress | G12: =_xlfn.IFS($C$3>AK12, "Complete", $C$3>AG12, "Open", $C$3>AC12, "Under Construction", TRUE, "Planning") -> Open | I12: Not Applicable | J12: Not Applicable | K12: Not Applicable | M12: Not Applicable | N12: Not Applicable | O12: Not Applicable | P12: Site Purchased | Q12: 43525 | R12: >80% Complete | S12: 42408 | V12: 45194 | AB12: 44953 | AC12: 45065 | AE12: 45810 | AG12: 45902 | AI12: 46296 | AK12: 46689 | AL12: =SUM(AM12:AP12) -> 48842266 | AM12: 30245269 | AN12: 15750000 | AO12: 2846997 | AQ12: Based on Tender Results | BD12: School opened September 2, 2025, with partial occupancy - gymnasium and child care were not complete. Gymnasium was completed in November while child care centre is expected to open January 5, 2026. Board hopes to get occupancy of the building, but it wont be full occupancy due to the elevator not installed. Vertex dropped off the elevator equipment in the chlid care centre. The general contractor cant touch the equpment bc it becomes his responsibility. ...so the elevator equipment is sitting in the cc centre. General contractor is requesting "up front payment" for work not undertaken yet regarding the elevator. SB holding off on it. | BE12: School expected to open September 2, 2025. School opened with partial occupancy, not full occupancy, b/c gymnasium and child care were not complete. Currently contractor is working on construction deficiencies and finishing the licensing requirements for the child care centre. Child care centre is expected to open January 5, 2026. It is expected the school will have full occupnacy by end of November, at which point the child care and gymnasium will be in use. Gym should be complete for November. | BF12: School expected to open September 2, 2025. School opened with partial occupancy, not full occupancy, b/c gymnasium and child care were not complete. Currently contractor is working on construction deficiencies and finishing the licensing requirements for the child care centre. Child care centre is expected to open January 5, 2026. It is expected the school will have full occupnacy by end of November, at which point the child care and gymnasium will be in use. | BG12: School expected to open September 2, 2025. Child care centre is expected to open January 5, 2026, the delay is a result of licensing. | CD12: =IF(AND(Q12="", A12<>"", P12<>"Site Purchased Prior to Capital Approval"), 1, 0) -> 0 | CE12: 39 | CF12: =_xlfn.XLOOKUP($A12, 'Project Commitment'!$A:$A, 'Project Commitment'!M:M, "") -> 0 | CG12: =_xlfn.XLOOKUP($A12, 'Project Commitment'!$A:$A, 'Project Commitment'!N:N, "") -> 0 | CH12: =_xlfn.XLOOKUP($A12, 'Project Commitment'!$A:$A, 'Project Commitment'!O:O, "") -> 0 | CI12: =_xlfn.XLOOKUP($A12, 'Project Commitment'!$A:$A, 'Project Commitment'!P:P, "") -> 0 | CJ12: =_xlfn.XLOOKUP($A12, 'Project Commitment'!$A:$A, 'Project Commitment'!Q:Q, "") -> 0 | CK12: =_xlfn.XLOOKUP($A12, 'Project Commitment'!$A:$A, 'Project Commitment'!R:R, "") -> 0 | CL12: =_xlfn.XLOOKUP($A12, 'Project Commitment'!$A:$A, 'Project Commitment'!S:S, "") -> #VALUE! | CM12: =_xlfn.XLOOKUP($A12, 'Project Commitment'!$A:$A, 'Project Commitment'!T:T, "") -> 0 | CN12: =_xlfn.XLOOKUP($A12, 'Project Commitment'!$A:$A, 'Project Commitment'!U:U, "") -> 44953 | CO12: =_xlfn.XLOOKUP($A12, 'Project Commitment'!$A:$A, 'Project Commitment'!V:V, "") -> #VALUE! | CP12: =_xlfn.XLOOKUP($A12, 'Project Commitment'!$A:$A, 'Project Commitment'!W:W, "") -> 0 | CQ12: =_xlfn.XLOOKUP($A12, 'Project Commitment'!$A:$A, 'Project Commitment'!X:X, "") -> 0 | CR12: =_xlfn.XLOOKUP($A12, 'Project Commitment'!$A:$A, 'Project Commitment'!Y:Y, "") -> 39 | CS12: =_xlfn.XLOOKUP($A12, 'Project Commitment'!$A:$A, 'Project Commitment'!Z:Z, "") -> 0 | CT12: =_xlfn.XLOOKUP($A12, 'Project Commitment'!$A:$A, 'Project Commitment'!AA:AA, "") -> 0 | CU12: =_xlfn.XLOOKUP($A12, 'Project Commitment'!$A:$A, 'Project Commitment'!AB:AB, "") -> -422 | DA12: =IF(C12="", "Meeting Minutes cannot be blank", "") | DF12: =_xlfn.IFS(AND(J12="Not Applicable", H12<>""), "No date is needed if Column 10 is Not Applicable",J12= "Not Applicable", "", H12="",DF$7&" cannot be blank", $AC12="", "", H12>$AC12, DF$7&" must preceed construction start date.", TRUE, "") | DG12: =_xlfn.IFS(I12="", DG$7&" cannot be left blank.",H12="", "", AND( H12 < TODAY(), I12="Not Yet Known"), "After the submission date, the pre-tender package type must be selected.", TRUE, "") | DI12: =EW12 | DJ12: =_xlfn.IFS(AND(N12="Not Applicable", L12<>""), "No date is needed if Column 14 is Not Applicable",N12= "Not Applicable", "", L12="",DJ$7&" cannot be blank", $AC12="", "", L12>$AC12, DJ$7&" must preceed construction start date.", TRUE, "") | DK12: =_xlfn.IFS(M12="", DK$7&" cannot be left blank.",L12="", "", AND( L12 < TODAY(), M12="Not Yet Known"), "After the submission date, the pre-tender package type must be selected.", TRUE, "") | DM12: =FA12 | DN12: =FE12 | DO12: =FI12 | DP12: =IF(R12="", DP$7&" cannot be blank", "") | DQ12: =_xlfn.IFS(S12="",DQ$7&" cannot be blank",AND(J12<>"Not yet submitted/reviewed",S12>TODAY()),DQ$7&" cannot be in the future if project is ready for a pre-tender package.",TRUE,"") | DR12: =_xlfn.IFS(CE12=0, "", T12="",DR$7&" cannot be blank if project includes child care.", AND(J12="Not Applicable",T12>TODAY()), "Projects under construction must have a "&DR$7, J12="Not Applicable", "", T12<I12, T8&" must preceed pre-tender package submission date",TRUE, "") -> Child Care Floorplan Approval Date cannot be blank if project includes child care. | DS12: =_xlfn.IFS(U12="",DS$7&" cannot be blank", $AC12="", "", U12>$AC12, DS$7&" must preceed construction start date.", TRUE, "") -> Initial Site Plan Submission Date cannot be blank | DT12: =_xlfn.IFS(W12<>"", "", V12="",DT$7&" cannot be blank", $AC12="", "", V12>$AC12, DT$7&" must preceed construction start date.", TRUE, "") -> Site Plan Approval Date must preceed construction start date. | DV12: =_xlfn.IFS(Y12<>"", "", X12="",DV$7&" cannot be blank", $AC12="", "", X12>$AC12, DV$7&" must preceed construction start date.", TRUE, "") -> Build Permit Obtained Date cannot be blank | DX12: =_xlfn.IFS(Z12="",DX$7&" cannot be blank", $AC12="", "", Z12>$AC12, DX$7&" must preceed construction start date.", TRUE, "") -> Tender Issued Date cannot be blank | DY12: =_xlfn.IFS(AA12="",DY$7&" cannot be blank", $AC12="", "", AA12>$AC12, DY$7&" must preceed construction start date.", TRUE, "") -> Tender Closed Date cannot be blank | DZ12: =_xlfn.IFS(AB12="",DZ$7&" cannot be blank", $AC12="", "", AB12>$AC12, DZ$7&" must preceed construction start date.", TRUE, "") | EA12: =_xlfn.IFS(AD12<>"", "", AC12="",EA$7&" cannot be blank", $AG12="", "", AC12>EDATE($AG12,-12), EA$7&" must preceed school opening date by more than 12 months.", TRUE, "") | EC12: =_xlfn.IFS(AF12<>"", "", AE12="",EC$7&" cannot be blank", $AG12="", "", AE12>EDATE($AG12,-1), EC$7&" must preceed school opening date by more than one month.", TRUE, "") | EE12: =_xlfn.IFS(AK12="", "", AG12="",EE$7&" cannot be blank",AH12<>"", "", $AG12="", "", AG12>=EDATE($AK12,-11), EE$7&" must preceed financial close date by at least 12 months.", TRUE, "") | EG12: =_xlfn.IFS(CE12=0, "", AI12="",EG$7&" cannot be blank",$AK12="", "",AJ12<>"", "", AI12>=EDATE($AK12,0), EG$7&" must preceed financial close date.", TRUE, "") | EI12: =_xlfn.IFS( AK12="",EI$7&" cannot be blank", TRUE, "") | EO12: =_xlfn.IFS(AQ12="", "Basis of Cost Estimate cannot be blank", AND(AC12<TODAY(), AQ12<>"Based on Tender Results"), "Contract awarded date suggests estimate should be based on tender results", AND(H12<TODAY(), AQ12<>"Based on Class A or B Cost Report"), "If project has already come in for a pre-tender budget, they must have a class A or B cost estimate.", TRUE, "") | EP12: =_xlfn.IFS(OR(AM12=0, AM12=""), "", AR12="", EP$7&" cannot be blank.", TRUE, "") -> Estimated Cost - Construction Project cannot be blank. | EQ12: =_xlfn.IFS(OR(AN12=0, AN12=""), "", AS12="", EQ$7&" cannot be blank.", TRUE, "") -> Estimated Cost - Land cannot be blank. | ER12: =_xlfn.IFS(OR(AO12=0, AO12=""), "", AT12="", ER$7&" cannot be blank.", TRUE, "") -> Estimated Cost - Demolition cannot be blank. | ES12: =_xlfn.IFS(OR(AP12=0, AP12=""), "", AU12="", ES$7&" cannot be blank.", TRUE, "") | EW12: =_xlfn.IFS(EX12<>"", EX12, EY12<>"", EY12, EZ12<>"", EZ12, TRUE, "") | EX12: =IF(J12="MISSING", "This package is missing!", "") | EY12: =IF(K12="", "Confirm you reviewed the pretender checkin documents", "") | EZ12: =IF(AND(K12="Not yet submitted/reviewed", J12<>"Not yet submitted/reviewed"), "Pretender package submitted; col 9 cann't indicate otherwise.", "") | FA12: =_xlfn.IFS(FB12<>"", FB12, FC12<>"", FC12, FD12<>"", FD12, TRUE, "") | FB12: =IF(N12="MISSING", "The post tender package is missing!", "") | FC12: =IF(O12="", "Confirm you reviewed the post tender check-in documents", "") | FD12: =IF(AND(O12="Not yet submitted/reviewed", N12<>"Not yet submitted/reviewed"), "Post-tender package submitted; col 9 cann't indicate otherwise.", "") | FE12: =_xlfn.IFS(FF12<>"", FF12, FG12<>"", FG12, TRUE, FH12) | FF12: =IF(P12<>"", "", "Site Ownership Status cannot be blank") | FG12: =_xlfn.IFS(AND(Q12="", OR(P12="Site Purchased Prior to Capital Approval", P12="Site Purchased")), "", AND(OR(P12="Site Purchased Prior to Capital Approval", P12="Site Purchased"), Q12>TODAY()), "Site purchase date is in the future, but site ownership status indicates site is already purchaseed", TRUE, "") | FH12: =IF(AND(AND(P12<>"Site Purchased Prior to Capital Approval", P12<>"Site Purchased"), Q12<=TODAY()), "Site purchase date is in the past, but site ownership status indicates site has not yet been purchaseed", "") | FI12: =_xlfn.IFS(FJ12<>"", FJ12, FK12<>"", FK12, TRUE,FL12 ) | FJ12: =IF(AND(P12<>"Not Applicable",Q12=""),"Site Purchased Date cannot be blank","") | FK12: =FE12 | FL12: =_xlfn.IFS(Q12="", "", U12="", "", Q12>U12, "Site Purchase Date must preceed Site Plan Submission.", TRUE, "")
