Workbook

Sheet form
A1: monthly_v2.0

Sheet Glossary
A1: Section 1: Project Details | B1: Definition
A2: Project ID | B2: Each project is assigned a unique ID for tracking throughout its lifecycle. Projects with a demolition component require a separate ID for the demolition
A3: Project Name | B3: The official name or title of the project.
A4: Address | B4: The specific location or physical address where the project is situated or being carried out.
A5: City | B5: The city in which the project is located
A6: Postal Code | B6: A series of letters, numbers, or both, assigned to a specific geographic area by the postal service.
A7: Project Type | B7: A classification that describes the nature or scope of the project. Project types include: (1) New Construction, (2) Retrofit, (3) Addition, (4) Other, (5) Land Acquisition, (6) Demolition, (7) Purchase
A8: Project Category | B8: A broader classification that groups the project within a certain area or field. Project categories include: (1) Accommodation Pressure, (2) ASD Pilot Project, (3) Child Care, (4) Community Based CC, (5) Condition, (6) Consolidation, (7) FDK, (8) FL Capital Transitional, (9) Other
A9: Project Status | B9: The project status indicates where the project stands with the ministry. Project statuses include: "Under Ministry Review," "In Progress", "Removed from tracker (Cancelled)", "Removed from tracker (Complete)".
A10: Construction Status | B10: Construction status refers to the current stage or condition of a construction project. It provides an update on whete the project stands in its lifecycle includes stages such as "Planning," Pre-Procurement," "Completed," "On Hold," or "Cancelled
A11: Planning | B11: This stage of construction will encompass all the work required during the planning stage of a process. This planning process extends from the conception of the project to when the board hires the architect to desgin the project.
A12: Pre-Procurement | B12: This stage of the construction process encompasses all activities following the planning phase to get the project ready for tender. This stage includes sourcing and qualifying general contractors, site plan application process, addressing budget constraints, environmental assessments, and any legal/contractual issues.
... A20: Project Reconciliation | B20: Project reconciliation is the process that ensures all financial records and project activities align accurately at the end of the project. The school will be reviewing expenses, identifying discrepancies, settling change orders, and roviding the ministry with final reporting.
A21: Section 2: Square Footage Specification
A22: Anticipate Design Change? | B22: Whether the school board anticipate needing to change the design of the project. This would required an approval from the ministry.
A23: Square Footage of New Construction | B23: The school board to confirm the size of the project
A24: Square Footage of Renovation/Retrofit | B24: The school board to confirm the size of the renovation/retrofit
A25: Square Footage of Demolition | B25: The school board to confirm the size of the demolition
A26: Square Footage of New Child Care | B26: The school board to confirm the size of the new child care
A27: Square Footage of EarlyOn | B27: The school board to confirm the size of the EarlyOn
A28: Section 3: Phase 1- Pre-Tender
A29: Site Ownership Status | B29: The school board needs to confirm the status of the site ownership
A30: Not Site Identified | B30: The board requires a site but has not found one yet
A31: Site Identified Only | B31: The school has only identified the site
A32: Site under option agreement | B32: The site has been identified and is under contract (but not obligation) to sell/buy an asset at a predetermined price.
A33: Site Purchased | B33: The school board has purchased the site needed for the project
A34: Not Applicable | B34: Site requirements do not apply to the project
A35: Site Purchase Date | B35: This is the date the site ownership transfer has occurred.
A36: Space Template Approval Date | B36: This is the date the space template was approved by the Ministry. If the date is yet to be approved, please enter an estimated date.
A37: Type of Designed Used | B37: A drop down for CAs to select the type of design used for the project. Options include: "New", "Repeat" (short for another repeat design), "EDU Catalogue"
A38: Design Status | B38: A drop down for CAs to update the status of design completion
A39: Class A/B Cost Estimate- Date | B39: This is the date the board submitted their class A/B cost estimate to the ministry.
A40: Child Care Floorplan Approval - Date | B40: This is the date the board received their child care floor plan approval.
A41: Site, Design and Child Care Related Comments | B41: A general comment box for analysts to provide useful information regarding site, design and child care related items.
A42: Section 4: Phase 2 - Tender
A43: Site Plan Submisison Date | B43: This is the date the school board started their site plan application with the municipality.
A44: Site Plan Approval Date | B44: This is the date the school board received their site plan approval.
A45: Build Permit Obtained Date | B45: This is the date the school board received their building permit which allows them to begin construction or renovation on a property.
A46: Tender Issued Date | B46: This is the date the school board formally invites contractors to submit bids or proposals for the construction project.
A47: Tender Closed Date | B47: This is the date the school board closes the bidding and proposals for the project has ended.
...

Sheet Board Contacts
A1: School Board Contact List
A4: Name | B4: Role | C4: Title | D4: Email | E4: Phone
A5: *((tbl*((board_contacts*((col*((name | B5: *((col*((role | C5: *((col*((title | D5: *((col*((email | E5: *((col*((phone

Sheet Monthly Update
A1: Monthly Project Updates
A2: *((var*((board_number_name | E2: *((var*((missing_data_count*((formula*((right | F2: =COLUMNS($D$3:$AI$3) - COUNTIF($D$3:$AI$3, "") -> 1 | J2: =IF($BQ$11, "Date Missing Here", "") -> #VALUE!
A3: Meeting Date | C3: *((var*((date_meeting | H3: =IF(COUNTBLANK($A$9:$A$100)=COUNTBLANK(H9:H100),"","Data Missing Here") | I3: =IF(COUNTBLANK($A$9:$A$100)=COUNTBLANK(I9:I100),"","Data Missing Here") | J3: *((var*((temp_site_purchase_formula*((formula*((up | K3: =IF(COUNTBLANK($A$9:$A$100)=COUNTBLANK(K9:K100),"","Date Missing Here") | M3: =IF(COUNTBLANK($A$9:$A$100)=COUNTBLANK(M9:M100),"","Date Missing Here") | N3: =IF(COUNTBLANK($A$9:$A$100)=COUNTBLANK(N9:N100),"","Date Missing Here") | O3: =IF(COUNTBLANK($A$9:$A$100)=COUNTBLANK(O9:O100),"","Date Missing Here") | P3: =IF(COUNTBLANK($A$9:$A$100)=COUNTBLANK(P9:P100),"","Date Missing Here") | Q3: =IF(COUNTBLANK($A$9:$A$100)=COUNTBLANK(Q9:Q100),"","Date Missing Here") | R3: =IF(COUNTBLANK($A$9:$A$100)=COUNTBLANK(R9:R100),"","Date Missing Here") | S3: =IF(COUNTBLANK($A$9:$A$100)=COUNTBLANK(S9:S100),"","Date Missing Here") | T3: =IF(COUNTBLANK($A$9:$A$100)=COUNTBLANK(T9:T100),"","Date Missing Here") | ... Y3: =IF(COUNTBLANK($A$9:$A$100)=COUNTBLANK(Y9:Y100),"","Date Missing Here") | AE3: =IF(COUNTBLANK($A$9:$A$100)=COUNTBLANK(AE9:AE100),"","Data Missing Here") | AF3: =IF(COUNTBLANK($A$9:$A$100)=COUNTBLANK(AF9:AF100),"","Data Missing Here") | AG3: =IF(COUNTBLANK($A$9:$A$100)=COUNTBLANK(AG9:AG100),"","Data Missing Here") | AH3: =IF(COUNTBLANK($A$9:$A$100)=COUNTBLANK(AH9:AH100),"","Data Missing Here") | AI3: =IF(COUNTBLANK($A$9:$A$100)=COUNTBLANK(AI9:AI100),"","Data Missing Here")
A4: Section 1: Project Details | H4: Section 3: Phase 1 - Pre-Tender | M4: Section 4: Phase 2 - Tender | T4: Section 5: Phase 3 - Construction | W4: Section 6: Phase 4 - Project Completion | Z4: Section 7: Approved Project Funding | AE4: Section 8: Projected Cost | AJ4: Section 10: Project Risks and Mitigation Stategies | AR4: Section 9: Historical Meeting Minutes
A5: ="Col "&COLUMN() -> Col 1 | B5: ="Col "&COLUMN() -> Col 2 | C5: ="Col "&COLUMN() -> Col 3 | D5: ="Col "&COLUMN() -> Col 4 | E5: ="Col "&COLUMN() -> Col 5 | F5: ="Col "&COLUMN() -> Col 6 | G5: ="Col "&COLUMN() -> Col 7 | H5: ="Col "&COLUMN() -> Col 8 | ... AJ5: ="Col "&COLUMN() -> Col 36 | AQ5: ="Col "&COLUMN() -> Col 43 | AR5: ="Col "&COLUMN() -> Col 44 | AS5: ="Col "&COLUMN() -> Col 45 | AT5: ="Col "&COLUMN() -> Col 46 | AU5: ="Col "&COLUMN() -> Col 47 | AV5: ="Col "&COLUMN() -> Col 48 | AW5: ="Col "&COLUMN() -> Col 49 | AX5: ="Col "&COLUMN() -> Col 50 | ... BO5: ="Col "&COLUMN() -> Col 67
A6: Project ID | B6: Project Name | C6: Meeting Minutes | D6: Project Type | E6: Project Category | F6: Record Status | G6: Construction Status | H6: Site Ownership Status | I6: Design Status | J6: Site Purchase Date | K6: Space Template Approval Date | L6: Child Care Floorplan Approval - Date | M6: Site Plan Submission Date | N6: Site Plan Approval Date | O6: Build Permit Obtained | P6: Pre-Tender Check-In Date | Q6: Tender Issued Date | R6: Tender Closed | S6: Post-Tender Check-In | T6: Contract Awarded | U6: Construction Start - Date | V6: Substantial Completion | W6: School Opening Date | X6: Child Care Opening Date | Y6: Financial Close-Out | Z6: Funding - All Associated Projects | AA6: Funding - Construction Project | AB6: Funding - Site Acquisition | AC6: Funding - Demolition | AD6: Funding - All Other Associated Projects | AE6: Basis of Cost Estimate | AF6: Estimated Cost - Construction Project | AG6: Estimated Cost - Land | AH6: Estimated Cost - Demolition | AI6: Estimated Cost - All Other Associated Projects | AJ6: Risk Type | AK6: Risk Rating | AL6: Risk Exposure Start Date | AM6: Min Cost of Risk ($M) | AN6: Max Cost of Risk ($M) | AO6: Min Delay of Risk (Months) | AP6: Max Delay of Risk (Months) | AQ6: Mitigation Stategies/Comments | AR6: ="*((tbl*((meeting_minutes_heading"&AR9 -> *((tbl*((meeting_minutes_heading*((col*((meeting_minutes_minus_1 | AS6: =AS9 -> *((col*((meeting_minutes_minus_2 | AT6: =AT9 -> *((col*((meeting_minutes_minus_3 | AU6: =AU9 -> *((col*((meeting_minutes_minus_4 | AV6: =AV9 -> *((col*((meeting_minutes_minus_5 | AW6: =AW9 -> *((col*((meeting_minutes_minus_6 | AX6: =AX9 -> *((col*((meeting_minutes_minus_7 | AY6: =AY9 -> *((col*((meeting_minutes_minus_8 | AZ6: =AZ9 -> *((col*((meeting_minutes_minus_9 | ... BO6: =BO9 -> *((col*((meeting_minutes_minus_24 | BQ6: *((table_end*((meeting_minutes_heading | BS6: cc_amount | BT6: ='Project Commitment'!M4 -> Site Purchase Date | BU6: ='Project Commitment'!N4 -> Space Template Approval Date | BV6: ='Project Commitment'!O4 -> Child Care Floorplan Approval - Date | BW6: ='Project Commitment'!P4 -> Site Plan Submission Date | BX6: ='Project Commitment'!Q4 -> Site Plan Approval Date | BY6: ='Project Commitment'!R4 -> Build Permit Obtained | BZ6: ='Project Commitment'!S4 -> Pre-Tender Check-In Date | CA6: ='Project Commitment'!T4 -> Tender Issued Date | ... CI6: ='Project Commitment'!AB4 -> Financial Close-Out
A7: No. de projet | B7: Nom du projet | D7: Type de projet | E7: Catégorie de projet | AB7: IP | AC7: Service de garde | AD7: Autre | AE7: Base de l'estimation des coûts | AI7: Coûts du site
A9: *((tbl*((monthly*((col*((project_id | B9: *((col*((project_name | C9: *((col*((meeting_minutes | D9: *((col*((project_type | E9: *((col*((project_category | F9: *((col*((record_status | G9: *((col*((construction_status*((formula*((down | H9: *((col*((site_status | I9: *((col*((design_status | J9: *((col*((date_site_purchase | K9: *((col*((date_space_template | L9: *((col*((date_cc_floorplan | M9: *((col*((date_site_plan_submission | N9: *((col*((date_site_plan_approved | O9: *((col*((date_building_permit | P9: *((col*((date_pretender | Q9: *((col*((date_tender_issue | R9: *((col*((date_tender_closed | S9: *((col*((date_posttender | T9: *((col*((date_tender | U9: *((col*((date_construction | V9: *((col*((date_substantial_completion | W9: *((col*((date_opening | X9: *((col*((date_opening_cc | Y9: *((col*((date_completion | Z9: *((col*((funding_all*((formula*((down | AA9: *((col*((funding_construction | AB9: *((col*((funding_site | AC9: *((col*((funding_demo | AD9: *((col*((funding_other_projects | AE9: *((col*((cost_basis | AF9: *((col*((cost_estimate_construction | AG9: *((col*((cost_estimate_land | AH9: *((col*((cost_estimate_demo | AI9: *((col*((cost_estimate_other_projects | AJ9: *((col*((risk_type | AK9: *((col*((risk_rating | AL9: *((col*((risk_date_start | AM9: *((col*((risk_cost_min | AN9: *((col*((risk_cost_max | AO9: *((col*((risk_delay_min | AP9: *((col*((risk_delay_max | AQ9: *((col*((risk_mitigation | AR9: *((col*((meeting_minutes_minus_1 | AS9: *((col*((meeting_minutes_minus_2 | AT9: *((col*((meeting_minutes_minus_3 | AU9: *((col*((meeting_minutes_minus_4 | AV9: *((col*((meeting_minutes_minus_5 | AW9: *((col*((meeting_minutes_minus_6 | AX9: *((col*((meeting_minutes_minus_7 | AY9: *((col*((meeting_minutes_minus_8 | AZ9: *((col*((meeting_minutes_minus_9 | BA9: *((col*((meeting_minutes_minus_10 | BB9: *((col*((meeting_minutes_minus_11 | BC9: *((col*((meeting_minutes_minus_12 | BD9: *((col*((meeting_minutes_minus_13 | BE9: *((col*((meeting_minutes_minus_14 | BF9: *((col*((meeting_minutes_minus_15 | BG9: *((col*((meeting_minutes_minus_16 | BH9: *((col*((meeting_minutes_minus_17 | BI9: *((col*((meeting_minutes_minus_18 | BJ9: *((col*((meeting_minutes_minus_19 | BK9: *((col*((meeting_minutes_minus_20 | BL9: *((col*((meeting_minutes_minus_21 | BM9: *((col*((meeting_minutes_minus_22 | BN9: *((col*((meeting_minutes_minus_23 | BO9: *((col*((meeting_minutes_minus_24 | BR9: *((col*((site_ownership_formula*((formula*((down | BS9: *((col*((funding_cc | BT9: ="*((col*((temp_formula_"&COLUMN()&"*((formula*((down" -> *((col*((temp_formula_72*((formula*((down | BU9: ="*((col*((temp_formula_"&COLUMN()&"*((formula*((down" -> *((col*((temp_formula_73*((formula*((down | BV9: ="*((col*((temp_formula_"&COLUMN()&"*((formula*((down" -> *((col*((temp_formula_74*((formula*((down | BW9: ="*((col*((temp_formula_"&COLUMN()&"*((formula*((down" -> *((col*((temp_formula_75*((formula*((down | BX9: ="*((col*((temp_formula_"&COLUMN()&"*((formula*((down" -> *((col*((temp_formula_76*((formula*((down | BY9: ="*((col*((temp_formula_"&COLUMN()&"*((formula*((down" -> *((col*((temp_formula_77*((formula*((down | BZ9: ="*((col*((temp_formula_"&COLUMN()&"*((formula*((down" -> *((col*((temp_formula_78*((formula*((down | CA9: ="*((col*((temp_formula_"&COLUMN()&"*((formula*((down" -> *((col*((temp_formula_79*((formula*((down | ... CI9: ="*((col*((temp_formula_"&COLUMN()&"*((formula*((down" -> *((col*((temp_formula_87*((formula*((down
G10: {=_xlfn.IFS($C$3>Y10, "Complete", $C$3>W10, "Open", $C$3>U10, "Under Construction", TRUE, "Planning")} -> Complete | Z10: =SUM(AA10:AD10) -> 0 | BR10: =IF(AND(J10="", A10<>"", H10<>"Site Purchased Prior to Capital Approval"), 1, 0) -> 0 | BT10: =_xlfn.XLOOKUP($A10, 'Project Commitment'!$A:$A, 'Project Commitment'!M:M, "") -> 0 | BU10: =_xlfn.XLOOKUP($A10, 'Project Commitment'!$A:$A, 'Project Commitment'!N:N, "") -> 0 | BV10: =_xlfn.XLOOKUP($A10, 'Project Commitment'!$A:$A, 'Project Commitment'!O:O, "") -> 0 | BW10: =_xlfn.XLOOKUP($A10, 'Project Commitment'!$A:$A, 'Project Commitment'!P:P, "") -> 0 | BX10: =_xlfn.XLOOKUP($A10, 'Project Commitment'!$A:$A, 'Project Commitment'!Q:Q, "") -> 0 | BY10: =_xlfn.XLOOKUP($A10, 'Project Commitment'!$A:$A, 'Project Commitment'!R:R, "") -> 0 | BZ10: =_xlfn.XLOOKUP($A10, 'Project Commitment'!$A:$A, 'Project Commitment'!S:S, "") -> 0 | CA10: =_xlfn.XLOOKUP($A10, 'Project Commitment'!$A:$A, 'Project Commitment'!T:T, "") -> 0 | CB10: =_xlfn.XLOOKUP($A10, 'Project Commitment'!$A:$A, 'Project Commitment'!U:U, "") -> 0 | CC10: =_xlfn.XLOOKUP($A10, 'Project Commitment'!$A:$A, 'Project Commitment'!V:V, "") -> 0 | CD10: =_xlfn.XLOOKUP($A10, 'Project Commitment'!$A:$A, 'Project Commitment'!W:W, "") -> 0 | CE10: =_xlfn.XLOOKUP($A10, 'Project Commitment'!$A:$A, 'Project Commitment'!X:X, "") -> 0 | CF10: =_xlfn.XLOOKUP($A10, 'Project Commitment'!$A:$A, 'Project Commitment'!Y:Y, "") -> 0 | CG10: =_xlfn.XLOOKUP($A10, 'Project Commitment'!$A:$A, 'Project Commitment'!Z:Z, "") -> 0 | CH10: =_xlfn.XLOOKUP($A10, 'Project Commitment'!$A:$A, 'Project Commitment'!AA:AA, "") -> 0 | CI10: =_xlfn.XLOOKUP($A10, 'Project Commitment'!$A:$A, 'Project Commitment'!AB:AB, "") -> 0
BQ11: *((var*((true_false_formula*((formula*((down
BQ12: =SUM($BR$9:$BR$100) <>0 -> FALSE

Sheet Basic Project Info
A1: Basic Project Information
A2: =Translation!A5 -> Section 1: Project Details | L2: =Translation!A68 -> Section 9: Communications Protocol | N2: =Translation!A72 -> Section 10: Project Risks and Mitigation Stategies | V2: =Translation!A71 -> Section 10: General Comments
A3: ="Col "&COLUMN() -> Col 1 | B3: ="Col "&COLUMN() -> Col 2 | C3: ="Col "&COLUMN() -> Col 3 | D3: ="Col "&COLUMN() -> Col 4 | E3: ="Col "&COLUMN() -> Col 5 | F3: ="Col "&COLUMN() -> Col 6 | G3: ="Col "&COLUMN() -> Col 7 | H3: ="Col "&COLUMN() -> Col 8 | ... N3: ="Col "&COLUMN() -> Col 14 | U3: ="Col "&COLUMN() -> Col 21 | V3: ="Col "&COLUMN() -> Col 22
A4: =Translation!A6 -> Project ID | B4: Board Name | C4: =Translation!A7 -> Project Name | D4: Official School Name | E4: =Translation!A11 -> Project Type | F4: =Translation!A13 -> Project Category | G4: =Translation!A8 -> Address | H4: =Translation!A9 -> City | I4: =Translation!A10 -> Postal Code | J4: Latitude | K4: Longitude | L4: Sign Installed | M4: =Translation!A70 -> Opening Ceremony - Date | N4: =Translation!A73 -> Risk Type | O4: =Translation!A74 -> Risk Rating | P4: =Translation!A75 -> Risk Exposure Start Date | Q4: Min Cost of Risk ($M) | R4: Max Cost of Risk ($M) | S4: Min Delay of Risk (Months) | T4: Max Delay of Risk (Months) | U4: =Translation!A78 -> Mitigation Stategies/Comments | V4: =Translation!A79 -> CA Comments
A5: No. de projet | C5: Nom du projet | E5: Type de projet | F5: Catégorie de projet
A6: project.id | C6: project.name | E6: project.type | F6: project.category | L6: Signage | M6: opening.ceremony | N6: comments | V6: comments
A7: *((tbl*((basic_project_info*((col*((project_id | B7: Rainbow DSB | C7: *((col*((project_name | D7: *((col*((project_name_official | E7: *((col*((project_type | F7: *((col*((project_category | G7: *((col*((location_address | H7: *((col*((location_city | I7: *((col*((location_postal_code | J7: *((col*((location_latitude | K7: *((col*((location_longitude | L7: *((col*((sign_installed | M7: *((col*((date_opening_ceremony | V7: *((col*((basic_project_info_comments
N16: Remove? | O16: Remove? | P16: Remove? | Q16: Remove? | R16: Remove? | S16: Remove? | T16: Remove? | U16: Remove?

Sheet Ad-Hoc or Potential Projects
A1: Ad-hoc & Potential Projects
A2: Parent ID | B2: Project ID | C2: Project Name | D2: Submission Type | E2: Project Type | F2: Year Open | G2: Project Category | H2: Project Type | I2: Timing | J2: Cost | K2: Funding Source | L2: Comments
B3: 99-123 | C3: Example Project | D3: Ad Hoc | E3: Land | F3: 2025 | G3: Accommodation Pressure | H3: Land

Sheet Project Commitment
A1: Project Commitments
A2: English | B2: =COLUMN() -> 2 | C2: =COLUMN() -> 3 | D2: =COLUMN() -> 4 | E2: =COLUMN() -> 5 | F2: =COLUMN() -> 6 | G2: =COLUMN() -> 7 | H2: =COLUMN() -> 8 | I2: =COLUMN() -> 9 | ... L2: =COLUMN() -> 12
A3: =Translation!A97 -> Project Info | C3: =Translation!A110 -> Key Milestones
A4: =Translation!A99 -> Project ID | B4: =Translation!A100 -> Project Name | C4: =Translation!A111 -> Site Purchase | D4: Space Template Approved | E4: Site Plan Approved | F4: Pre-Tender Checkin | G4: Tender Approved | H4: Post-Tender Checkin | I4: Construction Start | J4: Substantial Completion | K4: =Translation!A120 -> School/Addition Opening | L4: Financial Close | M4: ='Monthly Update'!J6 -> Site Purchase Date | N4: ='Monthly Update'!K6 -> Space Template Approval Date | O4: ='Monthly Update'!L6 -> Child Care Floorplan Approval - Date | P4: ='Monthly Update'!M6 -> Site Plan Submission Date | Q4: ='Monthly Update'!N6 -> Site Plan Approval Date | R4: ='Monthly Update'!O6 -> Build Permit Obtained | S4: ='Monthly Update'!P6 -> Pre-Tender Check-In Date | T4: ='Monthly Update'!Q6 -> Tender Issued Date | ... AB4: ='Monthly Update'!Y6 -> Financial Close-Out
A5: *((tbl*((pc*((col*((project_id | B5: *((col*((project_name | C5: *((col*((date_site_purchase | D5: *((col*((date_space_template | E5: *((col*((date_site_plan_approved | F5: *((col*((date_pretender | G5: *((col*((date_tender | H5: *((col*((date_posttender | I5: *((col*((date_construction | J5: *((col*((date_substantial_completion | K5: *((col*((date_opening | L5: *((col*((date_completion | M5: =C5&"_comparison*((formula*((down" -> *((col*((date_site_purchase_comparison*((formula*((down | N5: =D5&"_comparison*((formula*((down" -> *((col*((date_space_template_comparison*((formula*((down | O5: =E5&"_comparison*((formula*((down" -> *((col*((date_site_plan_approved_comparison*((formula*((down | P5: =F5&"_comparison*((formula*((down" -> *((col*((date_pretender_comparison*((formula*((down | Q5: =G5&"_comparison*((formula*((down" -> *((col*((date_tender_comparison*((formula*((down | R5: =H5&"_comparison*((formula*((down" -> *((col*((date_posttender_comparison*((formula*((down | S5: =I5&"_comparison*((formula*((down" -> *((col*((date_construction_comparison*((formula*((down | T5: =J5&"_comparison*((formula*((down" -> *((col*((date_substantial_completion_comparison*((formula*((down | ... AB5: =R5&"_comparison*((formula*((down" -> *((col*((date_posttender_comparison*((formula*((down_comparison*((formula*((down
M6: =C6-SUMIF('Monthly Update'!$A:$A,'Project Commitment'!$A6, 'Monthly Update'!J:J) -> 0 | N6: =D6-SUMIF('Monthly Update'!$A:$A,'Project Commitment'!$A6, 'Monthly Update'!K:K) -> 0 | O6: =0 -> 0 | P6: =0 -> 0 | Q6: =E6-SUMIF('Monthly Update'!$A:$A,'Project Commitment'!$A6, 'Monthly Update'!N:N) -> 0 | R6: =0 -> 0 | S6: =F6-SUMIF('Monthly Update'!$A:$A,'Project Commitment'!$A6, 'Monthly Update'!P:P) -> 0 | T6: =0 -> 0 | U6: =G6-SUMIF('Monthly Update'!$A:$A,'Project Commitment'!$A6, 'Monthly Update'!R:R) -> 0 | V6: =H6-SUMIF('Monthly Update'!$A:$A,'Project Commitment'!$A6, 'Monthly Update'!S:S) -> 0 | W6: =0 -> 0 | X6: =I6-SUMIF('Monthly Update'!$A:$A,'Project Commitment'!$A6, 'Monthly Update'!U:U) -> 0 | Y6: =J6-SUMIF('Monthly Update'!$A:$A,'Project Commitment'!$A6, 'Monthly Update'!V:V) -> 0 | Z6: =K6-SUMIF('Monthly Update'!$A:$A,'Project Commitment'!$A6, 'Monthly Update'!W:W) -> 0 | AA6: =0 -> 0 | AB6: =L6-SUMIF('Monthly Update'!$A:$A,'Project Commitment'!$A6, 'Monthly Update'!Y:Y) -> 0

Sheet Constants
A1: Constants
A3: Orange Date | B3: =-365*0.75 -> -273.75
A4: Red Date | B4: -365

Sheet List
A1: Actual/Estimated | B1: Language | C1: Construction Status | D1: Phase | E1: Yes / No | F1: Site Ownership Status | G1: Design Status | H1: Cost Basis | I1: Design | J1: Site Plan | K1: Project Category | L1: Project Type
A2: Actual | B2: English | C2: Planning | D2: 1 | E2: Yes / Oui | F2: No Site Identified | G2: <30% Complete | H2: Board Estimate | I2: New | J2: Yes/Oui | K2: Accommodation Pressure | L2: Land
A3: Estimate | B3: French | C3: Pre-Procurement | D3: 1 | E3: No / Non | F3: Site Identified Only | G3: 30%-80% Complete | H3: Repeat Design | I3: Repeat | J3: No/Non | K3: Facility Condition | L3: New School
C4: Tender Issuance | D4: 1 | E4: Not Applicable | F4: Site Under Option Agreement | G4: >80% Complete | H4: Architect Estimate | I4: EDU Catalogue | K4: School Consolidation | L4: Addition
C5: Tender Closed | D5: 1 | F5: Site Purchased | H5: Class D Estimate | K5: French Language Access | L5: Renovation
C6: Contract Awarded | D6: 1 | F6: Site Purchased Prior to Capital Approval | H6: Class C Estimate | K6: Other | L6: Disposition
C7: Site Preparation | D7: 2 | H7: Class B Estimate | L7: Demolition
C8: Construction | D8: 2 | H8: Class A Estimate | L8: Purchase
C9: Substantial Completion | D9: 3 | H9: Tender Results | L9: Other
C10: Completion | D10: 4
C11: Cost Reconciliation
A13: % Construction Progress | C13: Phase (List) | D13: Project Status | E13: Submission Type | F13: Project Risks | G13: Risk Rating | H13: Site Funding Source | I13: Mitigation Strategies
A14: 10 | C14: 0 | D14: In Progress | E14: CP | F14: Cost | G14: Low | H14: EDC | I14: Accept
A15: 20 | C15: 1 | D15: Remove from tracker (Cancelled) | E15: Ad Hoc | F15: Delay | G15: Medium | H15: LP | I15: Mitigate
A16: 30 | C16: 2 | D16: Remove from tracker (Complete) | F16: Delay/Cost | G16: High | H16: LP/EDC | I16: Transfer
A17: 40 | C17: 3 | I17: Avoid
A18: 50 | C18: 4 | F18: Market Risk
A19: 60 | F19: Governance Risk
A20: 70 | F20: Organization/Project Management Risk
A21: 80 | F21: Design Risk
A22: 90 | F22: Procurement/Tender Risk
A23: 100 | F23: Site Readiness/Enabling Works
F24: Permit, Licenses and Approvals
A25: Type of Design | F25: Construction Risk
A26: New | F26: Testing and Commissioning
A27: Repeat
A28: Catalogue
B32: Primary Contact
B33: Senior Buisness Official
B34: Director of Education
B35: Finance Contact
B36: Construction/Project Management Contact

Sheet Translation
A1: ='Project Commitment'!A2 -> English
A2: Output | B2: English | C2: French
A3: Monthly Update Sheet
A4: =IF($A$1="English",B4,C4) -> Meeting Date | B4: Meeting Date
A5: =IF($A$1="English",B5,C5) -> Section 1: Project Details | B5: Section 1: Project Details | C5: Détails associés aux projets
A6: =IF($A$1="English",B6,C6) -> Project ID | B6: Project ID
A7: =IF($A$1="English",B7,C7) -> Project Name | B7: Project Name
A8: =IF($A$1="English",B8,C8) -> Address | B8: Address
A9: =IF($A$1="English",B9,C9) -> City | B9: City
A10: =IF($A$1="English",B10,C10) -> Postal Code | B10: Postal Code
A11: =IF($A$1="English",B11,C11) -> Project Type | B11: Project Type
A12: =IF($A$1="English",B12,C12) -> Approval Period | B12: Approval Period
A13: =IF($A$1="English",B13,C13) -> Project Category | B13: Project Category
A14: =IF($A$1="English",B14,C14) -> Project Status | B14: Project Status
A15: =IF($A$1="English",B15,C15) -> Construction Status | B15: Construction Status
A16: =IF($A$1="English",B16,C16) -> Section 2: Square Footage Specification | B16: Section 2: Square Footage Specification
A17: =IF($A$1="English",B17,C17) -> Anticipate Design Change? | B17: Anticipate Design Change?
... A45: =IF($A$1="English",B45,C45) -> Project Reconciliation | B45: Project Reconciliation
A46: =IF($A$1="English",B46,C46) -> Section 7: Approved Project Funding | B46: Section 7: Approved Project Funding | C46: Financement approuvé du projet
A47: =IF($A$1="English",B47,C47) -> LP/EDC | B47: LP/EDC
A48: =IF($A$1="English",B48,C48) -> CP | B48: CP
A49: =IF($A$1="English",B49,C49) -> CC | B49: CC
A50: =IF($A$1="English",B50,C50) -> Other | B50: Other
A51: =IF($A$1="English",B51,C51) -> Total Approved Funding | B51: Total Approved Funding
A52: =IF($A$1="English",B52,C52) -> Section 8: Projected Construction Cost | B52: Section 8: Projected Construction Cost | C52: Coût prévu du projet
A53: =IF($A$1="English",B53,C53) -> Basis of Cost Estimate | B53: Basis of Cost Estimate
A54: =IF($A$1="English",B54,C54) -> Land Cost | B54: Land Cost
A55: =IF($A$1="English",B55,C55) -> Building Cost - School | B55: Building Cost - School
A56: =IF($A$1="English",B56,C56) -> Soft Costs - School | B56: Soft Costs - School
A57: =IF($A$1="English",B57,C57) -> Building Cost - Child Care | B57: Building Cost - Child Care
A58: =IF($A$1="English",B58,C58) -> Soft Costs -Child Care | B58: Soft Costs -Child Care
A59: =IF($A$1="English",B59,C59) -> Unique Site Costs - School | B59: Unique Site Costs - School
A60: =IF($A$1="English",B60,C60) -> Unique Site Costs - Child Care | B60: Unique Site Costs - Child Care
A61: =IF($A$1="English",B61,C61) -> Unique Site Costs - Other | B61: Unique Site Costs - Other
A62: =IF($A$1="English",B62,C62) -> Municipal/Extraordinary Cost - School | B62: Municipal/Extraordinary Cost - School
A63: =IF($A$1="English",B63,C63) -> Municipal/Extraordinary Cost - Child Care | B63: Municipal/Extraordinary Cost - Child Care
A64: =IF($A$1="English",B64,C64) -> Municipal/Extraordinary Cost - Other | B64: Municipal/Extraordinary Cost - Other
... A70: =IF($A$1="English",B70,C70) -> Opening Ceremony - Date | B70: Opening Ceremony - Date
A71: =IF($A$1="English",B71,C71) -> Section 10: General Comments | B71: Section 10: General Comments | C71: Commentaires
A72: =IF($A$1="English",B72,C72) -> Section 10: Project Risks and Mitigation Stategies | B72: Section 10: Project Risks and Mitigation Stategies
...
