Workbook

Sheet form
A1: monthly_v2.0

Sheet Instructions and Glossary
A1: Project Tracker - Instructions
B4: Purpose | C4: The Project Tracker is a tool for capital analysts to capture information about each board's projects. This data provides a line of sight into project progress and details that is critical to both analysts, other folks within the branch, and management. The data gathered here facilitates project accountability and oversight of project milestones and finances.
B6: Instructions
B7: During Meetings with the Board | C7: When analysts meet with their board to discuss projects, you should use this tool to guide your meetings and capture information. Make sure you update the meeting date on the Monthly Tracker worksheet. You'll notice that this sheet has conditional formatting that greys out the sheet when the meeting date is not set to the current day. This is done so you have a visual reminder to update this date before you talk with your boards. Taking comprehensive minutes is especially important part of your meetings with the boards. The template provides space for you to enter project-specific minutes, as well as a section for minuting any more general information discussed that might not fall under one specific project. The data is scraped regularly and then the template is regenerated with updated information. During this process, minutes are archived and relocated to the far-left side of the template (column BD), sorted with the most recent minutes closest to the left.
B8: As Needed | C8: If you need to update information at any time other than during a meeting with the board, you are free to do so and the revised information will be captured the next time the data team extracts data from worksheet. Do NOT change the meeting date during any such ad-hoc updates. You should only change the meeting dates when you actually meet with the school board.
B9: General Information & Error Checking | C9: As mentioned above, the Monthly Update worksheet contains conditional formatting that incentivizes you not to forget to enter a meeting date when you talk with the school board. You will notice that once the meeting date is has passed (i.e., it is something other than the current date), the whole sheet goes grey. This provides a visual cue for you to update the date prior to meeting with your board. The sheet also contains some automatic error checking. Cells contain errors when they are highlighted in purple. To determine the reason for the error, scroll over to columns CY to ES. This section contains the same columns as the main table; cells in this table will only contains text if there is an error. That text will describe the cause of the error in the corresponding cell in the main table.
B11: Within-Budget Acknowledgement Process
B12: Analyst Checks | C12: Confirm that the board has submitted all necessary documentation: •Class A/B cost estimate •Revised CPBF form that reflects the Class A/B cost estimate. •80% design drawings that align with the cost estimate and approved space template. •Child care floor plan approval letter (if applicable). Ensure that all documents are saved in the appropriate folder on the Share Drive. Once you have checked and confirmed all documents, send an email to the board acknowledging receipt of the pre/post tender package.
B13: Record Keeping | C13: Create a folder in the following directory: \\csc.ad.gov.on.ca\dfs$\GrpData\CBSD\CAPITAL\STRATEGY\Operations\BOARDS\^Project Commitment\Pre & Post Tender Check-In •The folder should be named using the following naming format: project id # YYYY-MM-DD Example: 12-123 # 2025-12-30 •The date in the folder name should be the date of the email acknowledging receipt of the documents and confirming the board can proceed. •Save the following in the folder you created above: o The CPBF form that reflects the pre-tender/post-tender budget. o The email to the school board (sent within 7 days of the board’s submission) confirming all documents have been submitted and that the ministry has no concerns with the board proceeding to tender/awarding the contract.
A15: Project Tracker Glossary
B17: Overview of the Worksheets within the Project Tracker
B18: Board Contacts | C18: Use this worksheet to enter the contact information for your boards. This is a central location for Capital Analysts to store this information, as well as a place where management and other analysts can go if they need this information. This is important to support coverage for analysts who are absent.
B19: Monthly Update | C19: Use this tab to memorialize meetings with the school boards. See instructions above and glossary below for more information.
B20: Basic Project Info | C20: Use this worksheet to enter the official school name, the school's location information, sign installation information, and the opening ceremony date. See below for a glossary, defining what should be entered in each column.
B21: Ad-Hoc or Potential Projects | C21: Use this worksheet to enter data about potential projects that have not yet been approved or about ad-hoc, minor projects that don't show up on the Monthly Tracker sheet.
B22: Project Commitment | C22: This sheet is for your reference only. It is not editable. It provides information about the current project commitment for the projects for this board.
A24: Glossary - Basic Project Info Tab
A26: ='Basic Project Info'!A2 -> Section 1: Project Details
A27: Col 1 | B27: =_xlfn.XLOOKUP(A27,'Basic Project Info'!$A$3:$L$3, 'Basic Project Info'!$A$4:$L$4) -> Project ID | C27: =C44 -> Automatically generated and uneditable. Each project is assigned a unique ID for tracking throughout its lifecycle. The ID displayed here is the ID for the construction portion of the project.
A28: ="Col " & ROW() -ROW($A$27)+1 -> Col 2 | B28: =_xlfn.XLOOKUP(A28,'Basic Project Info'!$A$3:$L$3, 'Basic Project Info'!$A$4:$L$4) -> Project Name | C28: Automatically generated and uneditable. This is the name assigned to the project when it is first approved. It cannot be changed and is constant throughout the project's lifecycle.
A29: ="Col " & ROW() -ROW($A$27)+1 -> Col 3 | B29: =_xlfn.XLOOKUP(A29,'Basic Project Info'!$A$3:$L$3, 'Basic Project Info'!$A$4:$L$4) -> Official School Name | C29: Use this field to update the official school name that will be used after the school is open. Please use the complete name and do not use abbreviations (e.g. use "Example Public School" instead of "Example" or "Example P.S.". If this project is an addition, this field can be completed as soon as the project is approved.
A30: ="Col " & ROW() -ROW($A$27)+1 -> Col 4 | B30: =_xlfn.XLOOKUP(A30,'Basic Project Info'!$A$3:$L$3, 'Basic Project Info'!$A$4:$L$4) -> Project Type | C30: =C47 -> Automatically generated and uneditable. Project types potentially included in this tracker are: New Construction, Retrofit, Addition, and Purchase.
A31: ="Col " & ROW() -ROW($A$27)+1 -> Col 5 | B31: =_xlfn.XLOOKUP(A31,'Basic Project Info'!$A$3:$L$3, 'Basic Project Info'!$A$4:$L$4) -> Project Category | C31: =C48 -> Automatically generated and uneditable. This field identifies the need that is met by the project. Potential project categories that could be included on this tracker are: Accommodation Pressure, Child Care, Facility Condition, Consolidation, and French Language Access.
A32: ="Col " & ROW() -ROW($A$27)+1 -> Col 6 | B32: =_xlfn.XLOOKUP(A32,'Basic Project Info'!$A$3:$L$3, 'Basic Project Info'!$A$4:$L$4) -> Address | C32: Enter the address for the school. If it's not yet known, leave it blank.
A33: ="Col " & ROW() -ROW($A$27)+1 -> Col 7 | B33: =_xlfn.XLOOKUP(A33,'Basic Project Info'!$A$3:$L$3, 'Basic Project Info'!$A$4:$L$4) -> City | C33: Use this field to enter the city/town where the project is located. This should be known at the time of project approval and be pre-populated on the template. Therefore, this field can be left unedited except for very rare circumstances.
A34: ="Col " & ROW() -ROW($A$27)+1 -> Col 8 | B34: =_xlfn.XLOOKUP(A34,'Basic Project Info'!$A$3:$L$3, 'Basic Project Info'!$A$4:$L$4) -> Postal Code | C34: Enter the postal code of the school. If the it's not yet known, leave it blank.
A35: ="Col " & ROW() -ROW($A$27)+1 -> Col 9 | B35: =_xlfn.XLOOKUP(A35,'Basic Project Info'!$A$3:$L$3, 'Basic Project Info'!$A$4:$L$4) -> Latitude | C35: Enter the latitude of the school. This information should be updated once the site has been purchased.
A36: ="Col " & ROW() -ROW($A$27)+1 -> Col 10 | B36: =_xlfn.XLOOKUP(A36,'Basic Project Info'!$A$3:$L$3, 'Basic Project Info'!$A$4:$L$4) -> Longitude | C36: Enter the longitude of the school. This information should be updated once the site has been purchased.
A37: ='Basic Project Info'!K2 -> Section 2: Communications Issues
A38: ="Col " & ROW() -ROW($A$27) -> Col 11 | B38: =_xlfn.XLOOKUP(A38,'Basic Project Info'!$A$3:$L$3, 'Basic Project Info'!$A$4:$L$4) -> Sign Installed | C38: Indicate whether the board has installed a sign on the project site.
A39: ="Col " & ROW() -ROW($A$27) -> Col 12 | B39: =_xlfn.XLOOKUP(A39,'Basic Project Info'!$A$3:$L$3, 'Basic Project Info'!$A$4:$L$4) -> Opening Ceremony - Date | C39: Use this once the project approaches completion if the board plans an opening ceremony. Otherwise, leave this blank.
A41: Glossary - Monthly Update Tab
A43: ='Monthly Update'!A5 -> Section 1: Project Details
A44: Col 1 | B44: =_xlfn.XLOOKUP(A44, 'Monthly Update'!$A$6:$AU$6, 'Monthly Update'!$A$7:$AU$7) -> Project ID | C44: Automatically generated and uneditable. Each project is assigned a unique ID for tracking throughout its lifecycle. The ID displayed here is the ID for the construction portion of the project.
A45: Col 2 | B45: =_xlfn.XLOOKUP(A45, 'Monthly Update'!$A$6:$AU$6, 'Monthly Update'!$A$7:$AU$7) -> Project Name | C45: Automatically generated and uneditable. This is the name assigned to the project when it is first approved. It cannot be changed and is constant throughout the project's lifecycle. The official name of the school can be modified on the Basic Project Info tab.
A46: Col 3 | B46: =_xlfn.XLOOKUP(A46, 'Monthly Update'!$A$6:$AU$6, 'Monthly Update'!$A$7:$AU$7) -> Meeting Minutes | C46: Enter details about each project based on conversations with the school board.
A47: Col 4 | B47: =_xlfn.XLOOKUP(A47, 'Monthly Update'!$A$6:$AU$6, 'Monthly Update'!$A$7:$AU$7) -> Project Type | C47: Automatically generated and uneditable. Project types potentially included in this tracker are: New Construction, Retrofit, Addition, and Purchase.
A48: Col 5 | B48: =_xlfn.XLOOKUP(A48, 'Monthly Update'!$A$6:$AU$6, 'Monthly Update'!$A$7:$AU$7) -> Project Category | C48: Automatically generated and uneditable. This field identifies the need that is met by the project. Potential project categories that could be included on this tracker are: Accommodation Pressure, Child Care, Facility Condition, Consolidation, and French Language Access.
A49: Col 6 | B49: =_xlfn.XLOOKUP(A49, 'Monthly Update'!$A$6:$AU$6, 'Monthly Update'!$A$7:$AU$7) -> Record Status | C49: This drop-down determines which projects will be removed from your trackers. If you want to remove a project, you must identify whether it has been completed or cancelled. The default is for projects to remain on the tracker. When projects are removed from the tracker, it triggers an email notification to your manager and director.
A50: Col 7 | B50: =_xlfn.XLOOKUP(A50, 'Monthly Update'!$A$6:$AU$6, 'Monthly Update'!$A$7:$AU$7) -> Construction Status | C50: Automatically generated and uneditable. This field is calculated based on the dates provided to the right in this sheet. If the meeting date is after the opening date, the construction status is "Open"; if the meeting date is after the construction date, the status is "Under Construction". Otherwise the project status is "Planning".
...

Sheet Board Contacts
A1: School Board Contact List
A4: Name | B4: Role | C4: Title | D4: Email | E4: Phone
A5: *((tbl*((board_contacts*((col*((name | B5: *((col*((role | C5: *((col*((title | D5: *((col*((email | E5: *((col*((phone

Sheet Basic Project Info
A1: Basic Project Information
A2: =Translation!A5 -> Section 1: Project Details | K2: Section 2: Communications Issues
A3: ="Col "&COLUMN() -> Col 1 | B3: ="Col "&COLUMN() -> Col 2 | C3: ="Col "&COLUMN() -> Col 3 | D3: ="Col "&COLUMN() -> Col 4 | E3: ="Col "&COLUMN() -> Col 5 | F3: ="Col "&COLUMN() -> Col 6 | G3: ="Col "&COLUMN() -> Col 7 | H3: ="Col "&COLUMN() -> Col 8 | ... L3: ="Col "&COLUMN() -> Col 12
A4: =Translation!A6 -> Project ID | B4: =Translation!A7 -> Project Name | C4: Official School Name | D4: =Translation!A11 -> Project Type | E4: =Translation!A13 -> Project Category | F4: =Translation!A8 -> Address | G4: =Translation!A9 -> City | H4: =Translation!A10 -> Postal Code | I4: Latitude | J4: Longitude | K4: Sign Installed | L4: =Translation!A70 -> Opening Ceremony - Date
A5: No. de projet | B5: Nom du projet | D5: Type de projet | E5: Catégorie de projet
A7: *((tbl*((basic_project_info*((col*((project_id | B7: *((col*((project_name | C7: *((col*((project_name_official | D7: *((col*((project_type | E7: *((col*((project_category | F7: *((col*((location_address | G7: *((col*((location_city | H7: *((col*((location_postal_code | I7: *((col*((location_latitude | J7: *((col*((location_longitude | K7: *((col*((sign_installed | L7: *((col*((date_opening_ceremony
A100: 1 | B100: 1 | C100: 1 | D100: 1 | E100: 1 | F100: 1 | G100: 1 | H100: 1 | I100: 1 | J100: 1 | K100: 1 | L100: 1

Sheet Monthly Update
A1: Monthly Project Updates | C1: *((var*((board_number_name
E2: *((var*((missing_data_count*((formula*((right | F2: =COLUMNS($D$3:$AU$3) - COUNTIF($D$3:$AU$3, "") -> 0
A3: Meeting Date | C3: *((var*((date_meeting | CX3: *((var*((error_count*((formula*((down | CY3: =AND(CX3, ISBLANK(CY11)) -> TRUE | CZ3: =AND(CZ4, ISBLANK(CZ11)) -> FALSE | DA3: =AND(DA4, ISBLANK(DA11)) -> FALSE | DB3: =AND(DB4, ISBLANK(DB11)) -> FALSE | DC3: =AND(DC4, ISBLANK(DC11)) -> FALSE | DD3: =AND(DD4, ISBLANK(DD11)) -> FALSE | DE3: =AND(DE4, ISBLANK(DE11)) -> FALSE | DF3: =AND(DF4, ISBLANK(DF11)) -> FALSE | DG3: =AND(DG4, ISBLANK(DG11)) -> FALSE | ... ES3: =AND(ES4, ISBLANK(ES11)) -> FALSE
B4: General Meeting Minutes: | C4: *((var*((meeting_minutes_general_current | AT4: Historical General Meeting Minutes -------------> | BD4: *((tbl*((meeting_minutes_general*((col*((meeting_minutes_general_minus_1 | BE4: ="*((col*((meeting_minutes_general_minus_"&COLUMN()-COLUMN($BD$4)+1 -> *((col*((meeting_minutes_general_minus_2 | BF4: ="*((col*((meeting_minutes_general_minus_"&COLUMN()-COLUMN($BD$4)+1 -> *((col*((meeting_minutes_general_minus_3 | BG4: ="*((col*((meeting_minutes_general_minus_"&COLUMN()-COLUMN($BD$4)+1 -> *((col*((meeting_minutes_general_minus_4 | BH4: ="*((col*((meeting_minutes_general_minus_"&COLUMN()-COLUMN($BD$4)+1 -> *((col*((meeting_minutes_general_minus_5 | BI4: ="*((col*((meeting_minutes_general_minus_"&COLUMN()-COLUMN($BD$4)+1 -> *((col*((meeting_minutes_general_minus_6 | BJ4: ="*((col*((meeting_minutes_general_minus_"&COLUMN()-COLUMN($BD$4)+1 -> *((col*((meeting_minutes_general_minus_7 | BK4: ="*((col*((meeting_minutes_general_minus_"&COLUMN()-COLUMN($BD$4)+1 -> *((col*((meeting_minutes_general_minus_8 | BL4: ="*((col*((meeting_minutes_general_minus_"&COLUMN()-COLUMN($BD$4)+1 -> *((col*((meeting_minutes_general_minus_9 | ... CA4: ="*((col*((meeting_minutes_general_minus_"&COLUMN()-COLUMN($BD$4)+1 -> *((col*((meeting_minutes_general_minus_24 | CX4: =COUNTA(CY10:ES105) -> 97 | CY4: =ISNUMBER(SEARCH("formula", CY10)) -> FALSE | CZ4: =ISNUMBER(SEARCH("formula", CZ10)) -> FALSE | DA4: =ISNUMBER(SEARCH("formula", DA10)) -> TRUE | DB4: =ISNUMBER(SEARCH("formula", DB10)) -> FALSE | DC4: =ISNUMBER(SEARCH("formula", DC10)) -> FALSE | DD4: =ISNUMBER(SEARCH("formula", DD10)) -> FALSE | DE4: =ISNUMBER(SEARCH("formula", DE10)) -> FALSE | DF4: =ISNUMBER(SEARCH("formula", DF10)) -> TRUE | ... ES4: =ISNUMBER(SEARCH("formula", ES10)) -> TRUE
A5: Section 1: Project Details | H5: Section 2: Project Commitment Progress | P5: Section 3: Pre-Tender | AB5: Section 4: Construction | AG5: Section 5: Project Completion | AL5: Section 6: Approved Project Funding | AQ5: Section 7: Projected Cost | AV5: Section 10: Project Risks and Mitigation Stategies | BD5: Section 8: Historical Meeting Minutes | CY5: Error Messages | DD5: Error Messages | DM5: Error Messages | DR5: Error Messages | DV5: Error Messages | DY5: Error Messages | EB5: Error Messages | EG5: Error Messages | EL5: Error Messages | EQ5: Error Messages
A6: ="Col "&COLUMN() -> Col 1 | B6: ="Col "&COLUMN() -> Col 2 | C6: ="Col "&COLUMN() -> Col 3 | D6: ="Col "&COLUMN() -> Col 4 | E6: ="Col "&COLUMN() -> Col 5 | F6: ="Col "&COLUMN() -> Col 6 | G6: ="Col "&COLUMN() -> Col 7 | H6: ="Col "&COLUMN() -> Col 8 | ... AV6: ="Col "&COLUMN() -> Col 48 | BC6: ="Col "&COLUMN() -> Col 55 | BD6: ="Col "&COLUMN() -> Col 56 | BE6: ="Col "&COLUMN() -> Col 57 | BF6: ="Col "&COLUMN() -> Col 58 | BG6: ="Col "&COLUMN() -> Col 59 | BH6: ="Col "&COLUMN() -> Col 60 | BI6: ="Col "&COLUMN() -> Col 61 | BJ6: ="Col "&COLUMN() -> Col 62 | ... CA6: ="Col "&COLUMN() -> Col 79 | CY6: =A6 -> Col 1 | CZ6: =B6 -> Col 2 | DA6: =C6 -> Col 3 | DB6: =D6 -> Col 4 | DC6: =E6 -> Col 5 | DD6: =F6 -> Col 6 | DE6: =G6 -> Col 7 | DF6: =H6 -> Col 8 | ... ES6: =AU6 -> Col 47 | EW6: =K6 -> Col 11 | EX6: =EW6 -> Col 11 | EY6: =EX6 -> Col 11 | EZ6: =EY6 -> Col 11 | FA6: =O6 -> Col 15 | FB6: =FA6 -> Col 15 | FC6: =FB6 -> Col 15 | FD6: =FC6 -> Col 15 | FE6: =P6 -> Col 16 | FF6: =FE6 -> Col 16 | FG6: =FF6 -> Col 16 | FH6: =FG6 -> Col 16 | FI6: =Q6 -> Col 17 | FJ6: =FI6 -> Col 17 | FK6: =FJ6 -> Col 17 | FL6: =FK6 -> Col 17
A7: Project ID | B7: Project Name | C7: Meeting Minutes | D7: Project Type | E7: Project Category | F7: Record Status | G7: Construction Status | H7: Pre-Tender Submission Date | I7: Pre-Tender Package Type | J7: Pre-Tender Package Complete | K7: CA Reviewed All Pre-Tender Documents | L7: Post-Tender Submission Date | M7: Post-Tender Package Type | N7: Post-Tender Package Complete | O7: CA Reviewed All Post-Tender Documents | P7: Site Ownership Status | Q7: Site Purchase Date | R7: Design Status | S7: Space Template Approval Date | T7: Child Care Floorplan Approval Date | U7: Initial Site Plan Submission Date | V7: Site Plan Approval Date | W7: Site Plan Approval Date Error Explanation | X7: Build Permit Obtained Date | Y7: =X7&" Error Explanation" -> Build Permit Obtained Date Error Explanation | Z7: Tender Issued Date | AA7: Tender Closed Date | AB7: Contract Awarded Date | AC7: Construction Start Date | AD7: =AC7&" Error Explanation" -> Construction Start Date Error Explanation | AE7: Substantial Completion Date | AF7: =AE7&" Error Explanation" -> Substantial Completion Date Error Explanation | AG7: School Opening Date | AH7: =AG7&" Error Explanation" -> School Opening Date Error Explanation | AI7: Child Care Opening Date | AJ7: =AI7&" Error Explanation" -> Child Care Opening Date Error Explanation | AK7: Financial Close-Out Date | AL7: Funding - All Associated Projects | AM7: Funding - Construction Project | AN7: Funding - Site Acquisition | AO7: Funding - Demolition | AP7: Funding - All Other Associated Projects | AQ7: Basis of Cost Estimate | AR7: Estimated Cost - Construction Project | AS7: Estimated Cost - Land | AT7: Estimated Cost - Demolition | AU7: Estimated Cost - All Other Associated Projects | AV7: Risk Type | AW7: Risk Rating | AX7: Risk Exposure Start Date | AY7: Min Cost of Risk ($M) | AZ7: Max Cost of Risk ($M) | BA7: Min Delay of Risk (Months) | BB7: Max Delay of Risk (Months) | BC7: Mitigation Stategies/Comments | BD7: ="*((tbl*((meeting_minutes_heading"&BD10 -> *((tbl*((meeting_minutes_heading*((col*((meeting_minutes_minus_1 | BE7: =BE10 -> *((col*((meeting_minutes_minus_2 | BF7: =BF10 -> *((col*((meeting_minutes_minus_3 | BG7: =BG10 -> *((col*((meeting_minutes_minus_4 | BH7: =BH10 -> *((col*((meeting_minutes_minus_5 | BI7: =BI10 -> *((col*((meeting_minutes_minus_6 | BJ7: =BJ10 -> *((col*((meeting_minutes_minus_7 | BK7: =BK10 -> *((col*((meeting_minutes_minus_8 | BL7: =BL10 -> *((col*((meeting_minutes_minus_9 | ... CA7: =CA10 -> *((col*((meeting_minutes_minus_24 | CC7: *((table_end*((meeting_minutes_heading | CE7: cc_amount | CF7: ='Project Commitment'!M4 -> Site Purchase Date | CG7: ='Project Commitment'!N4 -> Space Template Approval Date | CH7: ='Project Commitment'!O4 -> Child Care Floorplan Approval Date | CI7: ='Project Commitment'!P4 -> Initial Site Plan Submission Date | CJ7: ='Project Commitment'!Q4 -> Site Plan Approval Date | CK7: ='Project Commitment'!R4 -> Build Permit Obtained Date | CL7: ='Project Commitment'!S4 -> Pre-Tender Submission Date | CM7: ='Project Commitment'!T4 -> Tender Issued Date | ... CU7: ='Project Commitment'!AB4 -> Financial Close-Out Date | CY7: =A7 -> Project ID | CZ7: =B7 -> Project Name | DA7: =C7 -> Meeting Minutes | DB7: =D7 -> Project Type | DC7: =E7 -> Project Category | DD7: =F7 -> Record Status | DE7: =G7 -> Construction Status | DF7: =H7 -> Pre-Tender Submission Date | ... ES7: =AU7 -> Estimated Cost - All Other Associated Projects
A8: No. de projet | B8: Nom du projet | D8: Type de projet | E8: Catégorie de projet | AN8: IP | AO8: Service de garde | AP8: Autre | AQ8: Base de l'estimation des coûts | AU8: Coûts du site
A10: *((tbl*((monthly*((col*((project_id | B10: *((col*((project_name | C10: *((col*((meeting_minutes | D10: *((col*((project_type | E10: *((col*((project_category | F10: *((col*((record_status | G10: *((col*((construction_status*((formula*((down | H10: *((col*((date_pretender | I10: *((col*((pretender_package_type | J10: *((col*((pre_tender_complete | K10: *((col*((pre_tender_documents_reviewed | L10: *((col*((date_posttender | M10: *((col*((posttender_package_type | N10: *((col*((post_tender_complete | O10: *((col*((post_tender_documents_reviewed | P10: *((col*((site_status | Q10: *((col*((date_site_purchase | R10: *((col*((design_status | S10: *((col*((date_space_template | T10: *((col*((date_cc_floorplan | U10: *((col*((date_site_plan_submission | V10: *((col*((date_site_plan_approved | W10: ="*((col*((error_explained_"&COLUMN() -> *((col*((error_explained_23 | X10: *((col*((date_building_permit | Y10: ="*((col*((error_explained_"&COLUMN() -> *((col*((error_explained_25 | Z10: *((col*((date_tender_issue | AA10: *((col*((date_tender_closed | AB10: *((col*((date_tender | AC10: *((col*((date_construction | AD10: ="*((col*((error_explained_"&COLUMN() -> *((col*((error_explained_30 | AE10: *((col*((date_substantial_completion | AF10: ="*((col*((error_explained_"&COLUMN() -> *((col*((error_explained_32 | AG10: *((col*((date_opening | AH10: ="*((col*((error_explained_"&COLUMN() -> *((col*((error_explained_34 | AI10: *((col*((date_opening_cc | AJ10: ="*((col*((error_explained_"&COLUMN() -> *((col*((error_explained_36 | AK10: *((col*((date_completion | AL10: *((col*((funding_all*((formula*((down | AM10: *((col*((funding_construction | AN10: *((col*((funding_site | AO10: *((col*((funding_demo | AP10: *((col*((funding_other_projects | AQ10: *((col*((cost_basis | AR10: *((col*((cost_estimate_construction | AS10: *((col*((cost_estimate_land | AT10: *((col*((cost_estimate_demo | AU10: *((col*((cost_estimate_other_projects | AV10: *((col*((risk_type | AW10: *((col*((risk_rating | AX10: *((col*((risk_date_start | AY10: *((col*((risk_cost_min | AZ10: *((col*((risk_cost_max | BA10: *((col*((risk_delay_min | BB10: *((col*((risk_delay_max | BC10: *((col*((risk_mitigation | BD10: *((col*((meeting_minutes_minus_1 | BE10: *((col*((meeting_minutes_minus_2 | BF10: *((col*((meeting_minutes_minus_3 | BG10: *((col*((meeting_minutes_minus_4 | BH10: *((col*((meeting_minutes_minus_5 | BI10: *((col*((meeting_minutes_minus_6 | BJ10: *((col*((meeting_minutes_minus_7 | BK10: *((col*((meeting_minutes_minus_8 | BL10: *((col*((meeting_minutes_minus_9 | BM10: *((col*((meeting_minutes_minus_10 | BN10: *((col*((meeting_minutes_minus_11 | BO10: *((col*((meeting_minutes_minus_12 | BP10: *((col*((meeting_minutes_minus_13 | BQ10: *((col*((meeting_minutes_minus_14 | BR10: *((col*((meeting_minutes_minus_15 | BS10: *((col*((meeting_minutes_minus_16 | BT10: *((col*((meeting_minutes_minus_17 | BU10: *((col*((meeting_minutes_minus_18 | BV10: *((col*((meeting_minutes_minus_19 | BW10: *((col*((meeting_minutes_minus_20 | BX10: *((col*((meeting_minutes_minus_21 | BY10: *((col*((meeting_minutes_minus_22 | BZ10: *((col*((meeting_minutes_minus_23 | CA10: *((col*((meeting_minutes_minus_24 | CD10: *((col*((site_ownership_formula*((formula*((down | CE10: *((col*((scope_cc_spaces_added | CF10: ="*((col*((temp_formula_"&COLUMN()&"*((formula*((down" -> *((col*((temp_formula_84*((formula*((down | CG10: ="*((col*((temp_formula_"&COLUMN()&"*((formula*((down" -> *((col*((temp_formula_85*((formula*((down | CH10: ="*((col*((temp_formula_"&COLUMN()&"*((formula*((down" -> *((col*((temp_formula_86*((formula*((down | CI10: ="*((col*((temp_formula_"&COLUMN()&"*((formula*((down" -> *((col*((temp_formula_87*((formula*((down | CJ10: ="*((col*((temp_formula_"&COLUMN()&"*((formula*((down" -> *((col*((temp_formula_88*((formula*((down | CK10: ="*((col*((temp_formula_"&COLUMN()&"*((formula*((down" -> *((col*((temp_formula_89*((formula*((down | CL10: ="*((col*((temp_formula_"&COLUMN()&"*((formula*((down" -> *((col*((temp_formula_90*((formula*((down | CM10: ="*((col*((temp_formula_"&COLUMN()&"*((formula*((down" -> *((col*((temp_formula_91*((formula*((down | ... CU10: ="*((col*((temp_formula_"&COLUMN()&"*((formula*((down" -> *((col*((temp_formula_99*((formula*((down | DA10: ="*((col*((temp_formula_"&COLUMN()&"*((formula*((down" -> *((col*((temp_formula_105*((formula*((down | DF10: ="*((col*((temp_formula_"&COLUMN()&"*((formula*((down" -> *((col*((temp_formula_110*((formula*((down | DG10: ="*((col*((temp_formula_"&COLUMN()&"*((formula*((down" -> *((col*((temp_formula_111*((formula*((down | DI10: ="*((col*((temp_formula_"&COLUMN()&"*((formula*((down" -> *((col*((temp_formula_113*((formula*((down | DJ10: ="*((col*((temp_formula_"&COLUMN()&"*((formula*((down" -> *((col*((temp_formula_114*((formula*((down | DK10: ="*((col*((temp_formula_"&COLUMN()&"*((formula*((down" -> *((col*((temp_formula_115*((formula*((down | DM10: ="*((col*((temp_formula_"&COLUMN()&"*((formula*((down" -> *((col*((temp_formula_117*((formula*((down | DN10: ="*((col*((temp_formula_"&COLUMN()&"*((formula*((down" -> *((col*((temp_formula_118*((formula*((down | DO10: ="*((col*((temp_formula_"&COLUMN()&"*((formula*((down" -> *((col*((temp_formula_119*((formula*((down | DP10: ="*((col*((temp_formula_"&COLUMN()&"*((formula*((down" -> *((col*((temp_formula_120*((formula*((down | DQ10: ="*((col*((temp_formula_"&COLUMN()&"*((formula*((down" -> *((col*((temp_formula_121*((formula*((down | DR10: ="*((col*((temp_formula_"&COLUMN()&"*((formula*((down" -> *((col*((temp_formula_122*((formula*((down | DS10: ="*((col*((temp_formula_"&COLUMN()&"*((formula*((down" -> *((col*((temp_formula_123*((formula*((down | DT10: ="*((col*((temp_formula_"&COLUMN()&"*((formula*((down" -> *((col*((temp_formula_124*((formula*((down | DV10: ="*((col*((temp_formula_"&COLUMN()&"*((formula*((down" -> *((col*((temp_formula_126*((formula*((down | DX10: ="*((col*((temp_formula_"&COLUMN()&"*((formula*((down" -> *((col*((temp_formula_128*((formula*((down | DY10: ="*((col*((temp_formula_"&COLUMN()&"*((formula*((down" -> *((col*((temp_formula_129*((formula*((down | DZ10: ="*((col*((temp_formula_"&COLUMN()&"*((formula*((down" -> *((col*((temp_formula_130*((formula*((down | EA10: ="*((col*((temp_formula_"&COLUMN()&"*((formula*((down" -> *((col*((temp_formula_131*((formula*((down | EC10: ="*((col*((temp_formula_"&COLUMN()&"*((formula*((down" -> *((col*((temp_formula_133*((formula*((down | EE10: ="*((col*((temp_formula_"&COLUMN()&"*((formula*((down" -> *((col*((temp_formula_135*((formula*((down | EG10: ="*((col*((temp_formula_"&COLUMN()&"*((formula*((down" -> *((col*((temp_formula_137*((formula*((down | EI10: ="*((col*((temp_formula_"&COLUMN()&"*((formula*((down" -> *((col*((temp_formula_139*((formula*((down | EO10: ="*((col*((temp_formula_"&COLUMN()&"*((formula*((down" -> *((col*((temp_formula_145*((formula*((down | EP10: ="*((col*((temp_formula_"&COLUMN()&"*((formula*((down" -> *((col*((temp_formula_146*((formula*((down | EQ10: ="*((col*((temp_formula_"&COLUMN()&"*((formula*((down" -> *((col*((temp_formula_147*((formula*((down | ER10: ="*((col*((temp_formula_"&COLUMN()&"*((formula*((down" -> *((col*((temp_formula_148*((formula*((down | ES10: ="*((col*((temp_formula_"&COLUMN()&"*((formula*((down" -> *((col*((temp_formula_149*((formula*((down | EW10: ="*((col*((temp_formula_"&COLUMN()&"*((formula*((down" -> *((col*((temp_formula_153*((formula*((down | EX10: ="*((col*((temp_formula_"&COLUMN()&"*((formula*((down" -> *((col*((temp_formula_154*((formula*((down | EY10: ="*((col*((temp_formula_"&COLUMN()&"*((formula*((down" -> *((col*((temp_formula_155*((formula*((down | EZ10: ="*((col*((temp_formula_"&COLUMN()&"*((formula*((down" -> *((col*((temp_formula_156*((formula*((down | FA10: ="*((col*((temp_formula_"&COLUMN()&"*((formula*((down" -> *((col*((temp_formula_157*((formula*((down | FB10: ="*((col*((temp_formula_"&COLUMN()&"*((formula*((down" -> *((col*((temp_formula_158*((formula*((down | FC10: ="*((col*((temp_formula_"&COLUMN()&"*((formula*((down" -> *((col*((temp_formula_159*((formula*((down | FD10: ="*((col*((temp_formula_"&COLUMN()&"*((formula*((down" -> *((col*((temp_formula_160*((formula*((down | ... FL10: ="*((col*((temp_formula_"&COLUMN()&"*((formula*((down" -> *((col*((temp_formula_168*((formula*((down
G11: {=_xlfn.IFS($C$3>AK11, "Complete", $C$3>AG11, "Open", $C$3>AC11, "Under Construction", TRUE, "Planning")} -> Complete | AL11: =SUM(AM11:AP11) -> 0 | CD11: =IF(AND(Q11="", A11<>"", P11<>"Site Purchased Prior to Capital Approval"), 1, 0) -> 0 | CF11: =_xlfn.XLOOKUP($A11, 'Project Commitment'!$A:$A, 'Project Commitment'!M:M, "") -> 0 | CG11: =_xlfn.XLOOKUP($A11, 'Project Commitment'!$A:$A, 'Project Commitment'!N:N, "") -> 0 | CH11: =_xlfn.XLOOKUP($A11, 'Project Commitment'!$A:$A, 'Project Commitment'!O:O, "") -> 0 | CI11: =_xlfn.XLOOKUP($A11, 'Project Commitment'!$A:$A, 'Project Commitment'!P:P, "") -> 0 | CJ11: =_xlfn.XLOOKUP($A11, 'Project Commitment'!$A:$A, 'Project Commitment'!Q:Q, "") -> 0 | CK11: =_xlfn.XLOOKUP($A11, 'Project Commitment'!$A:$A, 'Project Commitment'!R:R, "") -> 0 | CL11: =_xlfn.XLOOKUP($A11, 'Project Commitment'!$A:$A, 'Project Commitment'!S:S, "") -> 0 | CM11: =_xlfn.XLOOKUP($A11, 'Project Commitment'!$A:$A, 'Project Commitment'!T:T, "") -> 0 | CN11: =_xlfn.XLOOKUP($A11, 'Project Commitment'!$A:$A, 'Project Commitment'!U:U, "") -> 0 | CO11: =_xlfn.XLOOKUP($A11, 'Project Commitment'!$A:$A, 'Project Commitment'!V:V, "") -> 0 | CP11: =_xlfn.XLOOKUP($A11, 'Project Commitment'!$A:$A, 'Project Commitment'!W:W, "") -> 0 | CQ11: =_xlfn.XLOOKUP($A11, 'Project Commitment'!$A:$A, 'Project Commitment'!X:X, "") -> 0 | CR11: =_xlfn.XLOOKUP($A11, 'Project Commitment'!$A:$A, 'Project Commitment'!Y:Y, "") -> 0 | CS11: =_xlfn.XLOOKUP($A11, 'Project Commitment'!$A:$A, 'Project Commitment'!Z:Z, "") -> 0 | CT11: =_xlfn.XLOOKUP($A11, 'Project Commitment'!$A:$A, 'Project Commitment'!AA:AA, "") -> 0 | CU11: =_xlfn.XLOOKUP($A11, 'Project Commitment'!$A:$A, 'Project Commitment'!AB:AB, "") -> 0 | DA11: =IF(C11="", "Meeting Minutes cannot be blank", "") -> Meeting Minutes cannot be blank | DF11: {=_xlfn.IFS(AND(J11="Not Applicable", H11<>""), "No date is needed if Column 10 is Not Applicable",J11= "Not Applicable", "", H11="",DF$7&" cannot be blank", $AC11="", "", H11>$AC11, DF$7&" must preceed construction start date.", TRUE, "")} -> Pre-Tender Submission Date cannot be blank | DG11: {=_xlfn.IFS(I11="", DG$7&" cannot be left blank.",H11="", "", AND( H11 < TODAY(), I11="Not Yet Known"), "After the submission date, the pre-tender package type must be selected.", TRUE, "")} -> Pre-Tender Package Type cannot be left blank. | DI11: =EW11 -> Confirm you reviewed the pretender checkin documents | DJ11: {=_xlfn.IFS(AND(N11="Not Applicable", L11<>""), "No date is needed if Column 14 is Not Applicable",N11= "Not Applicable", "", L11="",DJ$7&" cannot be blank", $AC11="", "", L11>$AC11, DJ$7&" must preceed construction start date.", TRUE, "")} -> Post-Tender Submission Date cannot be blank | DK11: {=_xlfn.IFS(M11="", DK$7&" cannot be left blank.",L11="", "", AND( L11 < TODAY(), M11="Not Yet Known"), "After the submission date, the pre-tender package type must be selected.", TRUE, "")} -> Post-Tender Package Type cannot be left blank. | DM11: =FA11 -> Confirm you reviewed the post tender check-in documents | DN11: =FE11 -> Site Ownership Status cannot be blank | DO11: =FI11 -> Site Purchased Date cannot be blank | DP11: =IF(R11="", DP$7&" cannot be blank", "") -> Design Status cannot be blank | DQ11: {=_xlfn.IFS(S11="",DQ$7&" cannot be blank",AND(J11<>"Not yet submitted/reviewed",S11>TODAY()),DQ$7&" cannot be in the future if project is ready for a pre-tender package.",TRUE,"")} -> Space Template Approval Date cannot be blank | DR11: {=_xlfn.IFS(CE11=0, "", T11="",DR$7&" cannot be blank if project includes child care.", AND(J11="Not Applicable",T11>TODAY()), "Projects under construction must have a "&DR$7, J11="Not Applicable", "", T11<I11, T7&" must preceed pre-tender package submission date",TRUE, "")} | DS11: {=_xlfn.IFS(U11="",DS$7&" cannot be blank", $AC11="", "", U11>$AC11, DS$7&" must preceed construction start date.", TRUE, "")} -> Initial Site Plan Submission Date cannot be blank | DT11: {=_xlfn.IFS(W11<>"", "", V11="",DT$7&" cannot be blank", $AC11="", "", V11>$AC11, DT$7&" must preceed construction start date.", TRUE, "")} -> Site Plan Approval Date cannot be blank | DV11: {=_xlfn.IFS(Y11<>"", "", X11="",DV$7&" cannot be blank", $AC11="", "", X11>$AC11, DV$7&" must preceed construction start date.", TRUE, "")} -> Build Permit Obtained Date cannot be blank | DX11: {=_xlfn.IFS(Z11="",DX$7&" cannot be blank", $AC11="", "", Z11>$AC11, DX$7&" must preceed construction start date.", TRUE, "")} -> Tender Issued Date cannot be blank | DY11: {=_xlfn.IFS(AA11="",DY$7&" cannot be blank", $AC11="", "", AA11>$AC11, DY$7&" must preceed construction start date.", TRUE, "")} -> Tender Closed Date cannot be blank | DZ11: {=_xlfn.IFS(AB11="",DZ$7&" cannot be blank", $AC11="", "", AB11>$AC11, DZ$7&" must preceed construction start date.", TRUE, "")} -> Contract Awarded Date cannot be blank | EA11: {=_xlfn.IFS(AD11<>"", "", AC11="",EA$7&" cannot be blank", $AG11="", "", AC11>EDATE($AG11,-12), EA$7&" must preceed school opening date by more than 12 months.", TRUE, "")} -> Construction Start Date cannot be blank | EC11: {=_xlfn.IFS(AF11<>"", "", AE11="",EC$7&" cannot be blank", $AG11="", "", AE11>EDATE($AG11,-1), EC$7&" must preceed school opening date by more than one month.", TRUE, "")} -> Substantial Completion Date cannot be blank | EE11: {=_xlfn.IFS(AK11="", "", AG11="",EE$7&" cannot be blank",AH11<>"", "", $AG11="", "", AG11>=EDATE($AK11,-11), EE$7&" must preceed financial close date by at least 12 months.", TRUE, "")} | EG11: {=_xlfn.IFS(CE11=0, "", AI11="",EG$7&" cannot be blank",$AK11="", "",AJ11<>"", "", AI11>=EDATE($AK11,0), EG$7&" must preceed financial close date.", TRUE, "")} | EI11: {=_xlfn.IFS( AK11="",EI$7&" cannot be blank", TRUE, "")} -> Financial Close-Out Date cannot be blank | EO11: {=_xlfn.IFS(AQ11="", "Basis of Cost Estimate cannot be blank", AND(AC11<TODAY(), AQ11<>"Based on Tender Results"), "Contract awarded date suggests estimate should be based on tender results", AND(H11<TODAY(), AQ11<>"Based on Class A or B Cost Report"), "If project has already come in for a pre-tender budget, they must have a class A or B cost estimate.", TRUE, "")} -> Basis of Cost Estimate cannot be blank | EP11: {=_xlfn.IFS(OR(AM11=0, AM11=""), "", AR11="", EP$7&" cannot be blank.", TRUE, "")} | EQ11: {=_xlfn.IFS(OR(AN11=0, AN11=""), "", AS11="", EQ$7&" cannot be blank.", TRUE, "")} | ER11: {=_xlfn.IFS(OR(AO11=0, AO11=""), "", AT11="", ER$7&" cannot be blank.", TRUE, "")} | ES11: {=_xlfn.IFS(OR(AP11=0, AP11=""), "", AU11="", ES$7&" cannot be blank.", TRUE, "")} | EW11: {=_xlfn.IFS(EX11<>"", EX11, EY11<>"", EY11, EZ11<>"", EZ11, TRUE, "")} -> Confirm you reviewed the pretender checkin documents | EX11: =IF(J11="MISSING", "This package is missing!", "") | EY11: =IF(K11="", "Confirm you reviewed the pretender checkin documents", "") -> Confirm you reviewed the pretender checkin documents | EZ11: =IF(AND(K11="Not yet submitted/reviewed", J11<>"Not yet submitted/reviewed"), "Pretender package submitted; col 9 cann't indicate otherwise.", "") | FA11: {=_xlfn.IFS(FB11<>"", FB11, FC11<>"", FC11, FD11<>"", FD11, TRUE, "")} -> Confirm you reviewed the post tender check-in documents | FB11: =IF(N11="MISSING", "The post tender package is missing!", "") | FC11: =IF(O11="", "Confirm you reviewed the post tender check-in documents", "") -> Confirm you reviewed the post tender check-in documents | FD11: =IF(AND(O11="Not yet submitted/reviewed", N11<>"Not yet submitted/reviewed"), "Post-tender package submitted; col 9 cann't indicate otherwise.", "") | FE11: {=_xlfn.IFS(FF11<>"", FF11, FG11<>"", FG11, TRUE, FH11)} -> Site Ownership Status cannot be blank | FF11: =IF(P11<>"", "", "Site Ownership Status cannot be blank") -> Site Ownership Status cannot be blank | FG11: {=_xlfn.IFS(AND(Q11="", OR(P11="Site Purchased Prior to Capital Approval", P11="Site Purchased")), "", AND(OR(P11="Site Purchased Prior to Capital Approval", P11="Site Purchased"), Q11>TODAY()), "Site purchase date is in the future, but site ownership status indicates site is already purchaseed", TRUE, "")} | FH11: =IF(AND(AND(P11<>"Site Purchased Prior to Capital Approval", P11<>"Site Purchased"), Q11<=TODAY()), "Site purchase date is in the past, but site ownership status indicates site has not yet been purchaseed", "") -> Site purchase date is in the past, but site ownership status indicates site has not yet been purchaseed | FI11: {=_xlfn.IFS(FJ11<>"", FJ11, FK11<>"", FK11, TRUE,FL11 )} -> Site Purchased Date cannot be blank | FJ11: =IF(AND(P11<>"Not Applicable",Q11=""),"Site Purchased Date cannot be blank","") -> Site Purchased Date cannot be blank | FK11: =FE11 -> Site Ownership Status cannot be blank | FL11: {=_xlfn.IFS(Q11="", "", U11="", "", Q11>U11, "Site Purchase Date must preceed Site Plan Submission.", TRUE, "")}
A86: 1 | B86: 1 | C86: 1 | D86: 1 | E86: 1 | F86: 1 | G86: 1 | H86: 1 | I86: 1 | J86: 1 | K86: 1 | L86: 1 | M86: 1 | N86: 1 | O86: 1 | P86: 1 | Q86: 1 | R86: 1 | S86: 1 | T86: 1 | U86: 1 | V86: 1 | W86: 1 | X86: 1 | Y86: 1 | Z86: 1 | AA86: 1 | AB86: 1 | AC86: 1 | AD86: 1 | AE86: 1 | AF86: 1 | AG86: 1 | AH86: 1 | AI86: 1 | AJ86: 1 | AK86: 1 | AL86: 1 | AM86: 1 | AN86: 1 | AO86: 1 | AP86: 1 | AQ86: 1 | AR86: 1 | AS86: 1 | AT86: 1 | AU86: 1 | AV86: 1 | AW86: 1 | AX86: 1 | AY86: 1 | AZ86: 1 | BA86: 1 | BB86: 1 | BC86: 1 | BD86: 1 | BE86: 1 | BF86: 1 | BG86: 1 | BH86: 1 | BI86: 1 | BJ86: 1 | BK86: 1 | BL86: 1 | BM86: 1 | BN86: 1 | BO86: 1 | BP86: 1 | BQ86: 1 | BR86: 1 | BS86: 1 | BT86: 1 | BU86: 1 | BV86: 1 | BW86: 1 | BX86: 1 | BY86: 1 | BZ86: 1 | CA86: 1 | CB86: 1 | CC86: 1 | CD86: 1 | CE86: 1 | CF86: 1 | CG86: 1 | CH86: 1 | CI86: 1 | CJ86: 1 | CK86: 1 | CL86: 1 | CM86: 1 | CN86: 1 | CO86: 1 | CP86: 1 | CQ86: 1 | CR86: 1 | CS86: 1 | CT86: 1 | CU86: 1 | CV86: 1 | CW86: 1 | CX86: 1 | CY86: 1 | CZ86: 1 | DA86: 1 | DB86: 1 | DC86: 1 | DD86: 1 | DE86: 1 | DF86: 1 | DH86: 1 | DI86: 1 | DJ86: 1 | DL86: 1 | DM86: 1 | DN86: 1 | DO86: 1 | DP86: 1 | DQ86: 1 | DR86: 1 | DS86: 1 | DT86: 1 | DU86: 1 | DV86: 1 | DW86: 1 | DX86: 1 | DY86: 1 | DZ86: 1 | EA86: 1 | EC86: 1 | EE86: 1 | EG86: 1 | EI86: 1 | EJ86: 1 | EK86: 1 | EL86: 1 | EM86: 1 | EN86: 1 | EO86: 1 | EP86: 1 | EQ86: 1 | ER86: 1 | ES86: 1 | ET86: 1 | EU86: 1 | EV86: 1 | EW86: 1 | EX86: 1 | EY86: 1 | EZ86: 1 | FA86: 1 | FB86: 1 | FC86: 1 | FD86: 1 | FE86: 1 | FF86: 1 | FG86: 1 | FH86: 1 | FI86: 1 | FJ86: 1 | FK86: 1 | FL86: 1 | FM86: 1 | FN86: 1 | FO86: 1 | FP86: 1 | FQ86: 1 | FR86: 1 | FS86: 1 | FT86: 1 | FU86: 1 | FV86: 1 | FW86: 1 | FX86: 1 | FY86: 1 | FZ86: 1 | GA86: 1 | GB86: 1 | GC86: 1 | GD86: 1 | GE86: 1 | GF86: 1 | GG86: 1 | GH86: 1 | GI86: 1 | GJ86: 1 | GK86: 1 | GL86: 1 | GM86: 1 | GN86: 1 | GO86: 1 | GP86: 1 | GQ86: 1 | GR86: 1 | GS86: 1 | GT86: 1 | GU86: 1 | GV86: 1 | GW86: 1 | GX86: 1 | GY86: 1 | GZ86: 1 | HA86: 1 | HB86: 1 | HC86: 1 | HD86: 1 | HE86: 1 | HF86: 1 | HG86: 1 | HH86: 1 | HI86: 1 | HJ86: 1 | HK86: 1 | HL86: 1

Sheet Ad-Hoc or Potential Projects
A1: Ad-hoc & Potential Projects
A2: Parent ID | B2: Project ID | C2: Project Name | D2: Submission Type | E2: Project Type | F2: Year Open | G2: Project Category | H2: Project Type | I2: Timing | J2: Cost | K2: Funding Source | L2: Comments
B3: 99-123 | C3: Example Project | D3: Ad Hoc | E3: Land | F3: 2025 | G3: Accommodation Pressure | H3: Land

Sheet Project Commitment
A1: Project Commitments
A2: English | B2: =COLUMN() -> 2 | C2: =COLUMN() -> 3 | D2: =COLUMN() -> 4 | E2: =COLUMN() -> 5 | F2: =COLUMN() -> 6 | G2: =COLUMN() -> 7 | H2: =COLUMN() -> 8 | I2: =COLUMN() -> 9 | ... L2: =COLUMN() -> 12
A3: =Translation!A97 -> Project Info | C3: =Translation!A110 -> Key Milestones
A4: =Translation!A99 -> Project ID | B4: =Translation!A100 -> Project Name | C4: =Translation!A111 -> Site Purchase | D4: Space Template Approved | E4: Site Plan Approved | F4: Pre-Tender Checkin | G4: Tender Approved | H4: Post-Tender Checkin | I4: Construction Start | J4: Substantial Completion | K4: =Translation!A120 -> School/Addition Opening | L4: Financial Close | M4: ='Monthly Update'!Q7 -> Site Purchase Date | N4: ='Monthly Update'!S7 -> Space Template Approval Date | O4: ='Monthly Update'!T7 -> Child Care Floorplan Approval Date | P4: ='Monthly Update'!U7 -> Initial Site Plan Submission Date | Q4: ='Monthly Update'!V7 -> Site Plan Approval Date | R4: ='Monthly Update'!X7 -> Build Permit Obtained Date | S4: ='Monthly Update'!H7 -> Pre-Tender Submission Date | T4: ='Monthly Update'!Z7 -> Tender Issued Date | U4: ='Monthly Update'!AA7 -> Tender Closed Date | V4: ='Monthly Update'!L7 -> Post-Tender Submission Date | W4: ='Monthly Update'!AB7 -> Contract Awarded Date | X4: ='Monthly Update'!AC7 -> Construction Start Date | Y4: ='Monthly Update'!AE7 -> Substantial Completion Date | Z4: ='Monthly Update'!AG7 -> School Opening Date | AA4: ='Monthly Update'!AI7 -> Child Care Opening Date | AB4: ='Monthly Update'!AK7 -> Financial Close-Out Date
A5: *((tbl*((pc*((col*((project_id | B5: *((col*((project_name | C5: *((col*((date_site_purchase | D5: *((col*((date_space_template | E5: *((col*((date_site_plan_approved | F5: *((col*((date_pretender | G5: *((col*((date_tender | H5: *((col*((date_posttender | I5: *((col*((date_construction | J5: *((col*((date_substantial_completion | K5: *((col*((date_opening | L5: *((col*((date_completion | M5: =C5&"_comparison*((formula*((down" -> *((col*((date_site_purchase_comparison*((formula*((down | N5: =D5&"_comparison*((formula*((down" -> *((col*((date_space_template_comparison*((formula*((down | O5: =E5&"_comparison*((formula*((down" -> *((col*((date_site_plan_approved_comparison*((formula*((down | P5: =F5&"_comparison*((formula*((down" -> *((col*((date_pretender_comparison*((formula*((down | Q5: =G5&"_comparison*((formula*((down" -> *((col*((date_tender_comparison*((formula*((down | R5: =H5&"_comparison*((formula*((down" -> *((col*((date_posttender_comparison*((formula*((down | S5: =I5&"_comparison*((formula*((down" -> *((col*((date_construction_comparison*((formula*((down | T5: =J5&"_comparison*((formula*((down" -> *((col*((date_substantial_completion_comparison*((formula*((down | ... AB5: =R5&"_comparison*((formula*((down" -> *((col*((date_posttender_comparison*((formula*((down_comparison*((formula*((down
M6: =C6-SUMIF('Monthly Update'!$A:$A,'Project Commitment'!$A6, 'Monthly Update'!Q:Q) -> 0 | N6: =D6-SUMIF('Monthly Update'!$A:$A,'Project Commitment'!$A6, 'Monthly Update'!S:S) -> 0 | O6: =0 -> 0 | P6: =0 -> 0 | Q6: =E6-SUMIF('Monthly Update'!$A:$A,'Project Commitment'!$A6, 'Monthly Update'!V:V) -> 0 | R6: =0 -> 0 | S6: =F6-SUMIF('Monthly Update'!$A:$A,'Project Commitment'!$A6, 'Monthly Update'!H:H) -> 0 | T6: =0 -> 0 | U6: =G6-SUMIF('Monthly Update'!$A:$A,'Project Commitment'!$A6, 'Monthly Update'!AA:AA) -> 0 | V6: =H6-SUMIF('Monthly Update'!$A:$A,'Project Commitment'!$A6, 'Monthly Update'!L:L) -> 0 | W6: =0 -> 0 | X6: =I6-SUMIF('Monthly Update'!$A:$A,'Project Commitment'!$A6, 'Monthly Update'!AC:AC) -> 0 | Y6: =J6-SUMIF('Monthly Update'!$A:$A,'Project Commitment'!$A6, 'Monthly Update'!AE:AE) -> 0 | Z6: =K6-SUMIF('Monthly Update'!$A:$A,'Project Commitment'!$A6, 'Monthly Update'!AG:AG) -> 0 | AA6: =0 -> 0 | AB6: =L6-SUMIF('Monthly Update'!$A:$A,'Project Commitment'!$A6, 'Monthly Update'!AK:AK) -> 0

Sheet Constants
A1: Constants
A3: Orange Date | B3: =-365*0.75 -> -273.75
A4: Red Date | B4: -365

Sheet List
A1: Actual/Estimated | B1: Language | C1: Construction Status | D1: Phase | E1: Yes / No | F1: Site Ownership Status | G1: Design Status | H1: Cost Basis | I1: Design | J1: Site Plan | K1: Project Category | L1: Project Type | M1: Package Type
A2: Actual | B2: English | C2: Planning | D2: 1 | E2: Yes | F2: No Site Identified | G2: <30% Complete | H2: Board Estimate | I2: New | J2: Yes | K2: Accommodation Pressure | L2: Land | M2: Within Budget
A3: Estimate | B3: French | C3: Pre-Procurement | D3: 1 | E3: No | F3: Site Identified Only | G3: 30%-80% Complete | H3: Repeat Design | I3: Repeat | J3: No | K3: Facility Condition | L3: New School | M3: Additional Funding Required
C4: Tender Issuance | D4: 1 | E4: Not Applicable | F4: Site Under Option Agreement | G4: >80% Complete | H4: Architect Estimate | I4: EDU Catalogue | K4: School Consolidation | L4: Addition | M4: Not Applicable
C5: Tender Closed | D5: 1 | F5: Site Purchased | H5: Class D Estimate | K5: French Language Access | L5: Renovation | M5: Not Yet Known
C6: Contract Awarded | D6: 1 | F6: Site Purchased Prior to Capital Approval | H6: Class C Estimate | K6: Other | L6: Disposition
C7: Site Preparation | D7: 2 | F7: Not Applicable | H7: Class B Estimate | L7: Demolition
C8: Construction | D8: 2 | H8: Class A Estimate | L8: Purchase
C9: Substantial Completion | D9: 3 | H9: Based on Tender Results | L9: Other
C10: Completion | D10: 4
C11: Cost Reconciliation
A13: % Construction Progress | C13: Phase (List) | D13: Project Status | E13: Submission Type | F13: Project Risks | G13: Risk Rating | H13: Site Funding Source | I13: Mitigation Strategies | J13: Sign Installed
A14: 10 | C14: 0 | D14: In Progress | E14: CP | F14: Cost | G14: Low | H14: EDC | I14: Accept | J14: Yes
A15: 20 | C15: 1 | D15: Remove from tracker (Cancelled) | E15: Ad Hoc | F15: Delay | G15: Medium | H15: LP | I15: Mitigate | J15: No
A16: 30 | C16: 2 | D16: Remove from tracker (Complete) | F16: Delay/Cost | G16: High | H16: LP/EDC | I16: Transfer | J16: No Site Purchased
A17: 40 | C17: 3 | I17: Avoid
A18: 50 | C18: 4 | F18: Market Risk
A19: 60 | F19: Governance Risk
A20: 70 | F20: Organization/Project Management Risk
A21: 80 | F21: Design Risk
A22: 90 | F22: Procurement/Tender Risk
A23: 100 | F23: Site Readiness/Enabling Works
F24: Permit, Licenses and Approvals
A25: Type of Design | F25: Construction Risk
A26: New | F26: Testing and Commissioning
A27: Repeat
A28: Catalogue
B32: Primary Contact
B33: Senior Buisness Official
B34: Director of Education
B35: Finance Contact
B36: Construction/Project Management Contact

Sheet Translation
A1: ='Project Commitment'!A2 -> English
A2: Output | B2: English | C2: French
A3: Monthly Update Sheet
A4: =IF($A$1="English",B4,C4) -> Meeting Date | B4: Meeting Date
A5: =IF($A$1="English",B5,C5) -> Section 1: Project Details | B5: Section 1: Project Details | C5: Détails associés aux projets
A6: =IF($A$1="English",B6,C6) -> Project ID | B6: Project ID
A7: =IF($A$1="English",B7,C7) -> Project Name | B7: Project Name
A8: =IF($A$1="English",B8,C8) -> Address | B8: Address
A9: =IF($A$1="English",B9,C9) -> City | B9: City
A10: =IF($A$1="English",B10,C10) -> Postal Code | B10: Postal Code
A11: =IF($A$1="English",B11,C11) -> Project Type | B11: Project Type
A12: =IF($A$1="English",B12,C12) -> Approval Period | B12: Approval Period
A13: =IF($A$1="English",B13,C13) -> Project Category | B13: Project Category
A14: =IF($A$1="English",B14,C14) -> Project Status | B14: Project Status
A15: =IF($A$1="English",B15,C15) -> Construction Status | B15: Construction Status
A16: =IF($A$1="English",B16,C16) -> Section 2: Square Footage Specification | B16: Section 2: Square Footage Specification
A17: =IF($A$1="English",B17,C17) -> Anticipate Design Change? | B17: Anticipate Design Change?
... A45: =IF($A$1="English",B45,C45) -> Project Reconciliation | B45: Project Reconciliation
A46: =IF($A$1="English",B46,C46) -> Section 7: Approved Project Funding | B46: Section 7: Approved Project Funding | C46: Financement approuvé du projet
A47: =IF($A$1="English",B47,C47) -> LP/EDC | B47: LP/EDC
A48: =IF($A$1="English",B48,C48) -> CP | B48: CP
A49: =IF($A$1="English",B49,C49) -> CC | B49: CC
A50: =IF($A$1="English",B50,C50) -> Other | B50: Other
A51: =IF($A$1="English",B51,C51) -> Total Approved Funding | B51: Total Approved Funding
A52: =IF($A$1="English",B52,C52) -> Section 8: Projected Construction Cost | B52: Section 8: Projected Construction Cost | C52: Coût prévu du projet
A53: =IF($A$1="English",B53,C53) -> Basis of Cost Estimate | B53: Basis of Cost Estimate
A54: =IF($A$1="English",B54,C54) -> Land Cost | B54: Land Cost
A55: =IF($A$1="English",B55,C55) -> Building Cost - School | B55: Building Cost - School
A56: =IF($A$1="English",B56,C56) -> Soft Costs - School | B56: Soft Costs - School
A57: =IF($A$1="English",B57,C57) -> Building Cost - Child Care | B57: Building Cost - Child Care
A58: =IF($A$1="English",B58,C58) -> Soft Costs -Child Care | B58: Soft Costs -Child Care
A59: =IF($A$1="English",B59,C59) -> Unique Site Costs - School | B59: Unique Site Costs - School
A60: =IF($A$1="English",B60,C60) -> Unique Site Costs - Child Care | B60: Unique Site Costs - Child Care
A61: =IF($A$1="English",B61,C61) -> Unique Site Costs - Other | B61: Unique Site Costs - Other
A62: =IF($A$1="English",B62,C62) -> Municipal/Extraordinary Cost - School | B62: Municipal/Extraordinary Cost - School
A63: =IF($A$1="English",B63,C63) -> Municipal/Extraordinary Cost - Child Care | B63: Municipal/Extraordinary Cost - Child Care
A64: =IF($A$1="English",B64,C64) -> Municipal/Extraordinary Cost - Other | B64: Municipal/Extraordinary Cost - Other
... A70: =IF($A$1="English",B70,C70) -> Opening Ceremony - Date | B70: Opening Ceremony - Date
A71: =IF($A$1="English",B71,C71) -> Section 10: General Comments | B71: Section 10: General Comments | C71: Commentaires
A72: =IF($A$1="English",B72,C72) -> Section 10: Project Risks and Mitigation Stategies | B72: Section 10: Project Risks and Mitigation Stategies
...
