Workbook

Sheet form
A1: monthly_v2.0

Sheet Instructions and Glossary
A1: Project Tracker - Instructions
B4: Purpose | C4: The Project Tracker is a tool for capital analysts to capture information about each board's projects. This data provides a line of sight into project progress and details that is critical to both analysts, other folks within the branch, and management. The data gathered here facilitates project accountability and oversight of project milestones and finances.
B6: Instructions
B7: During Meetings with the Board | C7: When analysts meet with their board to discuss projects, you should use this tool to guide your meetings and capture information. Make sure you update the meeting date on the Monthly Tracker worksheet. You'll notice that this sheet has conditional formatting that greys out the sheet when the meeting date is not set to the current day. This is done so you have a visual reminder to update this date before you talk with your boards. Taking comprehensive minutes is especially important part of your meetings with the boards. The template provides space for you to enter project-specific minutes, as well as a section for minuting any more general information discussed that might not fall under one specific project. The data is scraped regularly and then the template is regenerated with updated information. During this process, minutes are archived and relocated to the far-left side of the template (column BD), sorted with the most recent minutes closest to the left.
B8: As Needed | C8: If you need to update information at any time other than during a meeting with the board, you are free to do so and the revised information will be captured the next time the data team extracts data from worksheet. Do NOT change the meeting date during any such ad-hoc updates. You should only change the meeting dates when you actually meet with the school board.
B9: General Information & Error Checking | C9: As mentioned above, the Monthly Update worksheet contains conditional formatting that incentivizes you not to forget to enter a meeting date when you talk with the school board. You will notice that once the meeting date is has passed (i.e., it is something other than the current date), the whole sheet goes grey. This provides a visual cue for you to update the date prior to meeting with your board. The sheet also contains some automatic error checking. Cells contain errors when they are highlighted in purple. To determine the reason for the error, scroll over to columns CY to ES. This section contains the same columns as the main table; cells in this table will only contains text if there is an error. That text will describe the cause of the error in the corresponding cell in the main table.
B11: Within-Budget Acknowledgement Process
B12: Analyst Checks | C12: Confirm that the board has submitted all necessary documentation: •Class A/B cost estimate •Revised CPBF form that reflects the Class A/B cost estimate. •80% design drawings that align with the cost estimate and approved space template. •Child care floor plan approval letter (if applicable). Ensure that all documents are saved in the appropriate folder on the Share Drive. Once you have checked and confirmed all documents, send an email to the board acknowledging receipt of the pre/post tender package.
B13: Record Keeping | C13: Create a folder in the following directory: \\csc.ad.gov.on.ca\dfs$\GrpData\CBSD\CAPITAL\STRATEGY\Operations\BOARDS\^Project Commitment\Pre & Post Tender Check-In •The folder should be named using the following naming format: project id # YYYY-MM-DD Example: 12-123 # 2025-12-30 •The date in the folder name should be the date of the email acknowledging receipt of the documents and confirming the board can proceed. •Save the following in the folder you created above: o The CPBF form that reflects the pre-tender/post-tender budget. o The email to the school board (sent within 7 days of the board’s submission) confirming all documents have been submitted and that the ministry has no concerns with the board proceeding to tender/awarding the contract.
A15: Project Tracker Glossary
B17: Overview of the Worksheets within the Project Tracker
B18: Board Contacts | C18: Use this worksheet to enter the contact information for your boards. This is a central location for Capital Analysts to store this information, as well as a place where management and other analysts can go if they need this information. This is important to support coverage for analysts who are absent.
B19: Monthly Update | C19: Use this tab to memorialize meetings with the school boards. See instructions above and glossary below for more information.
B20: Basic Project Info | C20: Use this worksheet to enter the official school name, the school's location information, sign installation information, and the opening ceremony date. See below for a glossary, defining what should be entered in each column.
B21: Ad-Hoc or Potential Projects | C21: Use this worksheet to enter data about potential projects that have not yet been approved or about ad-hoc, minor projects that don't show up on the Monthly Tracker sheet.
B22: Project Commitment | C22: This sheet is for your reference only. It is not editable. It provides information about the current project commitment for the projects for this board.
A24: Glossary - Basic Project Info Tab
A26: ='Basic Project Info'!A2 -> Section 1: Project Details
A27: Col 1 | B27: =_xlfn.XLOOKUP(A27,'Basic Project Info'!$A$3:$L$3, 'Basic Project Info'!$A$4:$L$4) -> Project ID | C27: =C44 -> Automatically generated and uneditable. Each project is assigned a unique ID for tracking throughout its lifecycle. The ID displayed here is the ID for the construction portion of the project.
A28: ="Col " & ROW() -ROW($A$27)+1 -> Col 2 | B28: =_xlfn.XLOOKUP(A28,'Basic Project Info'!$A$3:$L$3, 'Basic Project Info'!$A$4:$L$4) -> Project Name | C28: Automatically generated and uneditable. This is the name assigned to the project when it is first approved. It cannot be changed and is constant throughout the project's lifecycle.
A29: ="Col " & ROW() -ROW($A$27)+1 -> Col 3 | B29: =_xlfn.XLOOKUP(A29,'Basic Project Info'!$A$3:$L$3, 'Basic Project Info'!$A$4:$L$4) -> Official School Name | C29: Use this field to update the official school name that will be used after the school is open. Please use the complete name and do not use abbreviations (e.g. use "Example Public School" instead of "Example" or "Example P.S.". If this project is an addition, this field can be completed as soon as the project is approved.
A30: ="Col " & ROW() -ROW($A$27)+1 -> Col 4 | B30: =_xlfn.XLOOKUP(A30,'Basic Project Info'!$A$3:$L$3, 'Basic Project Info'!$A$4:$L$4) -> Project Type | C30: =C47 -> Automatically generated and uneditable. Project types potentially included in this tracker are: New Construction, Retrofit, Addition, and Purchase.
A31: ="Col " & ROW() -ROW($A$27)+1 -> Col 5 | B31: =_xlfn.XLOOKUP(A31,'Basic Project Info'!$A$3:$L$3, 'Basic Project Info'!$A$4:$L$4) -> Project Category | C31: =C48 -> Automatically generated and uneditable. This field identifies the need that is met by the project. Potential project categories that could be included on this tracker are: Accommodation Pressure, Child Care, Facility Condition, Consolidation, and French Language Access.
A32: ="Col " & ROW() -ROW($A$27)+1 -> Col 6 | B32: =_xlfn.XLOOKUP(A32,'Basic Project Info'!$A$3:$L$3, 'Basic Project Info'!$A$4:$L$4) -> Address | C32: Enter the address for the school. If it's not yet known, leave it blank.
A33: ="Col " & ROW() -ROW($A$27)+1 -> Col 7 | B33: =_xlfn.XLOOKUP(A33,'Basic Project Info'!$A$3:$L$3, 'Basic Project Info'!$A$4:$L$4) -> City | C33: Use this field to enter the city/town where the project is located. This should be known at the time of project approval and be pre-populated on the template. Therefore, this field can be left unedited except for very rare circumstances.
A34: ="Col " & ROW() -ROW($A$27)+1 -> Col 8 | B34: =_xlfn.XLOOKUP(A34,'Basic Project Info'!$A$3:$L$3, 'Basic Project Info'!$A$4:$L$4) -> Postal Code | C34: Enter the postal code of the school. If the it's not yet known, leave it blank.
A35: ="Col " & ROW() -ROW($A$27)+1 -> Col 9 | B35: =_xlfn.XLOOKUP(A35,'Basic Project Info'!$A$3:$L$3, 'Basic Project Info'!$A$4:$L$4) -> Latitude | C35: Enter the latitude of the school. This information should be updated once the site has been purchased.
A36: ="Col " & ROW() -ROW($A$27)+1 -> Col 10 | B36: =_xlfn.XLOOKUP(A36,'Basic Project Info'!$A$3:$L$3, 'Basic Project Info'!$A$4:$L$4) -> Longitude | C36: Enter the longitude of the school. This information should be updated once the site has been purchased.
A37: ='Basic Project Info'!K2 -> Section 2: Communications Issues
A38: ="Col " & ROW() -ROW($A$27) -> Col 11 | B38: =_xlfn.XLOOKUP(A38,'Basic Project Info'!$A$3:$L$3, 'Basic Project Info'!$A$4:$L$4) -> Sign Installed | C38: Indicate whether the board has installed a sign on the project site.
A39: ="Col " & ROW() -ROW($A$27) -> Col 12 | B39: =_xlfn.XLOOKUP(A39,'Basic Project Info'!$A$3:$L$3, 'Basic Project Info'!$A$4:$L$4) -> Opening Ceremony - Date | C39: Use this once the project approaches completion if the board plans an opening ceremony. Otherwise, leave this blank.
A41: Glossary - Monthly Update Tab
A43: ='Monthly Update'!A5 -> Section 1: Project Details
A44: Col 1 | B44: =_xlfn.XLOOKUP(A44, 'Monthly Update'!$A$6:$AW$6, 'Monthly Update'!$A$7:$AW$7) -> Project ID | C44: Automatically generated and uneditable. Each project is assigned a unique ID for tracking throughout its lifecycle. The ID displayed here is the ID for the construction portion of the project.
A45: Col 2 | B45: =_xlfn.XLOOKUP(A45, 'Monthly Update'!$A$6:$AW$6, 'Monthly Update'!$A$7:$AW$7) -> Project Name | C45: Automatically generated and uneditable. This is the name assigned to the project when it is first approved. It cannot be changed and is constant throughout the project's lifecycle. The official name of the school can be modified on the Basic Project Info tab.
A46: Col 3 | B46: =_xlfn.XLOOKUP(A46, 'Monthly Update'!$A$6:$AW$6, 'Monthly Update'!$A$7:$AW$7) -> Meeting Minutes | C46: Enter details about each project based on conversations with the school board.
A47: Col 4 | B47: =_xlfn.XLOOKUP(A47, 'Monthly Update'!$A$6:$AW$6, 'Monthly Update'!$A$7:$AW$7) -> Project Type | C47: Automatically generated and uneditable. Project types potentially included in this tracker are: New Construction, Retrofit, Addition, and Purchase.
A48: Col 5 | B48: =_xlfn.XLOOKUP(A48, 'Monthly Update'!$A$6:$AW$6, 'Monthly Update'!$A$7:$AW$7) -> Project Category | C48: Automatically generated and uneditable. This field identifies the need that is met by the project. Potential project categories that could be included on this tracker are: Accommodation Pressure, Child Care, Facility Condition, Consolidation, and French Language Access.
A49: Col 6 | B49: =_xlfn.XLOOKUP(A49, 'Monthly Update'!$A$6:$AW$6, 'Monthly Update'!$A$7:$AW$7) -> Record Status | C49: This drop-down determines which projects will be removed from your trackers. If you want to remove a project, you must identify whether it has been completed or cancelled. The default is for projects to remain on the tracker. When projects are removed from the tracker, it triggers an email notification to your manager and director.
A50: Col 7 | B50: =_xlfn.XLOOKUP(A50, 'Monthly Update'!$A$6:$AW$6, 'Monthly Update'!$A$7:$AW$7) -> Project Status | C50: Automatically generated and uneditable. This field is calculated based on the dates provided to the right in this sheet. If the meeting date is after the opening date, the construction status is "Open"; if the meeting date is after the construction date, the status is "Under Construction". Otherwise the project status is "Planning".
...

Sheet Board Contacts
A1: School Board Contact List
A4: Name | B4: Role | C4: Title | D4: Email | E4: Phone
A5: *((tbl*((board_contacts*((col*((name | B5: *((col*((role | C5: *((col*((title | D5: *((col*((email | E5: *((col*((phone

Sheet Basic Project Info
A1: Basic Project Information
A2: =Translation!A5 -> Section 1: Project Details | K2: Section 2: Communications Issues
A3: ="Col "&COLUMN() -> Col 1 | B3: ="Col "&COLUMN() -> Col 2 | C3: ="Col "&COLUMN() -> Col 3 | D3: ="Col "&COLUMN() -> Col 4 | E3: ="Col "&COLUMN() -> Col 5 | F3: ="Col "&COLUMN() -> Col 6 | G3: ="Col "&COLUMN() -> Col 7 | H3: ="Col "&COLUMN() -> Col 8 | ... L3: ="Col "&COLUMN() -> Col 12
A4: =Translation!A6 -> Project ID | B4: =Translation!A7 -> Project Name | C4: Official School Name | D4: =Translation!A11 -> Project Type | E4: =Translation!A13 -> Project Category | F4: =Translation!A8 -> Address | G4: =Translation!A9 -> City | H4: =Translation!A10 -> Postal Code | I4: Latitude | J4: Longitude | K4: Sign Installed | L4: =Translation!A70 -> Opening Ceremony - Date
A5: No. de projet | B5: Nom du projet | D5: Type de projet | E5: Catégorie de projet
A7: *((tbl*((basic_project_info*((col*((project_id | B7: *((col*((project_name | C7: *((col*((project_name_official | D7: *((col*((project_type | E7: *((col*((project_category | F7: *((col*((location_address | G7: *((col*((location_city | H7: *((col*((location_postal_code | I7: *((col*((location_latitude | J7: *((col*((location_longitude | K7: *((col*((sign_installed | L7: *((col*((date_opening_ceremony
A100: 1 | B100: 1 | C100: 1 | D100: 1 | E100: 1 | F100: 1 | G100: 1 | H100: 1 | I100: 1 | J100: 1 | K100: 1 | L100: 1

Sheet Monthly Update
A1: Monthly Project Updates | C1: *((var*((board_number_name
E2: *((var*((missing_data_count*((formula*((right | F2: =COLUMNS($D$3:$AW$3) - COUNTIF($D$3:$AW$3, "") -> 0
A3: Meeting Date | C3: *((var*((date_meeting | CR3: *((var*((error_count*((formula*((down | CS3: =AND(CR3, ISBLANK(CS11)) -> TRUE | CT3: =AND(CT4, ISBLANK(CT11)) -> FALSE | CU3: =AND(CU4, ISBLANK(CU11)) -> FALSE | CV3: =AND(CV4, ISBLANK(CV11)) -> FALSE | CW3: =AND(CW4, ISBLANK(CW11)) -> FALSE | CX3: =AND(CX4, ISBLANK(CX11)) -> FALSE | CY3: =AND(CY4, ISBLANK(CY11)) -> FALSE | CZ3: =AND(CZ4, ISBLANK(CZ11)) -> FALSE | DA3: =AND(DA4, ISBLANK(DA11)) -> FALSE | ... DI3: =AND(DI4, ISBLANK(DI11)) -> FALSE | DK3: =AND(DK4, ISBLANK(DK11)) -> FALSE | DL3: =AND(DL4, ISBLANK(DL11)) -> FALSE | DM3: =AND(DM4, ISBLANK(DM11)) -> FALSE | DO3: =AND(DO4, ISBLANK(DO11)) -> FALSE | DP3: =AND(DP4, ISBLANK(DP11)) -> FALSE | DQ3: =AND(DQ4, ISBLANK(DQ11)) -> FALSE | DR3: =AND(DR4, ISBLANK(DR11)) -> FALSE | DS3: =AND(DS4, ISBLANK(DS11)) -> FALSE | DT3: =AND(DT4, ISBLANK(DT11)) -> FALSE | DU3: =AND(DU4, ISBLANK(DU11)) -> FALSE | DV3: =AND(DV4, ISBLANK(DV11)) -> FALSE | ... EO3: =AND(EO4, ISBLANK(EO11)) -> FALSE
B4: General Meeting Minutes: | C4: *((var*((meeting_minutes_general_current | AV4: Historical General Meeting Minutes -------------> | AX4: *((tbl*((meeting_minutes_general*((col*((meeting_minutes_general_minus_1 | AY4: ="*((col*((meeting_minutes_general_minus_"&COLUMN()-COLUMN($AX$4)+1 -> *((col*((meeting_minutes_general_minus_2 | AZ4: ="*((col*((meeting_minutes_general_minus_"&COLUMN()-COLUMN($AX$4)+1 -> *((col*((meeting_minutes_general_minus_3 | BA4: ="*((col*((meeting_minutes_general_minus_"&COLUMN()-COLUMN($AX$4)+1 -> *((col*((meeting_minutes_general_minus_4 | BB4: ="*((col*((meeting_minutes_general_minus_"&COLUMN()-COLUMN($AX$4)+1 -> *((col*((meeting_minutes_general_minus_5 | BC4: ="*((col*((meeting_minutes_general_minus_"&COLUMN()-COLUMN($AX$4)+1 -> *((col*((meeting_minutes_general_minus_6 | BD4: ="*((col*((meeting_minutes_general_minus_"&COLUMN()-COLUMN($AX$4)+1 -> *((col*((meeting_minutes_general_minus_7 | BE4: ="*((col*((meeting_minutes_general_minus_"&COLUMN()-COLUMN($AX$4)+1 -> *((col*((meeting_minutes_general_minus_8 | BF4: ="*((col*((meeting_minutes_general_minus_"&COLUMN()-COLUMN($AX$4)+1 -> *((col*((meeting_minutes_general_minus_9 | ... BU4: ="*((col*((meeting_minutes_general_minus_"&COLUMN()-COLUMN($AX$4)+1 -> *((col*((meeting_minutes_general_minus_24 | CR4: =COUNTA(CS10:EO105) -> 99 | CS4: =ISNUMBER(SEARCH("formula", CS10)) -> FALSE | CT4: =ISNUMBER(SEARCH("formula", CT10)) -> FALSE | CU4: =ISNUMBER(SEARCH("formula", CU10)) -> TRUE | CV4: =ISNUMBER(SEARCH("formula", CV10)) -> FALSE | CW4: =ISNUMBER(SEARCH("formula", CW10)) -> FALSE | CX4: =ISNUMBER(SEARCH("formula", CX10)) -> FALSE | CY4: =ISNUMBER(SEARCH("formula", CY10)) -> TRUE | CZ4: =ISNUMBER(SEARCH("formula", CZ10)) -> TRUE | ... DI4: =ISNUMBER(SEARCH("formula", DI10)) -> TRUE | DK4: =ISNUMBER(SEARCH("formula", DK10)) -> TRUE | DL4: =ISNUMBER(SEARCH("formula", DL10)) -> TRUE | DM4: =ISNUMBER(SEARCH("formula", DM10)) -> TRUE | DO4: =ISNUMBER(SEARCH("formula", DO10)) -> TRUE | DP4: =ISNUMBER(SEARCH("formula", DP10)) -> TRUE | DQ4: =ISNUMBER(SEARCH("formula", DQ10)) -> FALSE | DR4: =ISNUMBER(SEARCH("formula", DR10)) -> TRUE | DS4: =ISNUMBER(SEARCH("formula", DS10)) -> FALSE | DT4: =ISNUMBER(SEARCH("formula", DT10)) -> TRUE | DU4: =ISNUMBER(SEARCH("formula", DU10)) -> TRUE | DV4: =ISNUMBER(SEARCH("formula", DV10)) -> TRUE | ... EO4: =ISNUMBER(SEARCH("formula", EO10)) -> TRUE
A5: Section 1: Project Details | H5: Section 2: Project Commitment Progress | P5: Section 3: Pre-Tender | AD5: Section 4: Construction | AI5: Section 5: Project Completion | AN5: Section 6: Approved Project Funding | AS5: Section 7: Projected Cost | AX5: Section 8: Historical Meeting Minutes | CS5: Error Messages | CX5: Error Messages | DG5: Error Messages | DM5: Error Messages | DR5: Error Messages | DU5: Error Messages | DX5: Error Messages | EC5: Error Messages | EH5: Error Messages | EM5: Error Messages
A6: ="Col "&COLUMN() -> Col 1 | B6: ="Col "&COLUMN() -> Col 2 | C6: ="Col "&COLUMN() -> Col 3 | D6: ="Col "&COLUMN() -> Col 4 | E6: ="Col "&COLUMN() -> Col 5 | F6: ="Col "&COLUMN() -> Col 6 | G6: ="Col "&COLUMN() -> Col 7 | H6: ="Col "&COLUMN() -> Col 8 | ... BU6: ="Col "&COLUMN() -> Col 73 | CS6: =A6 -> Col 1 | CT6: =B6 -> Col 2 | CU6: =C6 -> Col 3 | CV6: =D6 -> Col 4 | CW6: =E6 -> Col 5 | CX6: =F6 -> Col 6 | CY6: =G6 -> Col 7 | CZ6: =H6 -> Col 8 | ... EO6: =AW6 -> Col 49 | ES6: =K6 -> Col 11 | ET6: =ES6 -> Col 11 | EU6: =ET6 -> Col 11 | EV6: =EU6 -> Col 11 | EW6: =O6 -> Col 15 | EX6: =EW6 -> Col 15 | EY6: =EX6 -> Col 15 | EZ6: =EY6 -> Col 15 | FA6: =P6 -> Col 16 | FB6: =FA6 -> Col 16 | FC6: =FB6 -> Col 16 | FD6: =FC6 -> Col 16 | FE6: =Q6 -> Col 17 | FF6: =FE6 -> Col 17 | FG6: =FF6 -> Col 17 | FH6: =FG6 -> Col 17
A7: Project ID | B7: Project Name | C7: Meeting Minutes | D7: Project Type | E7: Project Category | F7: Record Status | G7: Project Status | H7: Pre-Tender Submission Date | I7: Pre-Tender Package Type | J7: Pre-Tender Package Complete | K7: CA Reviewed All Pre-Tender Documents | L7: Post-Tender Submission Date | M7: Post-Tender Package Type | N7: Post-Tender Package Complete | O7: CA Reviewed All Post-Tender Documents | P7: Site Ownership Status | Q7: Site Purchase Date | R7: =Q7&" Error Explanation" -> Site Purchase Date Error Explanation | S7: Design Status | T7: Space Template Approval Date | U7: Child Care Floorplan Approval Date | V7: =U7&" Error Explanation" -> Child Care Floorplan Approval Date Error Explanation | W7: Initial Site Plan Submission Date | X7: Site Plan Approval Date | Y7: Site Plan Approval Date Error Explanation | Z7: Build Permit Obtained Date | AA7: =Z7&" Error Explanation" -> Build Permit Obtained Date Error Explanation | AB7: Tender Issued Date | AC7: Tender Closed Date | AD7: Contract Awarded Date | AE7: Construction Start Date | AF7: =AE7&" Error Explanation" -> Construction Start Date Error Explanation | AG7: Substantial Completion Date | AH7: =AG7&" Error Explanation" -> Substantial Completion Date Error Explanation | AI7: School Opening Date | AJ7: =AI7&" Error Explanation" -> School Opening Date Error Explanation | AK7: Child Care Opening Date | AL7: =AK7&" Error Explanation" -> Child Care Opening Date Error Explanation | AM7: Financial Close-Out Date | AN7: Funding - All Associated Projects | AO7: Funding - Construction Project | AP7: Funding - Site Acquisition | AQ7: Funding - Demolition | AR7: Funding - All Other Associated Projects | AS7: Basis of Cost Estimate | AT7: Estimated Cost - Construction Project | AU7: Estimated Cost - Land | AV7: Estimated Cost - Demolition | AW7: Estimated Cost - All Other Associated Projects | AX7: ="*((tbl*((meeting_minutes_heading"&AX10 -> *((tbl*((meeting_minutes_heading*((col*((meeting_minutes_minus_1 | AY7: =AY10 -> *((col*((meeting_minutes_minus_2 | AZ7: =AZ10 -> *((col*((meeting_minutes_minus_3 | BA7: =BA10 -> *((col*((meeting_minutes_minus_4 | BB7: =BB10 -> *((col*((meeting_minutes_minus_5 | BC7: =BC10 -> *((col*((meeting_minutes_minus_6 | BD7: =BD10 -> *((col*((meeting_minutes_minus_7 | BE7: =BE10 -> *((col*((meeting_minutes_minus_8 | BF7: =BF10 -> *((col*((meeting_minutes_minus_9 | ... BU7: =BU10 -> *((col*((meeting_minutes_minus_24 | BW7: *((table_end*((meeting_minutes_heading | BY7: cc_amount | BZ7: ='Project Commitment'!M4 -> Site Purchase Date | CA7: ='Project Commitment'!N4 -> Space Template Approval Date | CB7: ='Project Commitment'!O4 -> Child Care Floorplan Approval Date | CC7: ='Project Commitment'!P4 -> Initial Site Plan Submission Date | CD7: ='Project Commitment'!Q4 -> Site Plan Approval Date | CE7: ='Project Commitment'!R4 -> Build Permit Obtained Date | CF7: ='Project Commitment'!S4 -> Pre-Tender Submission Date | CG7: ='Project Commitment'!T4 -> Tender Issued Date | ... CO7: ='Project Commitment'!AB4 -> Financial Close-Out Date | CS7: =A7 -> Project ID | CT7: =B7 -> Project Name | CU7: =C7 -> Meeting Minutes | CV7: =D7 -> Project Type | CW7: =E7 -> Project Category | CX7: =F7 -> Record Status | CY7: =G7 -> Project Status | CZ7: =H7 -> Pre-Tender Submission Date | ... EO7: =AW7 -> Estimated Cost - All Other Associated Projects
A8: No. de projet | B8: Nom du projet | D8: Type de projet | E8: Catégorie de projet | AP8: IP | AQ8: Service de garde | AR8: Autre | AS8: Base de l'estimation des coûts | AW8: Coûts du site | DI8: =Q8 -> 0
DI9: =Q9 -> 0
A10: *((tbl*((monthly*((col*((project_id | B10: *((col*((project_name | C10: *((col*((meeting_minutes | D10: *((col*((project_type | E10: *((col*((project_category | F10: *((col*((record_status | G10: *((col*((construction_status*((formula*((down | H10: *((col*((date_pretender | I10: *((col*((pretender_package_type | J10: *((col*((pre_tender_complete | K10: *((col*((pre_tender_documents_reviewed | L10: *((col*((date_posttender | M10: *((col*((posttender_package_type | N10: *((col*((post_tender_complete | O10: *((col*((post_tender_documents_reviewed | P10: *((col*((site_status | Q10: *((col*((date_site_purchase | R10: ="*((col*((error_explained_"&RIGHT(Q10, LEN(Q10)-9) -> *((col*((error_explained_date_site_purchase | S10: *((col*((design_status | T10: *((col*((date_space_template | U10: *((col*((date_cc_floorplan | V10: ="*((col*((error_explained_"&RIGHT(U10, LEN(U10)-9) -> *((col*((error_explained_date_cc_floorplan | W10: *((col*((date_site_plan_submission | X10: *((col*((date_site_plan_approved | Y10: ="*((col*((error_explained_"&RIGHT(X10, LEN(X10)-9) -> *((col*((error_explained_date_site_plan_approved | Z10: *((col*((date_building_permit | AA10: ="*((col*((error_explained_date_building_permit" -> *((col*((error_explained_date_building_permit | AB10: *((col*((date_tender_issue | AC10: *((col*((date_tender_closed | AD10: *((col*((date_tender | AE10: *((col*((date_construction | AF10: ="*((col*((error_explained_date_construction" -> *((col*((error_explained_date_construction | AG10: *((col*((date_substantial_completion | AH10: ="*((col*((error_explained_date_substantial_completion" -> *((col*((error_explained_date_substantial_completion | AI10: *((col*((date_opening | AJ10: ="*((col*((error_explained_date_opening" -> *((col*((error_explained_date_opening | AK10: *((col*((date_opening_cc | AL10: ="*((col*((error_explained_date_opening_cc" -> *((col*((error_explained_date_opening_cc | AM10: *((col*((date_completion | AN10: *((col*((funding_all*((formula*((down | AO10: *((col*((funding_construction | AP10: *((col*((funding_site | AQ10: *((col*((funding_demo | AR10: *((col*((funding_other_projects | AS10: *((col*((cost_basis | AT10: *((col*((cost_estimate_construction | AU10: *((col*((cost_estimate_land | AV10: *((col*((cost_estimate_demo | AW10: *((col*((cost_estimate_other_projects | AX10: *((col*((meeting_minutes_minus_1 | AY10: *((col*((meeting_minutes_minus_2 | AZ10: *((col*((meeting_minutes_minus_3 | BA10: *((col*((meeting_minutes_minus_4 | BB10: *((col*((meeting_minutes_minus_5 | BC10: *((col*((meeting_minutes_minus_6 | BD10: *((col*((meeting_minutes_minus_7 | BE10: *((col*((meeting_minutes_minus_8 | BF10: *((col*((meeting_minutes_minus_9 | BG10: *((col*((meeting_minutes_minus_10 | BH10: *((col*((meeting_minutes_minus_11 | BI10: *((col*((meeting_minutes_minus_12 | BJ10: *((col*((meeting_minutes_minus_13 | BK10: *((col*((meeting_minutes_minus_14 | BL10: *((col*((meeting_minutes_minus_15 | BM10: *((col*((meeting_minutes_minus_16 | BN10: *((col*((meeting_minutes_minus_17 | BO10: *((col*((meeting_minutes_minus_18 | BP10: *((col*((meeting_minutes_minus_19 | BQ10: *((col*((meeting_minutes_minus_20 | BR10: *((col*((meeting_minutes_minus_21 | BS10: *((col*((meeting_minutes_minus_22 | BT10: *((col*((meeting_minutes_minus_23 | BU10: *((col*((meeting_minutes_minus_24 | BX10: *((col*((site_ownership_formula*((formula*((down | BY10: *((col*((scope_cc_spaces_added | BZ10: ="*((col*((temp_formula_"&COLUMN()&"*((formula*((down" -> *((col*((temp_formula_78*((formula*((down | CA10: ="*((col*((temp_formula_"&COLUMN()&"*((formula*((down" -> *((col*((temp_formula_79*((formula*((down | CB10: ="*((col*((temp_formula_"&COLUMN()&"*((formula*((down" -> *((col*((temp_formula_80*((formula*((down | CC10: ="*((col*((temp_formula_"&COLUMN()&"*((formula*((down" -> *((col*((temp_formula_81*((formula*((down | CD10: ="*((col*((temp_formula_"&COLUMN()&"*((formula*((down" -> *((col*((temp_formula_82*((formula*((down | CE10: ="*((col*((temp_formula_"&COLUMN()&"*((formula*((down" -> *((col*((temp_formula_83*((formula*((down | CF10: ="*((col*((temp_formula_"&COLUMN()&"*((formula*((down" -> *((col*((temp_formula_84*((formula*((down | CG10: ="*((col*((temp_formula_"&COLUMN()&"*((formula*((down" -> *((col*((temp_formula_85*((formula*((down | ... CO10: ="*((col*((temp_formula_"&COLUMN()&"*((formula*((down" -> *((col*((temp_formula_93*((formula*((down | CU10: ="*((col*((temp_formula_"&COLUMN()&"*((formula*((down" -> *((col*((temp_formula_99*((formula*((down | CY10: ="*((col*((temp_formula_"&COLUMN()&"*((formula*((down" -> *((col*((temp_formula_103*((formula*((down | CZ10: ="*((col*((temp_formula_"&COLUMN()&"*((formula*((down" -> *((col*((temp_formula_104*((formula*((down | DA10: ="*((col*((temp_formula_"&COLUMN()&"*((formula*((down" -> *((col*((temp_formula_105*((formula*((down | DC10: ="*((col*((temp_formula_"&COLUMN()&"*((formula*((down" -> *((col*((temp_formula_107*((formula*((down | DD10: ="*((col*((temp_formula_"&COLUMN()&"*((formula*((down" -> *((col*((temp_formula_108*((formula*((down | DE10: ="*((col*((temp_formula_"&COLUMN()&"*((formula*((down" -> *((col*((temp_formula_109*((formula*((down | DG10: ="*((col*((temp_formula_"&COLUMN()&"*((formula*((down" -> *((col*((temp_formula_111*((formula*((down | DH10: ="*((col*((temp_formula_"&COLUMN()&"*((formula*((down" -> *((col*((temp_formula_112*((formula*((down | DI10: ="*((col*((temp_formula_"&COLUMN()&"*((formula*((down" -> *((col*((temp_formula_113*((formula*((down | DK10: ="*((col*((temp_formula_"&COLUMN()&"*((formula*((down" -> *((col*((temp_formula_115*((formula*((down | DL10: ="*((col*((temp_formula_"&COLUMN()&"*((formula*((down" -> *((col*((temp_formula_116*((formula*((down | DM10: ="*((col*((temp_formula_"&COLUMN()&"*((formula*((down" -> *((col*((temp_formula_117*((formula*((down | DO10: ="*((col*((temp_formula_"&COLUMN()&"*((formula*((down" -> *((col*((temp_formula_119*((formula*((down | DP10: ="*((col*((temp_formula_"&COLUMN()&"*((formula*((down" -> *((col*((temp_formula_120*((formula*((down | DR10: ="*((col*((temp_formula_"&COLUMN()&"*((formula*((down" -> *((col*((temp_formula_122*((formula*((down | DT10: ="*((col*((temp_formula_"&COLUMN()&"*((formula*((down" -> *((col*((temp_formula_124*((formula*((down | DU10: ="*((col*((temp_formula_"&COLUMN()&"*((formula*((down" -> *((col*((temp_formula_125*((formula*((down | DV10: ="*((col*((temp_formula_"&COLUMN()&"*((formula*((down" -> *((col*((temp_formula_126*((formula*((down | DW10: ="*((col*((temp_formula_"&COLUMN()&"*((formula*((down" -> *((col*((temp_formula_127*((formula*((down | DY10: ="*((col*((temp_formula_"&COLUMN()&"*((formula*((down" -> *((col*((temp_formula_129*((formula*((down | EA10: ="*((col*((temp_formula_"&COLUMN()&"*((formula*((down" -> *((col*((temp_formula_131*((formula*((down | EC10: ="*((col*((temp_formula_"&COLUMN()&"*((formula*((down" -> *((col*((temp_formula_133*((formula*((down | EE10: ="*((col*((temp_formula_"&COLUMN()&"*((formula*((down" -> *((col*((temp_formula_135*((formula*((down | EK10: ="*((col*((temp_formula_"&COLUMN()&"*((formula*((down" -> *((col*((temp_formula_141*((formula*((down | EL10: ="*((col*((temp_formula_"&COLUMN()&"*((formula*((down" -> *((col*((temp_formula_142*((formula*((down | EM10: ="*((col*((temp_formula_"&COLUMN()&"*((formula*((down" -> *((col*((temp_formula_143*((formula*((down | EN10: ="*((col*((temp_formula_"&COLUMN()&"*((formula*((down" -> *((col*((temp_formula_144*((formula*((down | EO10: ="*((col*((temp_formula_"&COLUMN()&"*((formula*((down" -> *((col*((temp_formula_145*((formula*((down | ES10: ="*((col*((temp_formula_"&COLUMN()&"*((formula*((down" -> *((col*((temp_formula_149*((formula*((down | ET10: ="*((col*((temp_formula_"&COLUMN()&"*((formula*((down" -> *((col*((temp_formula_150*((formula*((down | EU10: ="*((col*((temp_formula_"&COLUMN()&"*((formula*((down" -> *((col*((temp_formula_151*((formula*((down | EV10: ="*((col*((temp_formula_"&COLUMN()&"*((formula*((down" -> *((col*((temp_formula_152*((formula*((down | EW10: ="*((col*((temp_formula_"&COLUMN()&"*((formula*((down" -> *((col*((temp_formula_153*((formula*((down | EX10: ="*((col*((temp_formula_"&COLUMN()&"*((formula*((down" -> *((col*((temp_formula_154*((formula*((down | EY10: ="*((col*((temp_formula_"&COLUMN()&"*((formula*((down" -> *((col*((temp_formula_155*((formula*((down | EZ10: ="*((col*((temp_formula_"&COLUMN()&"*((formula*((down" -> *((col*((temp_formula_156*((formula*((down | ... FH10: ="*((col*((temp_formula_"&COLUMN()&"*((formula*((down" -> *((col*((temp_formula_164*((formula*((down
G11: {=_xlfn.IFS(A11="", "", OR(AE11="", AI11="", AM11=""), "Missing Data", TODAY()>AM11, "Complete", TODAY()>AI11, "Open", TODAY()>AE11, "Under Construction", TRUE, "Planning")} | AN11: =SUM(AO11:AR11) -> 0 | BX11: =IF(AND(Q11="", A11<>"", P11<>"Site Purchased Prior to Capital Approval"), 1, 0) -> 0 | BZ11: =_xlfn.XLOOKUP($A11, 'Project Commitment'!$A:$A, 'Project Commitment'!M:M, "") -> 0 | CA11: =_xlfn.XLOOKUP($A11, 'Project Commitment'!$A:$A, 'Project Commitment'!N:N, "") -> 0 | CB11: =_xlfn.XLOOKUP($A11, 'Project Commitment'!$A:$A, 'Project Commitment'!O:O, "") -> 0 | CC11: =_xlfn.XLOOKUP($A11, 'Project Commitment'!$A:$A, 'Project Commitment'!P:P, "") -> 0 | CD11: =_xlfn.XLOOKUP($A11, 'Project Commitment'!$A:$A, 'Project Commitment'!Q:Q, "") -> 0 | CE11: =_xlfn.XLOOKUP($A11, 'Project Commitment'!$A:$A, 'Project Commitment'!R:R, "") -> 0 | CF11: =_xlfn.XLOOKUP($A11, 'Project Commitment'!$A:$A, 'Project Commitment'!S:S, "") -> 0 | CG11: =_xlfn.XLOOKUP($A11, 'Project Commitment'!$A:$A, 'Project Commitment'!T:T, "") -> 0 | CH11: =_xlfn.XLOOKUP($A11, 'Project Commitment'!$A:$A, 'Project Commitment'!U:U, "") -> 0 | CI11: =_xlfn.XLOOKUP($A11, 'Project Commitment'!$A:$A, 'Project Commitment'!V:V, "") -> 0 | CJ11: =_xlfn.XLOOKUP($A11, 'Project Commitment'!$A:$A, 'Project Commitment'!W:W, "") -> 0 | CK11: =_xlfn.XLOOKUP($A11, 'Project Commitment'!$A:$A, 'Project Commitment'!X:X, "") -> 0 | CL11: =_xlfn.XLOOKUP($A11, 'Project Commitment'!$A:$A, 'Project Commitment'!Y:Y, "") -> 0 | CM11: =_xlfn.XLOOKUP($A11, 'Project Commitment'!$A:$A, 'Project Commitment'!Z:Z, "") -> 0 | CN11: =_xlfn.XLOOKUP($A11, 'Project Commitment'!$A:$A, 'Project Commitment'!AA:AA, "") -> 0 | CO11: =_xlfn.XLOOKUP($A11, 'Project Commitment'!$A:$A, 'Project Commitment'!AB:AB, "") -> 0 | CU11: =IF(OR(A11="", C11<>""), "", "Meeting Minutes cannot be blank") | CY11: {=_xlfn.IFS(A11="", "", G11<>"Missing Data", "", AE11="", "Construction Start Date cannot be blank", AI11="", "School Opening Date cannot be blank", AM11="", "Financial Close-Out Date cannot be blank", TRUE, "")} | CZ11: {=_xlfn.IFS(A11="", "", AND(J11="Not Necessary", H11<>""), "No date is needed if Column 10 is Not Necessary", AND(J11<>"Not Necessary", H11=""), CZ$7&" cannot be blank", $AE11="", "", H11>$AE11, CZ$7&" must preceed construction start date.", TRUE, "")} | DA11: {=_xlfn.IFS(A11="", "", I11="", DA$7&" cannot be left blank.", H11="", "", AND(H11<TODAY(), I11="Not Yet Known"), "After the submission date, the pre-tender package type must be selected.", TRUE, "")} | DC11: {=_xlfn.IFS(A11="", "", J11="MISSING", "This package is missing!", K11="", "Confirm you reviewed the pretender checkin documents", AND(K11="Not yet submitted/reviewed", J11<>"Not yet submitted/reviewed"), "Pretender package submitted; col 9 can't indicate otherwise.", TRUE, "")} | DD11: {=_xlfn.IFS(A11="", "", AND(N11="Not Necessary", L11<>""), "No date is needed if Column 14 is Not Necessary", AND(N11<>"Not Necessary", L11=""), DD$7&" cannot be blank", $AE11="", "", L11>$AE11, DD$7&" must preceed construction start date.", TRUE, "")} | DE11: {=_xlfn.IFS(A11="", "", M11="", DE$7&" cannot be left blank.", L11="", "", AND(L11<TODAY(), M11="Not Yet Known"), "After the submission date, the pre-tender package type must be selected.", TRUE, "")} | DG11: {=_xlfn.IFS(A11="", "", N11="MISSING", "The post tender package is missing!", O11="", "Confirm you reviewed the post tender check-in documents", AND(O11="Not yet submitted/reviewed", N11<>"Not yet submitted/reviewed"), "Post-tender package submitted; col 9 can't indicate otherwise.", TRUE, "")} | DH11: {=_xlfn.IFS(A11="", "", P11="", "Site Ownership Status cannot be blank", AND(OR(P11="Site Purchased Prior to Capital Approval", P11="Site Purchased"), Q11>TODAY()), "Site purchase date is in the future, but site ownership status indicates site is already purchased", AND(P11<>"Site Purchased Prior to Capital Approval", P11<>"Site Purchased", Q11<=TODAY()), "Site purchase date is in the past, but site ownership status indicates site has not yet been purchased", TRUE, "")} | DI11: {=_xlfn.IFS(A11="", "", R11<>"", "", P11="Not Applicable", "", Q11="", "Site Purchased Date cannot be blank", W11="", "", Q11>W11, "Site Purchase Date must preceed Site Plan Submission.", TRUE, "")} | DK11: =IF(OR(A11="", S11<>""), "", DK$7&" cannot be blank") | DL11: {=_xlfn.IFS(A11="", "", T11="", DL$7&" cannot be blank", AND(J11<>"Not yet submitted/reviewed", T11>TODAY()), DL$7&" cannot be in the future if project is ready for a pre-tender package.", TRUE, "")} | DM11: {=_xlfn.IFS(A11="", "", V11<>"", "", BY11=0, "", U11="", DM$7&" cannot be blank if project includes child care.", U11<I11, DM$7&" must preceed pre-tender package submission date", TRUE, "")} | DO11: {=_xlfn.IFS(A11="", "", W11="", DO$7&" cannot be blank", $AE11="", "", W11>$AE11, DO$7&" must preceed construction start date.", TRUE, "")} | DP11: {=_xlfn.IFS(A11="", "", Y11<>"", "", X11="", DP$7&" cannot be blank", $AE11="", "", X11>$AE11, DP$7&" must preceed construction start date.", TRUE, "")} | DR11: {=_xlfn.IFS(A11="", "", AA11<>"", "", Z11="", DR$7&" cannot be blank", $AE11="", "", Z11>$AE11, DR$7&" must preceed construction start date.", TRUE, "")} | DT11: {=_xlfn.IFS(A11="", "", AB11="", DT$7&" cannot be blank", $AE11="", "", AB11>$AE11, DT$7&" must preceed construction start date.", TRUE, "")} | DU11: {=_xlfn.IFS(A11="", "", AC11="", DU$7&" cannot be blank", $AE11="", "", AC11>$AE11, DU$7&" must preceed construction start date.", TRUE, "")} | DV11: {=_xlfn.IFS(A11="", "", AD11="", DV$7&" cannot be blank", $AE11="", "", AD11>$AE11, DV$7&" must preceed construction start date.", TRUE, "")} | DW11: {=_xlfn.IFS(A11="", "", AF11<>"", "", AE11="", DW$7&" cannot be blank", $AI11="", "", AE11>EDATE($AI11,-12), DW$7&" must preceed school opening date by more than 12 months.", TRUE, "")} | DY11: {=_xlfn.IFS(A11="", "", AH11<>"", "", AG11="", DY$7&" cannot be blank", $AI11="", "", AG11>EDATE($AI11,-1), DY$7&" must preceed school opening date by more than one month.", TRUE, "")} | EA11: {=_xlfn.IFS(A11="", "", AM11="", "", AI11="", EA$7&" cannot be blank", AJ11<>"", "", $AI11="", "", AI11>=EDATE($AM11,-11), EA$7&" must preceed financial close date by at least 12 months.", TRUE, "")} | EC11: {=_xlfn.IFS(A11="", "", BY11=0, "", AK11="", EC$7&" cannot be blank", $AM11="", "", AL11<>"", "", AK11>=EDATE($AM11,0), EC$7&" must preceed financial close date.", TRUE, "")} | EE11: {=_xlfn.IFS(A11="", "", AM11="", EE$7&" cannot be blank", TRUE, "")} | EK11: {=_xlfn.IFS(A11="", "", AS11="", "Basis of Cost Estimate cannot be blank", AND(AE11<TODAY(), AS11<>"Based on Tender Results"), "Contract awarded date suggests estimate should be based on tender results", AND(H11<TODAY(), AS11<>"Based on Class A or B Cost Report"), "If project has already come in for a pre-tender budget, they must have a class A or B cost estimate.", TRUE, "")} | EL11: {=_xlfn.IFS(A11="", "", OR(AO11=0, AO11=""), "", AT11="", EL$7&" cannot be blank.", TRUE, "")} | EM11: {=_xlfn.IFS(A11="", "", OR(AP11=0, AP11=""), "", AU11="", EM$7&" cannot be blank.", TRUE, "")} | EN11: {=_xlfn.IFS(A11="", "", OR(AQ11=0, AQ11=""), "", AV11="", EN$7&" cannot be blank.", TRUE, "")} | EO11: {=_xlfn.IFS(A11="", "", OR(AR11=0, AR11=""), "", AW11="", EO$7&" cannot be blank.", TRUE, "")} | ES11: {=_xlfn.IFS(ET11<>"", ET11, EU11<>"", EU11, EV11<>"", EV11, TRUE, "")} -> Confirm you reviewed the pretender checkin documents | ET11: =IF(J11="MISSING", "This package is missing!", "") | EU11: =IF(K11="", "Confirm you reviewed the pretender checkin documents", "") -> Confirm you reviewed the pretender checkin documents | EV11: =IF(AND(K11="Not yet submitted/reviewed", J11<>"Not yet submitted/reviewed"), "Pretender package submitted; col 9 cann't indicate otherwise.", "") | EW11: {=_xlfn.IFS(EX11<>"", EX11, EY11<>"", EY11, EZ11<>"", EZ11, TRUE, "")} -> Confirm you reviewed the post tender check-in documents | EX11: =IF(N11="MISSING", "The post tender package is missing!", "") | EY11: =IF(O11="", "Confirm you reviewed the post tender check-in documents", "") -> Confirm you reviewed the post tender check-in documents | EZ11: =IF(AND(O11="Not yet submitted/reviewed", N11<>"Not yet submitted/reviewed"), "Post-tender package submitted; col 9 cann't indicate otherwise.", "") | FA11: {=_xlfn.IFS(FB11<>"", FB11, FC11<>"", FC11, TRUE, FD11)} -> Site Ownership Status cannot be blank | FB11: =IF(P11<>"", "", "Site Ownership Status cannot be blank") -> Site Ownership Status cannot be blank | FC11: {=_xlfn.IFS(AND(Q11="", OR(P11="Site Purchased Prior to Capital Approval", P11="Site Purchased")), "", AND(OR(P11="Site Purchased Prior to Capital Approval", P11="Site Purchased"), Q11>TODAY()), "Site purchase date is in the future, but site ownership status indicates site is already purchaseed", TRUE, "")} | FD11: =IF(AND(AND(P11<>"Site Purchased Prior to Capital Approval", P11<>"Site Purchased"), Q11<=TODAY()), "Site purchase date is in the past, but site ownership status indicates site has not yet been purchaseed", "") -> Site purchase date is in the past, but site ownership status indicates site has not yet been purchaseed | FE11: {=_xlfn.IFS(FF11<>"", FF11, FG11<>"", FG11, TRUE,FH11 )} -> Site Purchased Date cannot be blank | FF11: =IF(AND(P11<>"Not Applicable",Q11=""),"Site Purchased Date cannot be blank","") -> Site Purchased Date cannot be blank | FG11: =FA11 -> Site Ownership Status cannot be blank | FH11: {=_xlfn.IFS(Q11="", "", W11="", "", Q11>W11, "Site Purchase Date must preceed Site Plan Submission.", TRUE, "")}
A86: 1 | B86: 1 | C86: 1 | D86: 1 | E86: 1 | F86: 1 | G86: 1 | H86: 1 | I86: 1 | J86: 1 | K86: 1 | L86: 1 | M86: 1 | N86: 1 | O86: 1 | P86: 1 | Q86: 1 | R86: 1 | S86: 1 | T86: 1 | U86: 1 | V86: 1 | W86: 1 | X86: 1 | Y86: 1 | Z86: 1 | AA86: 1 | AB86: 1 | AC86: 1 | AD86: 1 | AE86: 1 | AF86: 1 | AG86: 1 | AH86: 1 | AI86: 1 | AJ86: 1 | AK86: 1 | AL86: 1 | AM86: 1 | AN86: 1 | AO86: 1 | AP86: 1 | AQ86: 1 | AR86: 1 | AS86: 1 | AT86: 1 | AU86: 1 | AV86: 1 | AW86: 1 | AX86: 1 | AY86: 1 | AZ86: 1 | BA86: 1 | BB86: 1 | BC86: 1 | BD86: 1 | BE86: 1 | BF86: 1 | BG86: 1 | BH86: 1 | BI86: 1 | BJ86: 1 | BK86: 1 | BL86: 1 | BM86: 1 | BN86: 1 | BO86: 1 | BP86: 1 | BQ86: 1 | BR86: 1 | BS86: 1 | BT86: 1 | BU86: 1 | BV86: 1 | BW86: 1 | BX86: 1 | BY86: 1 | BZ86: 1 | CA86: 1 | CB86: 1 | CC86: 1 | CD86: 1 | CE86: 1 | CF86: 1 | CG86: 1 | CH86: 1 | CI86: 1 | CJ86: 1 | CK86: 1 | CL86: 1 | CM86: 1 | CN86: 1 | CO86: 1 | CP86: 1 | CQ86: 1 | CR86: 1 | CS86: 1 | CT86: 1 | CU86: 1 | CV86: 1 | CW86: 1 | CX86: 1 | CY86: 1 | CZ86: 1 | DB86: 1 | DC86: 1 | DD86: 1 | DF86: 1 | DG86: 1 | DH86: 1 | DI86: 1 | DK86: 1 | DL86: 1 | DM86: 1 | DO86: 1 | DP86: 1 | DQ86: 1 | DR86: 1 | DS86: 1 | DT86: 1 | DU86: 1 | DV86: 1 | DW86: 1 | DY86: 1 | EA86: 1 | EC86: 1 | EE86: 1 | EF86: 1 | EG86: 1 | EH86: 1 | EI86: 1 | EJ86: 1 | EK86: 1 | EL86: 1 | EM86: 1 | EN86: 1 | EO86: 1 | EP86: 1 | EQ86: 1 | ER86: 1 | ES86: 1 | ET86: 1 | EU86: 1 | EV86: 1 | EW86: 1 | EX86: 1 | EY86: 1 | EZ86: 1 | FA86: 1 | FB86: 1 | FC86: 1 | FD86: 1 | FE86: 1 | FF86: 1 | FG86: 1 | FH86: 1 | FI86: 1 | FJ86: 1 | FK86: 1 | FL86: 1 | FM86: 1 | FN86: 1 | FO86: 1 | FP86: 1 | FQ86: 1 | FR86: 1 | FS86: 1 | FT86: 1 | FU86: 1 | FV86: 1 | FW86: 1 | FX86: 1 | FY86: 1 | FZ86: 1 | GA86: 1 | GB86: 1 | GC86: 1 | GD86: 1 | GE86: 1 | GF86: 1 | GG86: 1 | GH86: 1 | GI86: 1 | GJ86: 1 | GK86: 1 | GL86: 1 | GM86: 1 | GN86: 1 | GO86: 1 | GP86: 1 | GQ86: 1 | GR86: 1 | GS86: 1 | GT86: 1 | GU86: 1 | GV86: 1 | GW86: 1 | GX86: 1 | GY86: 1 | GZ86: 1 | HA86: 1 | HB86: 1 | HC86: 1 | HD86: 1 | HE86: 1 | HF86: 1 | HG86: 1 | HH86: 1

Sheet Errors
A1: Monthly Project Updates - Error Details
A3: Meeting Date
A5: Section 1: Project Details | H5: Section 2: Project Commitment Progress | P5: Section 3: Pre-Tender | AD5: Section 4: Construction | AI5: Section 5: Project Completion | AN5: Section 6: Approved Project Funding | AS5: Section 7: Projected Cost
A6: ="Col "&COLUMN() -> Col 1 | B6: ="Col "&COLUMN() -> Col 2 | C6: ="Col "&COLUMN() -> Col 3 | D6: ="Col "&COLUMN() -> Col 4 | E6: ="Col "&COLUMN() -> Col 5 | F6: ="Col "&COLUMN() -> Col 6 | G6: ="Col "&COLUMN() -> Col 7 | H6: ="Col "&COLUMN() -> Col 8 | ... AW6: ="Col "&COLUMN() -> Col 49
A7: Project ID | B7: Project Name | C7: Meeting Minutes | D7: Project Type | E7: Project Category | F7: Record Status | G7: Construction Status | H7: Pre-Tender Submission Date | I7: Pre-Tender Package Type | J7: Pre-Tender Package Complete | K7: CA Reviewed All Pre-Tender Documents | L7: Post-Tender Submission Date | M7: Post-Tender Package Type | N7: Post-Tender Package Complete | O7: CA Reviewed All Post-Tender Documents | P7: Site Ownership Status | Q7: Site Purchase Date | R7: =Q7&" Error Explanation" -> Site Purchase Date Error Explanation | S7: Design Status | T7: Space Template Approval Date | U7: Child Care Floorplan Approval Date | V7: =U7&" Error Explanation" -> Child Care Floorplan Approval Date Error Explanation | W7: Initial Site Plan Submission Date | X7: Site Plan Approval Date | Y7: Site Plan Approval Date Error Explanation | Z7: Build Permit Obtained Date | AA7: =Z7&" Error Explanation" -> Build Permit Obtained Date Error Explanation | AB7: Tender Issued Date | AC7: Tender Closed Date | AD7: Contract Awarded Date | AE7: Construction Start Date | AF7: =AE7&" Error Explanation" -> Construction Start Date Error Explanation | AG7: Substantial Completion Date | AH7: =AG7&" Error Explanation" -> Substantial Completion Date Error Explanation | AI7: School Opening Date | AJ7: =AI7&" Error Explanation" -> School Opening Date Error Explanation | AK7: Child Care Opening Date | AL7: =AK7&" Error Explanation" -> Child Care Opening Date Error Explanation | AM7: Financial Close-Out Date | AN7: Funding - All Associated Projects | AO7: Funding - Construction Project | AP7: Funding - Site Acquisition | AQ7: Funding - Demolition | AR7: Funding - All Other Associated Projects | AS7: Basis of Cost Estimate | AT7: Estimated Cost - Construction Project | AU7: Estimated Cost - Land | AV7: Estimated Cost - Demolition | AW7: Estimated Cost - All Other Associated Projects
A8: No. de projet | B8: Nom du projet | D8: Type de projet | E8: Catégorie de projet | AP8: IP | AQ8: Service de garde | AR8: Autre | AS8: Base de l'estimation des coûts | AW8: Coûts du site
A10: {=_xlfn.IFS(LEFT('Monthly Update'!A10, 3) = "*((", "", 'Monthly Update'!A10="", "", TRUE, 'Monthly Update'!A10)} | B10: {=_xlfn.IFS(LEFT('Monthly Update'!B10, 3) = "*((", "", 'Monthly Update'!B10="", "", TRUE, 'Monthly Update'!B10)} | C10: {=_xlfn.IFS(LEFT('Monthly Update'!CU10, 3) = "*((", "", 'Monthly Update'!CU10="", "", TRUE, 'Monthly Update'!CU10)} | D10: {=_xlfn.IFS(LEFT('Monthly Update'!CV10, 3) = "*((", "", 'Monthly Update'!CV10="", "", TRUE, 'Monthly Update'!CV10)} | E10: {=_xlfn.IFS(LEFT('Monthly Update'!CW10, 3) = "*((", "", 'Monthly Update'!CW10="", "", TRUE, 'Monthly Update'!CW10)} | F10: {=_xlfn.IFS(LEFT('Monthly Update'!CX10, 3) = "*((", "", 'Monthly Update'!CX10="", "", TRUE, 'Monthly Update'!CX10)} | G10: {=_xlfn.IFS(LEFT('Monthly Update'!CY10, 3) = "*((", "", 'Monthly Update'!CY10="", "", TRUE, 'Monthly Update'!CY10)} | H10: {=_xlfn.IFS(LEFT('Monthly Update'!CZ10, 3) = "*((", "", 'Monthly Update'!CZ10="", "", TRUE, 'Monthly Update'!CZ10)} | I10: {=_xlfn.IFS(LEFT('Monthly Update'!DA10, 3) = "*((", "", 'Monthly Update'!DA10="", "", TRUE, 'Monthly Update'!DA10)} | J10: {=_xlfn.IFS(LEFT('Monthly Update'!DB10, 3) = "*((", "", 'Monthly Update'!DB10="", "", TRUE, 'Monthly Update'!DB10)} | ... AW10: {=_xlfn.IFS(LEFT('Monthly Update'!EO10, 3) = "*((", "", 'Monthly Update'!EO10="", "", TRUE, 'Monthly Update'!EO10)}
A11: {=_xlfn.IFS(LEFT('Monthly Update'!A11, 3) = "*((", "", 'Monthly Update'!A11="", "", TRUE, 'Monthly Update'!A11)} | B11: {=_xlfn.IFS(LEFT('Monthly Update'!B11, 3) = "*((", "", 'Monthly Update'!B11="", "", TRUE, 'Monthly Update'!B11)} | C11: {=_xlfn.IFS(LEFT('Monthly Update'!CU11, 3) = "*((", "", 'Monthly Update'!CU11="", "", TRUE, 'Monthly Update'!CU11)} | D11: {=_xlfn.IFS(LEFT('Monthly Update'!CV11, 3) = "*((", "", 'Monthly Update'!CV11="", "", TRUE, 'Monthly Update'!CV11)} | E11: {=_xlfn.IFS(LEFT('Monthly Update'!CW11, 3) = "*((", "", 'Monthly Update'!CW11="", "", TRUE, 'Monthly Update'!CW11)} | F11: {=_xlfn.IFS(LEFT('Monthly Update'!CX11, 3) = "*((", "", 'Monthly Update'!CX11="", "", TRUE, 'Monthly Update'!CX11)} | G11: {=_xlfn.IFS(LEFT('Monthly Update'!CY11, 3) = "*((", "", 'Monthly Update'!CY11="", "", TRUE, 'Monthly Update'!CY11)} | H11: {=_xlfn.IFS(LEFT('Monthly Update'!CZ11, 3) = "*((", "", 'Monthly Update'!CZ11="", "", TRUE, 'Monthly Update'!CZ11)} | I11: {=_xlfn.IFS(LEFT('Monthly Update'!DA11, 3) = "*((", "", 'Monthly Update'!DA11="", "", TRUE, 'Monthly Update'!DA11)} | J11: {=_xlfn.IFS(LEFT('Monthly Update'!DB11, 3) = "*((", "", 'Monthly Update'!DB11="", "", TRUE, 'Monthly Update'!DB11)} | ... AW11: {=_xlfn.IFS(LEFT('Monthly Update'!EO11, 3) = "*((", "", 'Monthly Update'!EO11="", "", TRUE, 'Monthly Update'!EO11)}
A12: {=_xlfn.IFS(LEFT('Monthly Update'!A12, 3) = "*((", "", 'Monthly Update'!A12="", "", TRUE, 'Monthly Update'!A12)} | B12: {=_xlfn.IFS(LEFT('Monthly Update'!B12, 3) = "*((", "", 'Monthly Update'!B12="", "", TRUE, 'Monthly Update'!B12)} | C12: {=_xlfn.IFS(LEFT('Monthly Update'!CU12, 3) = "*((", "", 'Monthly Update'!CU12="", "", TRUE, 'Monthly Update'!CU12)} | D12: {=_xlfn.IFS(LEFT('Monthly Update'!CV12, 3) = "*((", "", 'Monthly Update'!CV12="", "", TRUE, 'Monthly Update'!CV12)} | E12: {=_xlfn.IFS(LEFT('Monthly Update'!CW12, 3) = "*((", "", 'Monthly Update'!CW12="", "", TRUE, 'Monthly Update'!CW12)} | F12: {=_xlfn.IFS(LEFT('Monthly Update'!CX12, 3) = "*((", "", 'Monthly Update'!CX12="", "", TRUE, 'Monthly Update'!CX12)} | G12: {=_xlfn.IFS(LEFT('Monthly Update'!CY12, 3) = "*((", "", 'Monthly Update'!CY12="", "", TRUE, 'Monthly Update'!CY12)} | H12: {=_xlfn.IFS(LEFT('Monthly Update'!CZ12, 3) = "*((", "", 'Monthly Update'!CZ12="", "", TRUE, 'Monthly Update'!CZ12)} | I12: {=_xlfn.IFS(LEFT('Monthly Update'!DA12, 3) = "*((", "", 'Monthly Update'!DA12="", "", TRUE, 'Monthly Update'!DA12)} | J12: {=_xlfn.IFS(LEFT('Monthly Update'!DB12, 3) = "*((", "", 'Monthly Update'!DB12="", "", TRUE, 'Monthly Update'!DB12)} | ... AW12: {=_xlfn.IFS(LEFT('Monthly Update'!EO12, 3) = "*((", "", 'Monthly Update'!EO12="", "", TRUE, 'Monthly Update'!EO12)}
A13: {=_xlfn.IFS(LEFT('Monthly Update'!A13, 3) = "*((", "", 'Monthly Update'!A13="", "", TRUE, 'Monthly Update'!A13)} | B13: {=_xlfn.IFS(LEFT('Monthly Update'!B13, 3) = "*((", "", 'Monthly Update'!B13="", "", TRUE, 'Monthly Update'!B13)} | C13: {=_xlfn.IFS(LEFT('Monthly Update'!CU13, 3) = "*((", "", 'Monthly Update'!CU13="", "", TRUE, 'Monthly Update'!CU13)} | D13: {=_xlfn.IFS(LEFT('Monthly Update'!CV13, 3) = "*((", "", 'Monthly Update'!CV13="", "", TRUE, 'Monthly Update'!CV13)} | E13: {=_xlfn.IFS(LEFT('Monthly Update'!CW13, 3) = "*((", "", 'Monthly Update'!CW13="", "", TRUE, 'Monthly Update'!CW13)} | F13: {=_xlfn.IFS(LEFT('Monthly Update'!CX13, 3) = "*((", "", 'Monthly Update'!CX13="", "", TRUE, 'Monthly Update'!CX13)} | G13: {=_xlfn.IFS(LEFT('Monthly Update'!CY13, 3) = "*((", "", 'Monthly Update'!CY13="", "", TRUE, 'Monthly Update'!CY13)} | H13: {=_xlfn.IFS(LEFT('Monthly Update'!CZ13, 3) = "*((", "", 'Monthly Update'!CZ13="", "", TRUE, 'Monthly Update'!CZ13)} | I13: {=_xlfn.IFS(LEFT('Monthly Update'!DA13, 3) = "*((", "", 'Monthly Update'!DA13="", "", TRUE, 'Monthly Update'!DA13)} | J13: {=_xlfn.IFS(LEFT('Monthly Update'!DB13, 3) = "*((", "", 'Monthly Update'!DB13="", "", TRUE, 'Monthly Update'!DB13)} | ... AW13: {=_xlfn.IFS(LEFT('Monthly Update'!EO13, 3) = "*((", "", 'Monthly Update'!EO13="", "", TRUE, 'Monthly Update'!EO13)}
A14: {=_xlfn.IFS(LEFT('Monthly Update'!A14, 3) = "*((", "", 'Monthly Update'!A14="", "", TRUE, 'Monthly Update'!A14)} | B14: {=_xlfn.IFS(LEFT('Monthly Update'!B14, 3) = "*((", "", 'Monthly Update'!B14="", "", TRUE, 'Monthly Update'!B14)} | C14: {=_xlfn.IFS(LEFT('Monthly Update'!CU14, 3) = "*((", "", 'Monthly Update'!CU14="", "", TRUE, 'Monthly Update'!CU14)} | D14: {=_xlfn.IFS(LEFT('Monthly Update'!CV14, 3) = "*((", "", 'Monthly Update'!CV14="", "", TRUE, 'Monthly Update'!CV14)} | E14: {=_xlfn.IFS(LEFT('Monthly Update'!CW14, 3) = "*((", "", 'Monthly Update'!CW14="", "", TRUE, 'Monthly Update'!CW14)} | F14: {=_xlfn.IFS(LEFT('Monthly Update'!CX14, 3) = "*((", "", 'Monthly Update'!CX14="", "", TRUE, 'Monthly Update'!CX14)} | G14: {=_xlfn.IFS(LEFT('Monthly Update'!CY14, 3) = "*((", "", 'Monthly Update'!CY14="", "", TRUE, 'Monthly Update'!CY14)} | H14: {=_xlfn.IFS(LEFT('Monthly Update'!CZ14, 3) = "*((", "", 'Monthly Update'!CZ14="", "", TRUE, 'Monthly Update'!CZ14)} | I14: {=_xlfn.IFS(LEFT('Monthly Update'!DA14, 3) = "*((", "", 'Monthly Update'!DA14="", "", TRUE, 'Monthly Update'!DA14)} | J14: {=_xlfn.IFS(LEFT('Monthly Update'!DB14, 3) = "*((", "", 'Monthly Update'!DB14="", "", TRUE, 'Monthly Update'!DB14)} | ... AW14: {=_xlfn.IFS(LEFT('Monthly Update'!EO14, 3) = "*((", "", 'Monthly Update'!EO14="", "", TRUE, 'Monthly Update'!EO14)}
A15: {=_xlfn.IFS(LEFT('Monthly Update'!A15, 3) = "*((", "", 'Monthly Update'!A15="", "", TRUE, 'Monthly Update'!A15)} | B15: {=_xlfn.IFS(LEFT('Monthly Update'!B15, 3) = "*((", "", 'Monthly Update'!B15="", "", TRUE, 'Monthly Update'!B15)} | C15: {=_xlfn.IFS(LEFT('Monthly Update'!CU15, 3) = "*((", "", 'Monthly Update'!CU15="", "", TRUE, 'Monthly Update'!CU15)} | D15: {=_xlfn.IFS(LEFT('Monthly Update'!CV15, 3) = "*((", "", 'Monthly Update'!CV15="", "", TRUE, 'Monthly Update'!CV15)} | E15: {=_xlfn.IFS(LEFT('Monthly Update'!CW15, 3) = "*((", "", 'Monthly Update'!CW15="", "", TRUE, 'Monthly Update'!CW15)} | F15: {=_xlfn.IFS(LEFT('Monthly Update'!CX15, 3) = "*((", "", 'Monthly Update'!CX15="", "", TRUE, 'Monthly Update'!CX15)} | G15: {=_xlfn.IFS(LEFT('Monthly Update'!CY15, 3) = "*((", "", 'Monthly Update'!CY15="", "", TRUE, 'Monthly Update'!CY15)} | H15: {=_xlfn.IFS(LEFT('Monthly Update'!CZ15, 3) = "*((", "", 'Monthly Update'!CZ15="", "", TRUE, 'Monthly Update'!CZ15)} | I15: {=_xlfn.IFS(LEFT('Monthly Update'!DA15, 3) = "*((", "", 'Monthly Update'!DA15="", "", TRUE, 'Monthly Update'!DA15)} | J15: {=_xlfn.IFS(LEFT('Monthly Update'!DB15, 3) = "*((", "", 'Monthly Update'!DB15="", "", TRUE, 'Monthly Update'!DB15)} | ... AW15: {=_xlfn.IFS(LEFT('Monthly Update'!EO15, 3) = "*((", "", 'Monthly Update'!EO15="", "", TRUE, 'Monthly Update'!EO15)}
A16: {=_xlfn.IFS(LEFT('Monthly Update'!A16, 3) = "*((", "", 'Monthly Update'!A16="", "", TRUE, 'Monthly Update'!A16)} | B16: {=_xlfn.IFS(LEFT('Monthly Update'!B16, 3) = "*((", "", 'Monthly Update'!B16="", "", TRUE, 'Monthly Update'!B16)} | C16: {=_xlfn.IFS(LEFT('Monthly Update'!CU16, 3) = "*((", "", 'Monthly Update'!CU16="", "", TRUE, 'Monthly Update'!CU16)} | D16: {=_xlfn.IFS(LEFT('Monthly Update'!CV16, 3) = "*((", "", 'Monthly Update'!CV16="", "", TRUE, 'Monthly Update'!CV16)} | E16: {=_xlfn.IFS(LEFT('Monthly Update'!CW16, 3) = "*((", "", 'Monthly Update'!CW16="", "", TRUE, 'Monthly Update'!CW16)} | F16: {=_xlfn.IFS(LEFT('Monthly Update'!CX16, 3) = "*((", "", 'Monthly Update'!CX16="", "", TRUE, 'Monthly Update'!CX16)} | G16: {=_xlfn.IFS(LEFT('Monthly Update'!CY16, 3) = "*((", "", 'Monthly Update'!CY16="", "", TRUE, 'Monthly Update'!CY16)} | H16: {=_xlfn.IFS(LEFT('Monthly Update'!CZ16, 3) = "*((", "", 'Monthly Update'!CZ16="", "", TRUE, 'Monthly Update'!CZ16)} | I16: {=_xlfn.IFS(LEFT('Monthly Update'!DA16, 3) = "*((", "", 'Monthly Update'!DA16="", "", TRUE, 'Monthly Update'!DA16)} | J16: {=_xlfn.IFS(LEFT('Monthly Update'!DB16, 3) = "*((", "", 'Monthly Update'!DB16="", "", TRUE, 'Monthly Update'!DB16)} | ... AW16: {=_xlfn.IFS(LEFT('Monthly Update'!EO16, 3) = "*((", "", 'Monthly Update'!EO16="", "", TRUE, 'Monthly Update'!EO16)}
A17: {=_xlfn.IFS(LEFT('Monthly Update'!A17, 3) = "*((", "", 'Monthly Update'!A17="", "", TRUE, 'Monthly Update'!A17)} | B17: {=_xlfn.IFS(LEFT('Monthly Update'!B17, 3) = "*((", "", 'Monthly Update'!B17="", "", TRUE, 'Monthly Update'!B17)} | C17: {=_xlfn.IFS(LEFT('Monthly Update'!CU17, 3) = "*((", "", 'Monthly Update'!CU17="", "", TRUE, 'Monthly Update'!CU17)} | D17: {=_xlfn.IFS(LEFT('Monthly Update'!CV17, 3) = "*((", "", 'Monthly Update'!CV17="", "", TRUE, 'Monthly Update'!CV17)} | E17: {=_xlfn.IFS(LEFT('Monthly Update'!CW17, 3) = "*((", "", 'Monthly Update'!CW17="", "", TRUE, 'Monthly Update'!CW17)} | F17: {=_xlfn.IFS(LEFT('Monthly Update'!CX17, 3) = "*((", "", 'Monthly Update'!CX17="", "", TRUE, 'Monthly Update'!CX17)} | G17: {=_xlfn.IFS(LEFT('Monthly Update'!CY17, 3) = "*((", "", 'Monthly Update'!CY17="", "", TRUE, 'Monthly Update'!CY17)} | H17: {=_xlfn.IFS(LEFT('Monthly Update'!CZ17, 3) = "*((", "", 'Monthly Update'!CZ17="", "", TRUE, 'Monthly Update'!CZ17)} | I17: {=_xlfn.IFS(LEFT('Monthly Update'!DA17, 3) = "*((", "", 'Monthly Update'!DA17="", "", TRUE, 'Monthly Update'!DA17)} | J17: {=_xlfn.IFS(LEFT('Monthly Update'!DB17, 3) = "*((", "", 'Monthly Update'!DB17="", "", TRUE, 'Monthly Update'!DB17)} | ... AW17: {=_xlfn.IFS(LEFT('Monthly Update'!EO17, 3) = "*((", "", 'Monthly Update'!EO17="", "", TRUE, 'Monthly Update'!EO17)}
A18: {=_xlfn.IFS(LEFT('Monthly Update'!A18, 3) = "*((", "", 'Monthly Update'!A18="", "", TRUE, 'Monthly Update'!A18)} | B18: {=_xlfn.IFS(LEFT('Monthly Update'!B18, 3) = "*((", "", 'Monthly Update'!B18="", "", TRUE, 'Monthly Update'!B18)} | C18: {=_xlfn.IFS(LEFT('Monthly Update'!CU18, 3) = "*((", "", 'Monthly Update'!CU18="", "", TRUE, 'Monthly Update'!CU18)} | D18: {=_xlfn.IFS(LEFT('Monthly Update'!CV18, 3) = "*((", "", 'Monthly Update'!CV18="", "", TRUE, 'Monthly Update'!CV18)} | E18: {=_xlfn.IFS(LEFT('Monthly Update'!CW18, 3) = "*((", "", 'Monthly Update'!CW18="", "", TRUE, 'Monthly Update'!CW18)} | F18: {=_xlfn.IFS(LEFT('Monthly Update'!CX18, 3) = "*((", "", 'Monthly Update'!CX18="", "", TRUE, 'Monthly Update'!CX18)} | G18: {=_xlfn.IFS(LEFT('Monthly Update'!CY18, 3) = "*((", "", 'Monthly Update'!CY18="", "", TRUE, 'Monthly Update'!CY18)} | H18: {=_xlfn.IFS(LEFT('Monthly Update'!CZ18, 3) = "*((", "", 'Monthly Update'!CZ18="", "", TRUE, 'Monthly Update'!CZ18)} | I18: {=_xlfn.IFS(LEFT('Monthly Update'!DA18, 3) = "*((", "", 'Monthly Update'!DA18="", "", TRUE, 'Monthly Update'!DA18)} | J18: {=_xlfn.IFS(LEFT('Monthly Update'!DB18, 3) = "*((", "", 'Monthly Update'!DB18="", "", TRUE, 'Monthly Update'!DB18)} | ... AW18: {=_xlfn.IFS(LEFT('Monthly Update'!EO18, 3) = "*((", "", 'Monthly Update'!EO18="", "", TRUE, 'Monthly Update'!EO18)}
A19: {=_xlfn.IFS(LEFT('Monthly Update'!A19, 3) = "*((", "", 'Monthly Update'!A19="", "", TRUE, 'Monthly Update'!A19)} | B19: {=_xlfn.IFS(LEFT('Monthly Update'!B19, 3) = "*((", "", 'Monthly Update'!B19="", "", TRUE, 'Monthly Update'!B19)} | C19: {=_xlfn.IFS(LEFT('Monthly Update'!CU19, 3) = "*((", "", 'Monthly Update'!CU19="", "", TRUE, 'Monthly Update'!CU19)} | D19: {=_xlfn.IFS(LEFT('Monthly Update'!CV19, 3) = "*((", "", 'Monthly Update'!CV19="", "", TRUE, 'Monthly Update'!CV19)} | E19: {=_xlfn.IFS(LEFT('Monthly Update'!CW19, 3) = "*((", "", 'Monthly Update'!CW19="", "", TRUE, 'Monthly Update'!CW19)} | F19: {=_xlfn.IFS(LEFT('Monthly Update'!CX19, 3) = "*((", "", 'Monthly Update'!CX19="", "", TRUE, 'Monthly Update'!CX19)} | G19: {=_xlfn.IFS(LEFT('Monthly Update'!CY19, 3) = "*((", "", 'Monthly Update'!CY19="", "", TRUE, 'Monthly Update'!CY19)} | H19: {=_xlfn.IFS(LEFT('Monthly Update'!CZ19, 3) = "*((", "", 'Monthly Update'!CZ19="", "", TRUE, 'Monthly Update'!CZ19)} | I19: {=_xlfn.IFS(LEFT('Monthly Update'!DA19, 3) = "*((", "", 'Monthly Update'!DA19="", "", TRUE, 'Monthly Update'!DA19)} | J19: {=_xlfn.IFS(LEFT('Monthly Update'!DB19, 3) = "*((", "", 'Monthly Update'!DB19="", "", TRUE, 'Monthly Update'!DB19)} | ... AW19: {=_xlfn.IFS(LEFT('Monthly Update'!EO19, 3) = "*((", "", 'Monthly Update'!EO19="", "", TRUE, 'Monthly Update'!EO19)}
A20: {=_xlfn.IFS(LEFT('Monthly Update'!A20, 3) = "*((", "", 'Monthly Update'!A20="", "", TRUE, 'Monthly Update'!A20)} | B20: {=_xlfn.IFS(LEFT('Monthly Update'!B20, 3) = "*((", "", 'Monthly Update'!B20="", "", TRUE, 'Monthly Update'!B20)} | C20: {=_xlfn.IFS(LEFT('Monthly Update'!CU20, 3) = "*((", "", 'Monthly Update'!CU20="", "", TRUE, 'Monthly Update'!CU20)} | D20: {=_xlfn.IFS(LEFT('Monthly Update'!CV20, 3) = "*((", "", 'Monthly Update'!CV20="", "", TRUE, 'Monthly Update'!CV20)} | E20: {=_xlfn.IFS(LEFT('Monthly Update'!CW20, 3) = "*((", "", 'Monthly Update'!CW20="", "", TRUE, 'Monthly Update'!CW20)} | F20: {=_xlfn.IFS(LEFT('Monthly Update'!CX20, 3) = "*((", "", 'Monthly Update'!CX20="", "", TRUE, 'Monthly Update'!CX20)} | G20: {=_xlfn.IFS(LEFT('Monthly Update'!CY20, 3) = "*((", "", 'Monthly Update'!CY20="", "", TRUE, 'Monthly Update'!CY20)} | H20: {=_xlfn.IFS(LEFT('Monthly Update'!CZ20, 3) = "*((", "", 'Monthly Update'!CZ20="", "", TRUE, 'Monthly Update'!CZ20)} | I20: {=_xlfn.IFS(LEFT('Monthly Update'!DA20, 3) = "*((", "", 'Monthly Update'!DA20="", "", TRUE, 'Monthly Update'!DA20)} | J20: {=_xlfn.IFS(LEFT('Monthly Update'!DB20, 3) = "*((", "", 'Monthly Update'!DB20="", "", TRUE, 'Monthly Update'!DB20)} | ... AW20: {=_xlfn.IFS(LEFT('Monthly Update'!EO20, 3) = "*((", "", 'Monthly Update'!EO20="", "", TRUE, 'Monthly Update'!EO20)}
